Workbook

Sheet AP25
E2: Porcentaje de Cumplimiento por KPI
E4: Market | F4: CSI | G4: SSI | H4: NRC | I4: Training | J4: Ser. Campaign | K4: Lead Mng. | L4: Share of Inv. | M4: Game Plan | N4: Sell In | O4: Retention | P4: Retail Sales
E5: COL | F5: 1.0076923 | G5: 1.0413043 | H5: 1 | I5: 0.96494444 | J5: =VLOOKUP(E5,'OR Q1'!$AJ$4:$AR$18,'OR Q1'!$AR$2,FALSE) -> 0.99852096 | K5: 1 | L5: 1 | M5: 1 | N5: =VLOOKUP(E5,'OR Q1'!$AA$4:$AC$19,'OR Q1'!$AB$3,FALSE) -> 1.0297799 | O5: =VLOOKUP(E5,'OR Q1'!$AA$4:$AC$19,'OR Q1'!$AC$3,FALSE) -> 1.030303 | P5: =VLOOKUP(E5,'OR Q1'!$W$4:$Y$19,'OR Q1'!$X$2,FALSE) -> 1.0675958
E6: PLT | F6: 1.0195122 | G6: 0.98021978 | I6: 1.0905556 | J6: =VLOOKUP(E6,'OR Q1'!$AJ$4:$AR$18,'OR Q1'!$AR$2,FALSE) -> 0.96711402 | K6: 0.5 | L6: 1 | M6: 1 | N6: =VLOOKUP(E6,'OR Q1'!$AA$4:$AC$19,'OR Q1'!$AB$3,FALSE) -> 0.95155751 | O6: =VLOOKUP(E6,'OR Q1'!$AA$4:$AC$19,'OR Q1'!$AC$3,FALSE) -> 1.0116279 | P6: =VLOOKUP(E6,'OR Q1'!$W$4:$Y$19,'OR Q1'!$X$2,FALSE) -> 0.85865076
E7: CST | F7: 1.0326087 | G7: 1.0163043 | H7: 1 | I7: 1.1111111 | J7: =VLOOKUP(E7,'OR Q1'!$AJ$4:$AR$18,'OR Q1'!$AR$2,FALSE) -> 1.0926723 | K7: 1 | L7: 1 | M7: 1 | N7: =VLOOKUP(E7,'OR Q1'!$AA$4:$AC$19,'OR Q1'!$AB$3,FALSE) -> 1.0488159 | O7: =VLOOKUP(E7,'OR Q1'!$AA$4:$AC$19,'OR Q1'!$AC$3,FALSE) -> 1 | P7: =VLOOKUP(E7,'OR Q1'!$W$4:$Y$19,'OR Q1'!$X$2,FALSE) -> 1.2970923
E8: ECA | F8: 1.0058824 | G8: 1.05 | H8: 1 | I8: 1.0758889 | J8: =VLOOKUP(E8,'OR Q1'!$AJ$4:$AR$18,'OR Q1'!$AR$2,FALSE) -> 1.2022301 | K8: 1 | L8: 1 | M8: 1 | N8: =VLOOKUP(E8,'OR Q1'!$AA$4:$AC$19,'OR Q1'!$AB$3,FALSE) -> 1.0401367 | O8: =VLOOKUP(E8,'OR Q1'!$AA$4:$AC$19,'OR Q1'!$AC$3,FALSE) -> 1.0194175 | P8: =VLOOKUP(E8,'OR Q1'!$W$4:$Y$19,'OR Q1'!$X$2,FALSE) -> 1.1223881
E9: PNM | F9: 1.0011628 | G9: 1.0733333 | H9: 1 | I9: 1.1111111 | J9: =VLOOKUP(E9,'OR Q1'!$AJ$4:$AR$18,'OR Q1'!$AR$2,FALSE) -> 1.0842398 | K9: 1 | L9: 1 | M9: 1 | N9: =VLOOKUP(E9,'OR Q1'!$AA$4:$AC$19,'OR Q1'!$AB$3,FALSE) -> 0.98023704 | O9: =VLOOKUP(E9,'OR Q1'!$AA$4:$AC$19,'OR Q1'!$AC$3,FALSE) -> 1.0126582 | P9: =VLOOKUP(E9,'OR Q1'!$W$4:$Y$19,'OR Q1'!$X$2,FALSE) -> 0.6884984
E10: URU | F10: 1.0531915 | G10: 1.0284211 | H10: 1 | I10: 1.0793333 | J10: =VLOOKUP(E10,'OR Q1'!$AJ$4:$AR$18,'OR Q1'!$AR$2,FALSE) -> 1.0284499 | K10: 1 | L10: 1 | M10: 1 | N10: =VLOOKUP(E10,'OR Q1'!$AA$4:$AC$19,'OR Q1'!$AB$3,FALSE) -> 0.97245646 | O10: =VLOOKUP(E10,'OR Q1'!$AA$4:$AC$19,'OR Q1'!$AC$3,FALSE) -> 0.98823529 | P10: =VLOOKUP(E10,'OR Q1'!$W$4:$Y$19,'OR Q1'!$X$2,FALSE) -> 1.4946619
E11: ELS | F11: 1.0914286 | G11: 1.146988 | H11: 1 | I11: 1.0779444 | J11: =VLOOKUP(E11,'OR Q1'!$AJ$4:$AR$18,'OR Q1'!$AR$2,FALSE) -> 0.99609054 | K11: 1 | L11: 1 | M11: 1 | N11: =VLOOKUP(E11,'OR Q1'!$AA$4:$AC$19,'OR Q1'!$AB$3,FALSE) -> 1.0057885 | O11: =VLOOKUP(E11,'OR Q1'!$AA$4:$AC$19,'OR Q1'!$AC$3,FALSE) -> 0.91836735 | P11: =VLOOKUP(E11,'OR Q1'!$W$4:$Y$19,'OR Q1'!$X$2,FALSE) -> 1.1842105
E12: HND | F12: 0.86571429 | G12: 1.2048193 | H12: 1 | I12: 1.0956667 | J12: =VLOOKUP(E12,'OR Q1'!$AJ$4:$AR$18,'OR Q1'!$AR$2,FALSE) -> 0.99273276 | K12: 1 | L12: 1 | M12: 1 | N12: =VLOOKUP(E12,'OR Q1'!$AA$4:$AC$19,'OR Q1'!$AB$3,FALSE) -> 1.0282038 | O12: =VLOOKUP(E12,'OR Q1'!$AA$4:$AC$19,'OR Q1'!$AC$3,FALSE) -> 1.0265487 | P12: =VLOOKUP(E12,'OR Q1'!$W$4:$Y$19,'OR Q1'!$X$2,FALSE) -> 1.1839827
E13: NIC | F13: 0.84857143 | G13: 1.0951807 | H13: 1 | I13: 1.0593333 | J13: =VLOOKUP(E13,'OR Q1'!$AJ$4:$AR$18,'OR Q1'!$AR$2,FALSE) -> 0.92865528 | K13: 1 | L13: 1 | M13: 1 | N13: =VLOOKUP(E13,'OR Q1'!$AA$4:$AC$19,'OR Q1'!$AB$3,FALSE) -> 1.0626019 | O13: =VLOOKUP(E13,'OR Q1'!$AA$4:$AC$19,'OR Q1'!$AC$3,FALSE) -> 1.1 | P13: =VLOOKUP(E13,'OR Q1'!$W$4:$Y$19,'OR Q1'!$X$2,FALSE) -> 1.2666667
E14: DOM | F14: 1.1742857 | G14: 1.0681818 | H14: 1 | I14: 1.1111111 | J14: =VLOOKUP(E14,'OR Q1'!$AJ$4:$AR$18,'OR Q1'!$AR$2,FALSE) -> 0.99273284 | K14: 1 | L14: 1 | M14: 1 | N14: =VLOOKUP(E14,'OR Q1'!$AA$4:$AC$19,'OR Q1'!$AB$3,FALSE) -> 0.96809833 | O14: =VLOOKUP(E14,'OR Q1'!$AA$4:$AC$19,'OR Q1'!$AC$3,FALSE) -> 0.93377483 | P14: =VLOOKUP(E14,'OR Q1'!$W$4:$Y$19,'OR Q1'!$X$2,FALSE) -> 0.92715232
E15: GUT | F15: 1.024 | G15: 0.96385542 | H15: 1 | I15: 1.0859444 | J15: =VLOOKUP(E15,'OR Q1'!$AJ$4:$AR$18,'OR Q1'!$AR$2,FALSE) -> 0.83839679 | K15: 1 | L15: - | M15: 1 | N15: =VLOOKUP(E15,'OR Q1'!$AA$4:$AC$19,'OR Q1'!$AB$3,FALSE) -> 1.1357956 | O15: =VLOOKUP(E15,'OR Q1'!$AA$4:$AC$19,'OR Q1'!$AC$3,FALSE) -> 0.99280576 | P15: =VLOOKUP(E15,'OR Q1'!$W$4:$Y$19,'OR Q1'!$X$2,FALSE) -> 0.7512605
E16: PRG | F16: 1.0857143 | G16: 1.0488889 | H16: 1 | I16: 1.0567778 | J16: =VLOOKUP(E16,'OR Q1'!$AJ$4:$AR$18,'OR Q1'!$AR$2,FALSE) -> 0.97986766 | K16: 1 | L16: - | M16: 1 | N16: =VLOOKUP(E16,'OR Q1'!$AA$4:$AC$19,'OR Q1'!$AB$3,FALSE) -> 0.90039765 | O16: =VLOOKUP(E16,'OR Q1'!$AA$4:$AC$19,'OR Q1'!$AC$3,FALSE) -> 1.1496063 | P16: =VLOOKUP(E16,'OR Q1'!$W$4:$Y$19,'OR Q1'!$X$2,FALSE) -> 0.76970954
E17: BOL | F17: 1.0294118 | G17: 1.0816092 | H17: 1 | I17: 1.0724444 | J17: =VLOOKUP(E17,'OR Q1'!$AJ$4:$AR$18,'OR Q1'!$AR$2,FALSE) -> 0.98002087 | K17: 1 | L17: - | M17: 1 | N17: =VLOOKUP(E17,'OR Q1'!$AA$4:$AC$19,'OR Q1'!$AB$3,FALSE) -> 0.91089448 | O17: =VLOOKUP(E17,'OR Q1'!$AA$4:$AC$19,'OR Q1'!$AC$3,FALSE) -> 0.90588235 | P17: =VLOOKUP(E17,'OR Q1'!$W$4:$Y$19,'OR Q1'!$X$2,FALSE) -> 1.1469534
E18: MASSY | F18: 0.73571429 | G18: 1.0579545 | H18: 1 | I18: 0.93888889 | J18: 0.75 | K18: 1 | L18: - | M18: 1 | N18: =VLOOKUP(E18,'OR Q1'!$AA$4:$AC$19,'OR Q1'!$AB$3,FALSE) -> 1 | O18: =VLOOKUP(E18,'OR Q1'!$AA$4:$AC$19,'OR Q1'!$AC$3,FALSE) -> 0.92322792 | P18: =VLOOKUP(E18,'OR Q1'!$W$4:$Y$19,'OR Q1'!$X$2,FALSE) -> 0.91784038
E19: Gel Group | F19: - | G19: - | H19: 1 | I19: 0.5 | J19: 0.1 | K19: 0.5 | L19: - | M19: 1 | N19: =VLOOKUP(E19,'OR Q1'!$AA$4:$AC$19,'OR Q1'!$AB$3,FALSE) -> 1 | O19: =VLOOKUP(E19,'OR Q1'!$AA$4:$AC$19,'OR Q1'!$AC$3,FALSE) -> 0.35117205 | P19: =VLOOKUP(E19,'OR Q1'!$W$4:$Y$19,'OR Q1'!$X$2,FALSE) -> 1.2521739
E21: Peso por KPI
E23: Market | F23: CSI | G23: SSI | H23: NRC | I23: Training | J23: Ser. Campaign | K23: Lead Mng. | L23: Share of Inv. | M23: Game Plan | N23: Sell In | O23: Retention | P23: Retail Sales | Q23: Total
E24: COL | F24: 0.06 | G24: 0.06 | H24: 0.05 | I24: 0.04 | J24: 0.04 | K24: 0.05 | L24: 0.03 | M24: 0.07 | N24: 0.2 | O24: 0.1 | P24: 0.3 | Q24: =SUM(F24:P24) -> 1
E25: PLT | F25: 0.06 | G25: 0.06 | H25: 0.05 | I25: 0.04 | J25: 0.04 | K25: 0.05 | L25: 0.03 | M25: 0.07 | N25: 0.2 | O25: 0.1 | P25: 0.3 | Q25: =SUM(F25:P25) -> 1
E26: CST | F26: 0.06 | G26: 0.06 | H26: 0.05 | I26: 0.04 | J26: 0.04 | K26: 0.05 | L26: 0.03 | M26: 0.07 | N26: 0.2 | O26: 0.1 | P26: 0.3 | Q26: =SUM(F26:P26) -> 1
E27: ECA | F27: 0.06 | G27: 0.06 | H27: 0.05 | I27: 0.04 | J27: 0.04 | K27: 0.05 | L27: 0.03 | M27: 0.07 | N27: 0.2 | O27: 0.1 | P27: 0.3 | Q27: =SUM(F27:P27) -> 1
E28: PNM | F28: 0.06 | G28: 0.06 | H28: 0.05 | I28: 0.04 | J28: 0.04 | K28: 0.05 | L28: 0.03 | M28: 0.07 | N28: 0.2 | O28: 0.1 | P28: 0.3 | Q28: =SUM(F28:P28) -> 1
E29: URU | F29: 0.06 | G29: 0.06 | H29: 0.05 | I29: 0.04 | J29: 0.04 | K29: 0.05 | L29: 0.03 | M29: 0.07 | N29: 0.2 | O29: 0.1 | P29: 0.3 | Q29: =SUM(F29:P29) -> 1
E30: ELS | F30: 0.06 | G30: 0.06 | H30: 0.05 | I30: 0.04 | J30: 0.04 | K30: 0.05 | L30: 0.03 | M30: 0.07 | N30: 0.2 | O30: 0.1 | P30: 0.3 | Q30: =SUM(F30:P30) -> 1
E31: HND | F31: 0.06 | G31: 0.06 | H31: 0.05 | I31: 0.04 | J31: 0.04 | K31: 0.05 | L31: 0.03 | M31: 0.07 | N31: 0.2 | O31: 0.1 | P31: 0.3 | Q31: =SUM(F31:P31) -> 1
E32: NIC | F32: 0.06 | G32: 0.06 | H32: 0.05 | I32: 0.04 | J32: 0.04 | K32: 0.05 | L32: 0.03 | M32: 0.07 | N32: 0.2 | O32: 0.1 | P32: 0.3 | Q32: =SUM(F32:P32) -> 1
E33: DOM | F33: 0.06 | G33: 0.06 | H33: 0.05 | I33: 0.04 | J33: 0.04 | K33: 0.05 | L33: 0.03 | M33: 0.07 | N33: 0.2 | O33: 0.1 | P33: 0.3 | Q33: =SUM(F33:P33) -> 1
E34: GUT | F34: 0.06 | G34: 0.06 | H34: 0.05 | I34: 0.04 | J34: 0.04 | K34: 0.05 | L34: - | M34: 0.1 | N34: 0.2 | O34: 0.1 | P34: 0.3 | Q34: =SUM(F34:P34) -> 1
E35: PRG | F35: 0.06 | G35: 0.06 | H35: 0.05 | I35: 0.04 | J35: 0.04 | K35: 0.05 | L35: - | M35: 0.1 | N35: 0.2 | O35: 0.1 | P35: 0.3 | Q35: =SUM(F35:P35) -> 1
E36: BOL | F36: 0.06 | G36: 0.06 | H36: 0.05 | I36: 0.04 | J36: 0.04 | K36: 0.05 | L36: - | M36: 0.1 | N36: 0.2 | O36: 0.1 | P36: 0.3 | Q36: =SUM(F36:P36) -> 1
E37: MASSY | F37: 0.06 | G37: 0.06 | H37: 0.05 | I37: 0.04 | J37: 0.04 | K37: 0.05 | L37: - | M37: 0.1 | N37: 0.2 | O37: 0.1 | P37: 0.3 | Q37: =SUM(F37:P37) -> 1
E38: Gel Group | F38: - | G38: - | H38: 0.05 | I38: 0.05 | J38: 0.05 | K38: 0.05 | L38: - | M38: 0.1 | N38: 0.25 | O38: 0.1 | P38: 0.35 | Q38: =SUM(F38:P38) -> 1
E41: Market | F41: CSI | G41: SSI | H41: NRC | I41: Training | J41: Ser. Campaign | K41: Lead Mng. | L41: Share of Inv. | M41: Game Plan | N41: Sell In | O41: Retention | P41: Retail Sales | Q41: Total
E42: COL | F42: =IF(F5>=100%,F24,(F5*F24)/100%) -> 0.06 | G42: =IF(G5>=100%,G24,(G5*G24)/100%) -> 0.06 | H42: =IF(H5>=100%,H24,(H5*H24)/100%) -> 0.05 | I42: =IF(I5>=100%,I24,(I5*I24)/100%) -> 0.038597778 | J42: =IF(J5>=100%,J24,(J5*J24)/100%) -> 0.039940839 | K42: =IF(K5>=100%,K24,(K5*K24)/100%) -> 0.05 | L42: =IF(L5>=100%,L24,(L5*L24)/100%) -> 0.03 | M42: =IF(M5>=100%,M24,(M5*M24)/100%) -> 0.07 | ... P42: =IF(P5>=100%,P24,(P5*P24)/100%) -> 0.3 | Q42: =SUM(F42:P42) -> 0.99853862
E43: PLT | F43: =IF(F6>=100%,F25,(F6*F25)/100%) -> 0.06 | G43: =IF(G6>=100%,G25,(G6*G25)/100%) -> 0.058813187 | H43: =IF(H6>=100%,H25,(H6*H25)/100%) -> 0 | I43: =IF(I6>=100%,I25,(I6*I25)/100%) -> 0.04 | J43: =IF(J6>=100%,J25,(J6*J25)/100%) -> 0.038684561 | K43: =IF(K6>=100%,K25,(K6*K25)/100%) -> 0.025 | L43: =IF(L6>=100%,L25,(L6*L25)/100%) -> 0.03 | M43: =IF(M6>=100%,M25,(M6*M25)/100%) -> 0.07 | ... P43: =IF(P6>=100%,P25,(P6*P25)/100%) -> 0.25759523 | Q43: =SUM(F43:P43) -> 0.87040448
E44: CST | F44: =IF(F7>=100%,F26,(F7*F26)/100%) -> 0.06 | G44: =IF(G7>=100%,G26,(G7*G26)/100%) -> 0.06 | H44: =IF(H7>=100%,H26,(H7*H26)/100%) -> 0.05 | I44: =IF(I7>=100%,I26,(I7*I26)/100%) -> 0.04 | J44: =IF(J7>=100%,J26,(J7*J26)/100%) -> 0.04 | K44: =IF(K7>=100%,K26,(K7*K26)/100%) -> 0.05 | L44: =IF(L7>=100%,L26,(L7*L26)/100%) -> 0.03 | M44: =IF(M7>=100%,M26,(M7*M26)/100%) -> 0.07 | ... P44: =IF(P7>=100%,P26,(P7*P26)/100%) -> 0.3 | Q44: =SUM(F44:P44) -> 1
E45: ECA | F45: =IF(F8>=100%,F27,(F8*F27)/100%) -> 0.06 | G45: =IF(G8>=100%,G27,(G8*G27)/100%) -> 0.06 | H45: =IF(H8>=100%,H27,(H8*H27)/100%) -> 0.05 | I45: =IF(I8>=100%,I27,(I8*I27)/100%) -> 0.04 | J45: =IF(J8>=100%,J27,(J8*J27)/100%) -> 0.04 | K45: =IF(K8>=100%,K27,(K8*K27)/100%) -> 0.05 | L45: =IF(L8>=100%,L27,(L8*L27)/100%) -> 0.03 | M45: =IF(M8>=100%,M27,(M8*M27)/100%) -> 0.07 | ... P45: =IF(P8>=100%,P27,(P8*P27)/100%) -> 0.3 | Q45: =SUM(F45:P45) -> 1
E46: PNM | F46: =IF(F9>=100%,F28,(F9*F28)/100%) -> 0.06 | G46: =IF(G9>=100%,G28,(G9*G28)/100%) -> 0.06 | H46: =IF(H9>=100%,H28,(H9*H28)/100%) -> 0.05 | I46: =IF(I9>=100%,I28,(I9*I28)/100%) -> 0.04 | J46: =IF(J9>=100%,J28,(J9*J28)/100%) -> 0.04 | K46: =IF(K9>=100%,K28,(K9*K28)/100%) -> 0.05 | L46: =IF(L9>=100%,L28,(L9*L28)/100%) -> 0.03 | M46: =IF(M9>=100%,M28,(M9*M28)/100%) -> 0.07 | ... P46: =IF(P9>=100%,P28,(P9*P28)/100%) -> 0.20654952 | Q46: =SUM(F46:P46) -> 0.90259693
...

Sheet OR Q1
B2: 1 | C2: 2 | D2: 3 | E2: 4 | F2: 5 | G2: 6 | H2: 7 | W2: 1 | X2: 2 | Y2: 3 | AE2: 1 | AF2: 2 | AG2: 3 | AH2: 4 | AJ2: 1 | AK2: 2 | AL2: 3 | AM2: 4 | AN2: 5 | AO2: 6 | AP2: 7 | AQ2: 8 | AR2: 9
B3: NSC | C3: Target Sell-In | D3: Total Sell-In | E3: % Achi. Sell In | F3: Target Service Frequency | G3: Service Frequency | H3: %Achi, Retention | J3: 1 | K3: 2 | L3: 3 | M3: 4 | N3: 5 | S3: Q1 vs PY | W3: Q1 vs BP | AA3: 1 | AB3: 2 | AC3: 3 | AE3: Lead Management | AK3: Serv. Campaign Target | AN3: Serv. Campaign Real | AT3: 1 | AU3: 2 | AV3: 3 | AW3: 4 | AX3: 5 | AY3: 6 | AZ3: 7 | BA3: 8 | BB3: 9
J4: Market | K4: CSI | L4: Real CSI | M4: %Cumplimiento CSI | N4: SSI | O4: Real SSI | P4: %Cumplimiento SSI | S4: NSC | T4: RS | U4: MS | W4: NSC | X4: RS | Y4: MS | AA4: Market | AB4: Sell In | AC4: Retention | AE4: Market | AF4: Mayo | AG4: Junio | AH4: Average | AJ4: NSC | AK4: APR | AL4: MAY | AM4: Total | AN4: NSC | AO4: APR | AP4: MAY | AQ4: Total | AR4: %Achiev. | AT4: Market | AU4: TR Sales | AV4: Real TR Sales | AW4: %Ach. TR Sales | AX4: TR AS | AY4: Real TR AS | AZ4: Trainin (Compliance %) | BA4: Real TR | BB4: Result
B5: COL | C5: 3401185 | D5: 3502472 | E5: =D5/C5 -> 1.0297799 | F5: 0.99 | G5: 1.02 | H5: =G5/F5 -> 1.030303 | J5: COL | K5: 0.78 | L5: 0.786 | M5: 1.0076923 | N5: 0.92 | O5: 0.958 | P5: 1.0413043 | S5: COL | T5: 1.186677 | U5: 0.96590806 | W5: Gel Group | X5: 1.2521739 | Y5: 1.231389 | AA5: COL | AB5: 1.0297799 | AC5: 1.030303 | AE5: COL | AF5: 1 | AG5: 1 | AH5: =AVERAGE(AF5:AG5) -> 1 | AJ5: ECA | AK5: 463.16667 | AL5: 523.33333 | AM5: =SUM(AK5:AL5) -> 986.5 | AN5: ECA | AO5: 509 | AP5: 677 | AQ5: =SUM(AO5:AP5) -> 1186 | AR5: =AQ5/AM5 -> 1.2022301 | AT5: COL | AU5: 0.9 | AV5: 0.9996 | AW5: =AV5/AU5 -> 1.1106667 | AX5: 0.9 | AY5: 0.8369 | AZ5: 0.9 | BA5: 0.86845 | BB5: =BA5/AZ5 -> 0.96494444
B6: BOL | C6: 502943 | D6: 458128 | E6: =D6/C6 -> 0.91089448 | F6: 0.85 | G6: 0.77 | H6: =G6/F6 -> 0.90588235 | J6: PLT | K6: 0.82 | L6: 0.836 | M6: 1.0195122 | N6: 0.91 | O6: 0.892 | P6: 0.98021978 | S6: PLT | T6: 0.77154639 | U6: 0.82677044 | W6: Massy | X6: 0.91784038 | Y6: 0.94113582 | AA6: PLT | AB6: 0.95155751 | AC6: 1.0116279 | AE6: PLT | AF6: 1 | AG6: 0 | AH6: =AVERAGE(AF6:AG6) -> 0.5 | AJ6: CST | AK6: 877.72917 | AL6: 965.45833 | AM6: =SUM(AK6:AL6) -> 1843.1875 | AN6: CST | AO6: 927 | AP6: 1087 | AQ6: =SUM(AO6:AP6) -> 2014 | AR6: =AQ6/AM6 -> 1.0926723 | AT6: PLT | AU6: 0.9 | AV6: 0.963 | AW6: =AV6/AU6 -> 1.07 | AX6: 0.9 | AY6: 1 | AZ6: 0.9 | BA6: 0.9815 | BB6: =BA6/AZ6 -> 1.0905556
B7: ECA | C7: 900696 | D7: 936847 | E7: =D7/C7 -> 1.0401367 | F7: 1.03 | G7: 1.05 | H7: =G7/F7 -> 1.0194175 | J7: CST | K7: 0.92 | L7: 0.95 | M7: 1.0326087 | N7: 0.92 | O7: 0.935 | P7: 1.0163043 | S7: CST | T7: 1.0078585 | U7: 1.2233881 | W7: COL | X7: 1.0675958 | Y7: 0.9405252 | AA7: CST | AB7: 1.0488159 | AC7: 1 | AE7: CST | AF7: 1 | AG7: 1 | AH7: =AVERAGE(AF7:AG7) -> 1 | AJ7: URU | AK7: 1938.3125 | AL7: 2000.625 | AM7: =SUM(AK7:AL7) -> 3938.9375 | AN7: URU | AO7: 1943 | AP7: 2108 | AQ7: =SUM(AO7:AP7) -> 4051 | AR7: =AQ7/AM7 -> 1.0284499 | AT7: CST | AU7: 0.9 | AV7: 1 | AW7: =AV7/AU7 -> 1.1111111 | AX7: 0.9 | AY7: 1 | AZ7: 0.9 | BA7: 1 | BB7: =BA7/AZ7 -> 1.1111111
B8: PRG | C8: 861566 | D8: 775752 | E8: =D8/C8 -> 0.90039765 | F8: 1.27 | G8: 1.46 | H8: =G8/F8 -> 1.1496063 | J8: ECA | K8: 0.85 | L8: 0.855 | M8: 1.0058824 | N8: 0.94 | O8: 0.987 | P8: 1.05 | S8: HND | T8: 0.71316819 | U8: 1.0189976 | W8: PLT | X8: 0.85865076 | Y8: 0.77809516 | AA8: ECA | AB8: 1.0401367 | AC8: 1.0194175 | AE8: ECA | AF8: 1 | AG8: 1 | AH8: =AVERAGE(AF8:AG8) -> 1 | AJ8: COL | AK8: 5003.7167 | AL8: 5239.4333 | AM8: =SUM(AK8:AL8) -> 10243.15 | AN8: COL | AO8: 4904 | AP8: 5324 | AQ8: =SUM(AO8:AP8) -> 10228 | AR8: =AQ8/AM8 -> 0.99852096 | AT8: ECA | AU8: 0.9 | AV8: 0.9804 | AW8: =AV8/AU8 -> 1.0893333 | AX8: 0.9 | AY8: 0.9562 | AZ8: 0.9 | BA8: 0.9683 | BB8: =BA8/AZ8 -> 1.0758889
B9: URU | C9: 691124 | D9: 672088 | E9: =D9/C9 -> 0.97245646 | F9: 0.85 | G9: 0.84 | H9: =G9/F9 -> 0.98823529 | J9: PNM | K9: 0.86 | L9: 0.861 | M9: 1.0011628 | N9: 0.9 | O9: 0.966 | P9: 1.0733333 | S9: ECA | T9: 0.56969697 | U9: 0.49332267 | W9: ECA | X9: 1.1223881 | Y9: 0.87051458 | AA9: PNM | AB9: 0.98023704 | AC9: 1.0126582 | AE9: PNM | AF9: 1 | AG9: 1 | AH9: =AVERAGE(AF9:AG9) -> 1 | AJ9: PLT | AK9: 1782.0683 | AL9: 1873.1367 | AM9: =SUM(AK9:AL9) -> 3655.205 | AN9: PLT | AO9: 1734 | AP9: 1801 | AQ9: =SUM(AO9:AP9) -> 3535 | AR9: =AQ9/AM9 -> 0.96711402 | AT9: PNM | AU9: 0.9 | AV9: 1 | AW9: =AV9/AU9 -> 1.1111111 | AX9: 0.9 | AY9: 1 | AZ9: 0.9 | BA9: 1 | BB9: =BA9/AZ9 -> 1.1111111
B10: ANT | C10: - | D10: - | F10: 1.06 | G10: 1.52 | H10: =G10/F10 -> 1.4339623 | J10: URU | K10: 0.94 | L10: 0.99 | M10: 1.0531915 | N10: 0.95 | O10: 0.977 | P10: 1.0284211 | S10: URU | T10: 0.64417178 | U10: 0.63667376 | W10: CST | X10: 1.2970923 | Y10: 1.1659973 | AA10: URU | AB10: 0.97245646 | AC10: 0.98823529 | AE10: URU | AF10: 1 | AG10: 1 | AH10: =AVERAGE(AF10:AG10) -> 1 | AJ10: PNM | AK10: 422.73333 | AL10: 441.46667 | AM10: =SUM(AK10:AL10) -> 864.2 | AN10: PNM | AO10: 442 | AP10: 495 | AQ10: =SUM(AO10:AP10) -> 937 | AR10: =AQ10/AM10 -> 1.0842398 | AT10: URU | AU10: 0.9 | AV10: 0.9785 | AW10: =AV10/AU10 -> 1.0872222 | AX10: 0.9 | AY10: 0.9643 | AZ10: 0.9 | BA10: 0.9714 | BB10: =BA10/AZ10 -> 1.0793333
B11: BAR | C11: - | D11: 351 | F11: 1.84 | G11: 0.5 | H11: =G11/F11 -> 0.27173913 | J11: ELS | K11: 0.7 | L11: 0.764 | M11: 1.0914286 | N11: 0.83 | O11: 0.952 | P11: 1.146988 | S11: PNM | T11: 0.74696707 | U11: 0.76591604 | W11: URU | X11: 1.4946619 | Y11: 1.3219075 | AA11: ELS | AB11: 1.0057885 | AC11: 0.91836735 | AE11: ELS | AF11: 1 | AG11: 1 | AH11: =AVERAGE(AF11:AG11) -> 1 | AJ11: BOL | AK11: 476.79583 | AL11: 493.59167 | AM11: =SUM(AK11:AL11) -> 970.3875 | AN11: BOL | AO11: 471 | AP11: 480 | AQ11: =SUM(AO11:AP11) -> 951 | AR11: =AQ11/AM11 -> 0.98002087 | AT11: ELS | AU11: 0.9 | AV11: 0.9503 | AW11: =AV11/AU11 -> 1.0558889 | AX11: 0.9 | AY11: 0.99 | AZ11: 0.9 | BA11: 0.97015 | BB11: =BA11/AZ11 -> 1.0779444
B12: BEM | C12: - | D12: - | F12: 1.21 | G12: - | J12: HND | K12: 0.7 | L12: 0.606 | M12: 0.86571429 | N12: 0.83 | O12: 1 | P12: 1.2048193 | S12: Massy | T12: 0.73634652 | U12: 0.82265571 | W12: PNM | X12: 0.6884984 | Y12: 0.58887509 | AA12: HND | AB12: 1.0282038 | AC12: 1.0265487 | AE12: HND | AF12: 1 | AG12: 1 | AH12: =AVERAGE(AF12:AG12) -> 1 | AJ12: PRG | AK12: 348.1 | AL12: 362.2 | AM12: =SUM(AK12:AL12) -> 710.3 | AN12: PRG | AO12: 336 | AP12: 360 | AQ12: =SUM(AO12:AP12) -> 696 | AR12: =AQ12/AM12 -> 0.97986766 | AT12: HND | AU12: 0.9 | AV12: 1 | AW12: =AV12/AU12 -> 1.1111111 | AX12: 0.9 | AY12: 0.9722 | AZ12: 0.9 | BA12: 0.9861 | BB12: =BA12/AZ12 -> 1.0956667
B13: BHM | C13: - | D13: - | F13: 1.06 | G13: 0.53 | H13: =G13/F13 -> 0.5 | J13: NIC | K13: 0.7 | L13: 0.594 | M13: 0.84857143 | N13: 0.83 | O13: 0.909 | P13: 1.0951807 | S13: ELS | T13: 0.93927894 | U13: 0.95493359 | W13: DOM | X13: 0.92715232 | Y13: 0.78000111 | AA13: NIC | AB13: 1.0626019 | AC13: 1.1 | AE13: NIC | AF13: 1 | AG13: 1 | AH13: =AVERAGE(AF13:AG13) -> 1 | AJ13: NIC | AK13: 93.225 | AL13: 98.45 | AM13: =SUM(AK13:AL13) -> 191.675 | AN13: NIC | AO13: 88 | AP13: 90 | AQ13: =SUM(AO13:AP13) -> 178 | AR13: =AQ13/AM13 -> 0.92865528 | AT13: NIC | AU13: 0.9 | AV13: 1 | AW13: =AV13/AU13 -> 1.1111111 | AX13: 0.9 | AY13: 0.9068 | AZ13: 0.9 | BA13: 0.9534 | BB13: =BA13/AZ13 -> 1.0593333
B14: DMT | C14: - | D14: - | F14: 1.07 | G14: - | J14: DOM | K14: 0.7 | L14: 0.822 | M14: 1.1742857 | N14: 0.88 | O14: 0.94 | P14: 1.0681818 | S14: DOM | T14: 0.83832335 | U14: 0.89685679 | W14: GUT | X14: 0.7512605 | Y14: 0.68330768 | AA14: DOM | AB14: 0.96809833 | AC14: 0.93377483 | AE14: DOM | AF14: 1 | AG14: 1 | AH14: =AVERAGE(AF14:AG14) -> 1 | AJ14: ELS | AK14: 183.82917 | AL14: 196.65833 | AM14: =SUM(AK14:AL14) -> 380.4875 | AN14: ELS | AO14: 178 | AP14: 201 | AQ14: =SUM(AO14:AP14) -> 379 | AR14: =AQ14/AM14 -> 0.99609054 | AT14: DOM | AU14: 0.9 | AV14: 1 | AW14: =AV14/AU14 -> 1.1111111 | AX14: 0.9 | AY14: 1 | AZ14: 0.9 | BA14: 1 | BB14: =BA14/AZ14 -> 1.1111111
B15: GRN | C15: - | D15: - | F15: 1.06 | G15: 2.76 | H15: =G15/F15 -> 2.6037736 | J15: GUT | K15: 0.75 | L15: 0.768 | M15: 1.024 | N15: 0.83 | O15: 0.8 | P15: 0.96385542 | S15: BOL | T15: 0.68376068 | U15: 0.81382727 | W15: PRG | X15: 0.76970954 | Y15: 0.68543275 | AA15: GUT | AB15: 1.1357956 | AC15: 0.99280576 | AE15: GUT | AF15: 1 | AG15: 1 | AH15: =AVERAGE(AF15:AG15) -> 1 | AJ15: GUT | AK15: 103.07917 | AL15: 121.15833 | AM15: =SUM(AK15:AL15) -> 224.2375 | AN15: GUT | AO15: 91 | AP15: 97 | AQ15: =SUM(AO15:AP15) -> 188 | AR15: =AQ15/AM15 -> 0.83839679 | AT15: GUT | AU15: 0.9 | AV15: 1 | AW15: =AV15/AU15 -> 1.1111111 | AX15: 0.9 | AY15: 0.9547 | AZ15: 0.9 | BA15: 0.97735 | BB15: =BA15/AZ15 -> 1.0859444
B16: GUI | C16: - | D16: - | F16: 1.07 | G16: 0.38 | H16: =G16/F16 -> 0.35514019 | J16: PRG | K16: 0.84 | L16: 0.912 | M16: 1.0857143 | N16: 0.9 | O16: 0.944 | P16: 1.0488889 | S16: PRG | T16: 0.82444444 | U16: 0.76684654 | W16: BOL | X16: 1.1469534 | Y16: 1.2034473 | AA16: PRG | AB16: 0.90039765 | AC16: 1.1496063 | AE16: PRG | AF16: 1 | AG16: 1 | AH16: =AVERAGE(AF16:AG16) -> 1 | AJ16: DOM | AK16: 416.0375 | AL16: 425.075 | AM16: =SUM(AK16:AL16) -> 841.1125 | AN16: DOM | AO16: 414 | AP16: 421 | AQ16: =SUM(AO16:AP16) -> 835 | AR16: =AQ16/AM16 -> 0.99273284 | AT16: PRG | AU16: 0.9 | AV16: 0.913 | AW16: =AV16/AU16 -> 1.0144444 | AX16: 0.9 | AY16: 0.9892 | AZ16: 0.9 | BA16: 0.9511 | BB16: =BA16/AZ16 -> 1.0567778
B17: JAM | C17: 10000 | D17: 954 | E17: =D17/C17 -> 0.0954 | F17: 1.84 | G17: 0.79 | H17: =G17/F17 -> 0.42934783 | J17: BOL | K17: 0.85 | L17: 0.875 | M17: 1.0294118 | N17: 0.87 | O17: 0.941 | P17: 1.0816092 | S17: GUT | T17: 1.192 | U17: 1.2394842 | W17: HND | X17: 1.1839827 | Y17: 1.0662326 | AA17: BOL | AB17: 0.91089448 | AC17: 0.90588235 | AE17: BOL | AF17: 1 | AG17: 1 | AH17: =AVERAGE(AF17:AG17) -> 1 | AJ17: HND | AK17: 177.55 | AL17: 187.1 | AM17: =SUM(AK17:AL17) -> 364.65 | AN17: HND | AO17: 177 | AP17: 185 | AQ17: =SUM(AO17:AP17) -> 362 | AR17: =AQ17/AM17 -> 0.99273276 | AT17: BOL | AU17: 0.9 | AV17: 0.9752 | AW17: =AV17/AU17 -> 1.0835556 | AX17: 0.9 | AY17: 0.9552 | AZ17: 0.9 | BA17: 0.9652 | BB17: =BA17/AZ17 -> 1.0724444
B18: SRI | C18: - | D18: - | F18: 1.06 | G18: - | J18: MASSY | K18: 0.7 | L18: 0.515 | M18: 0.73571429 | N18: 0.88 | O18: 0.931 | P18: 1.0579545 | S18: NIC | T18: 1.201581 | U18: 1.4198637 | W18: NIC | X18: 1.2666667 | Y18: 1.027183 | AA18: MASSY | AB18: 1 | AC18: 0.92322792 | AE18: MASSY | AF18: 1 | AG18: 1 | AH18: =AVERAGE(AF18:AG18) -> 1 | AJ18: TRD | AK18: 42.2 | AL18: 56.4 | AM18: =SUM(AK18:AL18) -> 98.6 | AN18: TRD | AO18: 44 | AP18: 67 | AQ18: =SUM(AO18:AP18) -> 111 | AR18: =AQ18/AM18 -> 1.1257606 | AT18: MASSY | AU18: 0.9 | AV18: 0.9 | AW18: =AV18/AU18 -> 1 | AX18: 0.9 | AY18: 0.79 | AZ18: 0.9 | BA18: 0.845 | BB18: =BA18/AZ18 -> 0.93888889
B19: STK | C19: - | D19: - | F19: - | G19: 0.69 | S19: Gel Group | T19: 0.94117647 | U19: 1.1053876 | W19: ELS | X19: 1.1842105 | Y19: 1.0279605 | AA19: Gel Group | AB19: 1 | AC19: 0.35117205 | AE19: Gel Group | AF19: 0 | AG19: 1 | AH19: =AVERAGE(AF19:AG19) -> 0.5 | AT19: GEL | AU19: 0.9 | AV19: 0.6 | AW19: =AV19/AU19 -> 0.66666667 | AX19: 0.9 | AY19: 0.3 | AZ19: 0.9 | BA19: 0.45 | BB19: =BA19/AZ19 -> 0.5
B20: STL | C20: - | D20: 30576 | F20: 1.84 | G20: 0.59 | H20: =G20/F20 -> 0.32065217 | S20: 1 | T20: 2
B21: STV | C21: - | D21: - | F21: 1.82 | G21: - | J21: Market | K21: CSI | L21: SSI | M21: Sell In | N21: Retention | S21: NSC | T21: FY24
B22: TRD | C22: 1858 | D22: 60247 | E22: =D22/C22 -> 32.425727 | F22: 1.06 | G22: 1.03 | H22: =G22/F22 -> 0.97169811 | J22: COL | K22: 1.0076923 | L22: 1.0413043 | M22: =VLOOKUP(J22,$B$3:$H$34,$E$2,FALSE) -> 1.0297799 | N22: =VLOOKUP(J22,$B$3:$H$34,$H$2,FALSE) -> 1.030303 | S22: COL | T22: 0.98980082
B23: PNM | C23: 828368 | D23: 811997 | E23: =D23/C23 -> 0.98023704 | F23: 0.79 | G23: 0.8 | H23: =G23/F23 -> 1.0126582 | J23: PLT | K23: 1.0195122 | L23: 0.98021978 | M23: =VLOOKUP(J23,$B$3:$H$34,$E$2,FALSE) -> 0.95155751 | N23: =VLOOKUP(J23,$B$3:$H$34,$H$2,FALSE) -> 1.0116279 | S23: CST | T23: 1
B24: GUT | C24: 668932 | D24: 759770 | E24: =D24/C24 -> 1.1357956 | F24: 1.39 | G24: 1.38 | H24: =G24/F24 -> 0.99280576 | J24: CST | K24: 1.0326087 | L24: 1.0163043 | M24: =VLOOKUP(J24,$B$3:$H$34,$E$2,FALSE) -> 1.0488159 | N24: =VLOOKUP(J24,$B$3:$H$34,$H$2,FALSE) -> 1 | S24: ECA | T24: 0.96686117
B25: ELS | C25: 478187 | D25: 480955 | E25: =D25/C25 -> 1.0057885 | F25: 0.98 | G25: 0.9 | H25: =G25/F25 -> 0.91836735 | J25: ECA | K25: 1.0058824 | L25: 1.05 | M25: =VLOOKUP(J25,$B$3:$H$34,$E$2,FALSE) -> 1.0401367 | N25: =VLOOKUP(J25,$B$3:$H$34,$H$2,FALSE) -> 1.0194175 | S25: URU | T25: 0.9311047
B26: HND | C26: 603678 | D26: 620704 | E26: =D26/C26 -> 1.0282038 | F26: 1.13 | G26: 1.16 | H26: =G26/F26 -> 1.0265487 | J26: PNM | K26: 1.0011628 | L26: 1.0733333 | M26: =VLOOKUP(J26,$B$3:$H$34,$E$2,FALSE) -> 0.98023704 | N26: =VLOOKUP(J26,$B$3:$H$34,$H$2,FALSE) -> 1.0126582 | S26: BOL | T26: 0.9
B27: NIC | C27: 203700 | D27: 216452 | E27: =D27/C27 -> 1.0626019 | F27: 0.9 | G27: 0.99 | H27: =G27/F27 -> 1.1 | J27: URU | K27: 1.0531915 | L27: 1.0284211 | M27: =VLOOKUP(J27,$B$3:$H$34,$E$2,FALSE) -> 0.97245646 | N27: =VLOOKUP(J27,$B$3:$H$34,$H$2,FALSE) -> 0.98823529 | S27: PRG | T27: 0.99989691
B28: ALB | C28: 72878 | D28: 67853 | E28: =D28/C28 -> 0.93104915 | F28: - | G28: - | J28: ELS | K28: 1.0914286 | L28: 1.146988 | M28: =VLOOKUP(J28,$B$3:$H$34,$E$2,FALSE) -> 1.0057885 | N28: =VLOOKUP(J28,$B$3:$H$34,$H$2,FALSE) -> 0.91836735 | S28: GUT | T28: 0.86477083
B29: BLZ | C29: 28542 | D29: 32786 | E29: =D29/C29 -> 1.1486932 | F29: - | G29: - | J29: HND | K29: 0.86571429 | L29: 1.2048193 | M29: =VLOOKUP(J29,$B$3:$H$34,$E$2,FALSE) -> 1.0282038 | N29: =VLOOKUP(J29,$B$3:$H$34,$H$2,FALSE) -> 1.0265487 | S29: PNM | T29: 0.91
B30: CUR | C30: 84691 | D30: 80745 | E30: =D30/C30 -> 0.95340709 | F30: - | G30: - | J30: NIC | K30: 0.84857143 | L30: 1.0951807 | M30: =VLOOKUP(J30,$B$3:$H$34,$E$2,FALSE) -> 1.0626019 | N30: =VLOOKUP(J30,$B$3:$H$34,$H$2,FALSE) -> 1.1 | S30: PLT | T30: 0.98132093
B31: DOM | C31: 864939 | D31: 837346 | E31: =D31/C31 -> 0.96809833 | F31: 1.51 | G31: 1.41 | H31: =G31/F31 -> 0.93377483 | J31: DOM | K31: 1.1742857 | L31: 1.0681818 | M31: =VLOOKUP(J31,$B$3:$H$34,$E$2,FALSE) -> 0.96809833 | N31: =VLOOKUP(J31,$B$3:$H$34,$H$2,FALSE) -> 0.93377483 | S31: DOM | T31: 0.94524218
B32: HIT | C32: 111350 | D32: 107487 | E32: =D32/C32 -> 0.96530759 | F32: 0.51 | G32: - | J32: GUT | K32: 1.024 | L32: 0.96385542 | M32: =VLOOKUP(J32,$B$3:$H$34,$E$2,FALSE) -> 1.1357956 | N32: =VLOOKUP(J32,$B$3:$H$34,$H$2,FALSE) -> 0.99280576 | S32: ELS | T32: 0.97207403
B33: PLT | C33: 692099 | D33: 658572 | E33: =D33/C33 -> 0.95155751 | F33: 0.86 | G33: 0.87 | H33: =G33/F33 -> 1.0116279 | J33: PRG | K33: 1.0857143 | L33: 1.0488889 | M33: =VLOOKUP(J33,$B$3:$H$34,$E$2,FALSE) -> 0.90039765 | N33: =VLOOKUP(J33,$B$3:$H$34,$H$2,FALSE) -> 1.1496063 | S33: HND | T33: 0.97973452
B34: CST | C34: 1659419 | D34: 1740425 | E34: =D34/C34 -> 1.0488159 | F34: 1.32 | G34: 1.32 | H34: =G34/F34 -> 1 | J34: BOL | K34: 1.0294118 | L34: 1.0816092 | M34: =VLOOKUP(J34,$B$3:$H$34,$E$2,FALSE) -> 0.91089448 | N34: =VLOOKUP(J34,$B$3:$H$34,$H$2,FALSE) -> 0.90588235 | S34: NIC | T34: 0.93991572
J35: MASSY | K35: 0.73571429 | L35: 1.0579545 | M35: 1 | N35: 0.92322792 | S35: Gel Group | T35: 0.48232272
B36: Massy | C36: =SUM(C44:C53) -> 1858 | D36: =SUM(D44:D53) -> 60247 | E36: =D36/C36 -> 32.425727 | J36: Gel | K36: - | L36: - | M36: 1 | N36: 0.35117205 | S36: Massy Group | T36: 0.63392386
B37: Gel | C37: =SUM(C40:C43) -> 10000 | D37: =SUM(D40:D43) -> 31881 | E37: =D37/C37 -> 3.1881
C39: Target Sell IN | D39: Real Sell In | E39: Target Retention | F39: Real Retention | G39: OR Target | H39: OR real | I39: UIO | J39: UIO Real
B40: BAR | C40: =VLOOKUP(B40,$B$3:$H$34,$C$2,FALSE) -> - | D40: =VLOOKUP(B40,$B$3:$H$34,$D$2,FALSE) -> 351 | E40: =VLOOKUP(B40,$B$3:$H$34,$F$2,FALSE) -> 1.84 | F40: =VLOOKUP(B40,$B$3:$H$34,$G$2,FALSE) -> 0.5 | G40: =VLOOKUP($B$40,$B$56:$F$87,C55,FALSE) -> 669 | H40: =VLOOKUP(B40,$B$56:$F$87,$D$55,FALSE) -> 180 | I40: =VLOOKUP(B40,$B$56:$F$87,$E$55,FALSE) -> 363 | J40: =VLOOKUP(B40,$B$56:$F$87,$F$55,FALSE) -> 363
B41: JAM | C41: =VLOOKUP(B41,$B$3:$H$34,$C$2,FALSE) -> 10000 | D41: =VLOOKUP(B41,$B$3:$H$34,$D$2,FALSE) -> 954 | E41: =VLOOKUP(B41,$B$3:$H$34,$F$2,FALSE) -> 1.84 | F41: =VLOOKUP(B41,$B$3:$H$34,$G$2,FALSE) -> 0.79 | G41: =VLOOKUP(B41,$B$56:$F$87,$C$55,FALSE) -> 1233 | H41: =VLOOKUP(B41,$B$56:$F$87,$D$55,FALSE) -> 531 | I41: =VLOOKUP(B41,$B$56:$F$87,$E$55,FALSE) -> 670 | J41: =VLOOKUP(B41,$B$56:$F$87,$F$55,FALSE) -> 670
B42: STL | C42: =VLOOKUP(B42,$B$3:$H$34,$C$2,FALSE) -> - | D42: =VLOOKUP(B42,$B$3:$H$34,$D$2,FALSE) -> 30576 | E42: =VLOOKUP(B42,$B$3:$H$34,$F$2,FALSE) -> 1.84 | F42: =VLOOKUP(B42,$B$3:$H$34,$G$2,FALSE) -> 0.59 | G42: =VLOOKUP(B42,$B$56:$F$87,$C$55,FALSE) -> 259 | H42: =VLOOKUP(B42,$B$56:$F$87,$D$55,FALSE) -> 83 | I42: =VLOOKUP(B42,$B$56:$F$87,$E$55,FALSE) -> 141 | J42: =VLOOKUP(B42,$B$56:$F$87,$F$55,FALSE) -> 141
...

Sheet OR Q2
B2: 1 | C2: 2 | D2: 3 | E2: 4 | F2: 5 | G2: 6 | H2: 7 | AB2: 1 | AC2: 2 | AD2: 3 | AE2: 4
B3: NSC | C3: Target Sell-In | D3: Total Sell-In Real | E3: % Achi. Sell In | F3: Service Frequency | G3: Service Frequency Real | H3: %Achi, Retention | I3: Total Repair Orders | J3: Total Repair Orders Real | K3: UIO | AB3: NSC | AC3: Mercado | AD3: Target | AE3: Real Sales | AG3: NSC | AH3: Mercado | AI3: Real PV | AL3: 1 | AM3: 2
M4: NSC | N4: APR | O4: MAY | P4: JUN | Q4: JUL | R4: FYTD | T4: NSC | U4: APR | V4: MAY | W4: JUN | X4: JUL | Y4: FYTD | AB4: ANT | AC4: ANTIGUA (DIS25D07) | AD4: 0.9 | AE4: 1 | AG4: ANT | AH4: ANTIGUA (DIS25D07) | AI4: 0.43529412 | AL4: Market | AM4: TR
B5: COL | C5: 4794458 | D5: 4975969 | E5: =D5/C5 -> 1.0378585 | F5: 0.99 | G5: 1.05 | H5: =G5/F5 -> 1.0606061 | I5: 47909 | J5: 50688 | K5: 48269 | M5: ECA | N5: 463.16667 | O5: 523.33333 | P5: 583.5 | Q5: 643.66667 | R5: =SUM(N5:Q5) -> 2213.6667 | T5: BAR | U5: 84.633333 | V5: 88.266667 | W5: 91.9 | X5: 95.533333 | Y5: =SUM(U5:X5) -> 360.33333 | AB5: ALB | AC5: ARUBA (DIS25D17) | AD5: 0.9 | AE5: 1 | AG5: ALB | AH5: ARUBA (DIS25D17) | AI5: 0.83783784 | AL5: COL | AM5: 0.96701656
B6: BOL | C6: 700043 | D6: 624524 | E6: =D6/C6 -> 0.89212234 | F6: 0.86 | G6: 0.81 | H6: =G6/F6 -> 0.94186047 | I6: 5594 | J6: 5258 | K6: 6490 | M6: CST | N6: 877.72917 | O6: 965.45833 | P6: 1053.1875 | Q6: 1140.9167 | R6: =SUM(N6:Q6) -> 4037.2917 | T6: JAM | U6: 23.65 | V6: 30.3 | W6: 36.95 | X6: 43.6 | Y6: =SUM(U6:X6) -> 134.5 | AB6: BHM | AC6: BAHAMAS (DIS25D13) | AD6: 0.9 | AE6: 1 | AG6: BHM | AH6: BAHAMAS (DIS25D13) | AI6: 0.34163701 | AL6: PLT
B7: ECA | C7: 1260252 | D7: 1250021 | E7: =D7/C7 -> 0.99188178 | F7: 1.03 | G7: 1.05 | H7: =G7/F7 -> 1.0194175 | I7: 9577 | J7: 9730 | K7: 9272 | M7: URU | N7: 1938.3125 | O7: 2000.625 | P7: 2062.9375 | Q7: 2125.25 | R7: =SUM(N7:Q7) -> 8127.125 | T7: STL | U7: 1.1083333 | V7: 2.2166667 | W7: 3.325 | X7: 4.4333333 | Y7: =SUM(U7:X7) -> 11.083333 | AB7: BAR | AC7: BARBADOS (DIS25D04) | AD7: 0.9 | AE7: 0.42857143 | AG7: BAR | AH7: BARBADOS (DIS25D04) | AI7: 0.10422164 | AL7: CST | AM7: 1.1111111
B8: PRG | C8: 1264567 | D8: 1122863 | E8: =D8/C8 -> 0.88794267 | F8: 1.27 | G8: 1.14 | H8: =G8/F8 -> 0.8976378 | I8: 6124 | J8: 5511 | K8: 4820 | M8: COL | N8: 5003.7167 | O8: 5239.4333 | P8: 5475.15 | Q8: 5710.8667 | R8: =SUM(N8:Q8) -> 21429.167 | T8: STV | U8: 0.9125 | V8: 1.825 | W8: 2.7375 | X8: 3.65 | Y8: =SUM(U8:X8) -> 9.125 | AB8: BER | AC8: BERMUDA (DIS25D11) | AD8: 0.9 | AE8: 1 | AG8: BLZ | AH8: BELIZE (DIS25D18) | AI8: 0.53551913 | AL8: ECA | AM8: 1.0637912
B9: URU | C9: 926654 | D9: 894183 | E9: =D9/C9 -> 0.96495887 | F9: 0.85 | G9: 0.84 | H9: =G9/F9 -> 0.98823529 | I9: 6557 | J9: 6508 | K9: 7744 | M9: PLT | N9: 1782.0683 | O9: 1873.1367 | P9: 1964.205 | Q9: 2055.2733 | R9: =SUM(N9:Q9) -> 7674.6833 | AB9: BOL | AC9: Bolivia | AD9: 0.9 | AE9: 1 | AG9: BOL | AH9: Bolivia | AI9: 0.96668581 | AL9: PNM | AM9: 1.1111111
B10: ANT | F10: 1.04 | G10: 1.66 | H10: =G10/F10 -> 1.5961538 | I10: 355 | J10: 567 | K10: 342 | M10: PNM | N10: 422.73333 | O10: 441.46667 | P10: 460.2 | Q10: 478.93333 | R10: =SUM(N10:Q10) -> 1803.3333 | T10: NSC | U10: APR | V10: MAY | W10: JUN | X10: JUL | Y10: FYTD | AB10: COL | AC10: Colombia | AD10: 0.9 | AE10: 0.99531465 | AG10: COL | AH10: Colombia | AI10: 0.8406298 | AL10: URU | AM10: 1.0069077
B11: BAR | D11: 540 | F11: 2.08 | G11: 1.7 | H11: =G11/F11 -> 0.81730769 | I11: 1009 | J11: 824 | K11: 484 | M11: BOL | N11: 476.79583 | O11: 493.59167 | P11: 510.3875 | Q11: 527.18333 | R11: =SUM(N11:Q11) -> 2007.9583 | T11: BAR | U11: 85 | V11: 90 | W11: 91 | X11: 91 | Y11: =SUM(U11:X11) -> 357 | AB11: CST | AC11: Costa Rica | AD11: 0.9 | AE11: 1 | AG11: CST | AH11: Costa Rica | AI11: 1 | AL11: ELS | AM11: 1.0857092
B12: BEM | F12: 1.2 | G12: - | I12: 57 | K12: 47 | M12: PRG | N12: 348.1 | O12: 362.2 | P12: 376.3 | Q12: 390.4 | R12: =SUM(N12:Q12) -> 1477 | T12: JAM | U12: 19 | V12: 29 | W12: 37 | X12: 37 | Y12: =SUM(U12:X12) -> 122 | AB12: CUR | AC12: CURAZAO (DIS25D14) | AD12: 0.9 | AE12: 1 | AG12: CUR | AH12: CURAZAO (DIS25D14) | AI12: 1 | AL12: HND | AM12: 1.0987458
B13: BHM | F13: 1.04 | G13: 0.4 | H13: =G13/F13 -> 0.38461538 | I13: 351 | J13: 134 | K13: 339 | M13: NIC | N13: 93.225 | O13: 98.45 | P13: 103.675 | Q13: 108.9 | R13: =SUM(N13:Q13) -> 404.25 | T13: STL | U13: 0 | V13: 0 | W13: 0 | X13: 0 | Y13: =SUM(U13:X13) -> 0 | AB13: DMT | AC13: DOMINICA (DIS25D12) | AD13: 0.9 | AE13: 1 | AG13: DMT | AH13: DOMINICA (DIS25D12) | AI13: 1 | AL13: NIC | AM13: 1.0716166
B14: DMT | F14: 1.04 | G14: - | I14: 153 | K14: 146 | M14: ELS | N14: 183.82917 | O14: 196.65833 | P14: 209.4875 | Q14: 222.31667 | R14: =SUM(N14:Q14) -> 812.29167 | T14: STV | U14: 0 | V14: 0 | W14: 0 | X14: 0 | Y14: =SUM(U14:X14) -> 0 | AB14: ECA | AC14: Ecuador | AD14: 0.9 | AE14: 0.95864198 | AG14: ECA | AH14: Ecuador | AI14: 0.95618221 | AL14: DOM | AM14: 1.1111111
B15: GRN | F15: 1.04 | G15: 2.99 | H15: =G15/F15 -> 2.875 | I15: 158 | J15: 455 | K15: 152 | M15: GUT | N15: 103.07917 | O15: 121.15833 | P15: 139.2375 | Q15: 157.31667 | R15: =SUM(N15:Q15) -> 520.79167 | AB15: ELS | AC15: El Salvador | AD15: 0.9 | AE15: 0.96428571 | AG15: ELS | AH15: El Salvador | AI15: 0.9899909 | AL15: GUT | AM15: 0.99721559
B16: GUI | F16: 1.04 | G16: 0.28 | H16: =G16/F16 -> 0.26923077 | I16: 306 | J16: 83 | K16: 293 | M16: DOM | N16: 416.0375 | O16: 425.075 | P16: 434.1125 | Q16: 443.15 | R16: =SUM(N16:Q16) -> 1718.375 | T16: GEL | U16: =SUM(Y5:Y8) -> 515.04167 | V16: =SUM(Y11:Y14) -> 479 | W16: =V16/U16 -> 0.93002184 | AB16: GRN | AC16: GRENADA (DIS25D08) | AD16: 0.9 | AE16: 1 | AG16: GRN | AH16: GRENADA (DIS25D08) | AI16: 0.71311475 | AL16: PRG | AM16: 0.96666667
B17: JAM | C17: 20000 | D17: 954 | E17: =D17/C17 -> 0.0477 | F17: 2.08 | G17: 2.5 | H17: =G17/F17 -> 1.2019231 | I17: 1860 | J17: 2235 | K17: 894 | M17: HND | N17: 177.55 | O17: 187.1 | P17: 196.65 | Q17: 206.2 | R17: =SUM(N17:Q17) -> 767.5 | T17: target | U17: 0.28428909 | V17: 0.31600086 | W17: 0.34771263 | X17: 0.3794244 | AB17: GUT | AC17: Guatemala | AD17: 0.9 | AE17: 1 | AG17: GUT | AH17: Guatemala | AI17: 0.89498807 | AL17: BOL | AM17: 1.0926032
B18: SRI | F18: 1.04 | G18: - | I18: 244 | K18: 235 | M18: TRD | N18: 42.2 | O18: 56.4 | P18: 70.6 | Q18: 84.8 | R18: =SUM(N18:Q18) -> 254 | T18: real | U18: 0.26804124 | V18: 0.30670103 | W18: 0.32989691 | X18: 0.32989691 | Y18: =X18/X17 -> 0.86946677 | AB18: GUI | AC18: GUYANA (DIS25D15) | AD18: 0.9 | AE18: 1 | AG18: GUI | AH18: GUYANA (DIS25D15) | AI18: 1 | AL18: MASSY
B19: STK | G19: 0.82 | J19: 100 | K19: 123 | AB19: HND | AC19: Honduras | AD19: 0.9 | AE19: 1 | AG19: HIT | AH19: HAITI (DIS25D03) | AI19: 0.0035587189 | AL19: GEL
B20: STL | D20: 30934 | F20: 2.09 | G20: 2.73 | H20: =G20/F20 -> 1.3062201 | I20: 391 | J20: 511 | K20: 187 | AB20: JAM | AC20: JAMAICA (DIS25D02) | AD20: 0.9 | AE20: 0.89393939 | AG20: HND | AH20: Honduras | AI20: 0.97774245
B21: STV | F21: 2.06 | G21: - | I21: 151 | K21: 73 | M21: 1 | N21: 2 | O21: 3 | P21: 4 | Q21: 5 | R21: 6 | S21: 7 | AB21: NIC | AC21: Nicaragua | AD21: 0.9 | AE21: 1 | AG21: JAM | AH21: JAMAICA (DIS25D02) | AI21: 0.58857143
B22: TRD | C22: 51858 | D22: 108093 | E22: =D22/C22 -> 2.0844036 | F22: 1.04 | G22: 1.06 | H22: =G22/F22 -> 1.0192308 | I22: 4361 | J22: 4424 | K22: 4192 | M22: NSC | N22: APR | O22: MAY | P22: JUN | Q22: JUL | R22: FYTD | S22: %Achiev. | U22: NSC | V22: APR | W22: MAY | X22: JUN | Y22: JUL | Z22: FYTD | AB22: PNM | AC22: Panama | AD22: 0.9 | AE22: 1 | AG22: NIC | AH22: Nicaragua | AI22: 0.92890995
B23: PNM | C23: 1219414 | D23: 1097794 | E23: =D23/C23 -> 0.90026357 | F23: 0.8 | G23: 0.8 | H23: =G23/F23 -> 1 | I23: 10564 | J23: 10667 | K23: 13255 | M23: ECA | N23: 509 | O23: 677 | P23: 905 | Q23: 1203 | R23: =SUM(N23:Q23) -> 3294 | S23: =R23/R5 -> 1.4880289 | U23: TRD | V23: 42.2 | W23: 56.4 | X23: 70.6 | Y23: 84.8 | Z23: =SUM(V23:Y23) -> 254 | AB23: PRG | AC23: Paraguay | AD23: 0.9 | AE23: 0.84 | AG23: PNM | AH23: Panama | AI23: 1
B24: GUT | C24: 839105 | D24: 1055311 | E24: =D24/C24 -> 1.2576626 | F24: 1.39 | G24: 1.37 | H24: =G24/F24 -> 0.98561151 | I24: 7308 | J24: 7188 | K24: 5250 | M24: CST | N24: 927 | O24: 1087 | P24: 1270 | Q24: 1513 | R24: =SUM(N24:Q24) -> 4797 | S24: =R24/R6 -> 1.1881728 | U24: ANT | V24: 1.7458333 | W24: 3.4916667 | X24: 5.2375 | Y24: 6.9833333 | Z24: =SUM(V24:Y24) -> 17.458333 | AB24: DOM | AC24: República Dominicana | AD24: 0.9 | AE24: 1 | AG24: PRG | AH24: Paraguay | AI24: 0.98919308
B25: ELS | C25: 715634 | D25: 736938 | E25: =D25/C25 -> 1.0297694 | F25: 1.01 | G25: 0.93 | H25: =G25/F25 -> 0.92079208 | I25: 5470 | J25: 5013 | K25: 5391 | M25: URU | N25: 1943 | O25: 2108 | P25: 2213 | Q25: 2293 | R25: =SUM(N25:Q25) -> 8557 | S25: =R25/R7 -> 1.0528939 | U25: BHM | V25: 1.125 | W25: 2.25 | X25: 3.375 | Y25: 4.5 | Z25: =SUM(V25:Y25) -> 11.25 | AB25: STK | AC25: ST KITTS (DIS25D09) | AD25: 0.9 | AE25: 0.6 | AG25: DOM | AH25: República Dominicana | AI25: 1
B26: HND | C26: 839768 | D26: 927163 | E26: =D26/C26 -> 1.1040704 | F26: 1.16 | G26: 1.19 | H26: =G26/F26 -> 1.0258621 | I26: 6904 | J26: 7079 | K26: 5934 | M26: COL | N26: 4904 | O26: 5324 | P26: 5807 | Q26: 6100 | R26: =SUM(N26:Q26) -> 22135 | S26: =R26/R8 -> 1.032938 | U26: DMT | V26: 1.0833333 | W26: 1.1666667 | X26: 1.25 | Y26: 1.3333333 | Z26: =SUM(V26:Y26) -> 4.8333333 | AB26: STL | AC26: ST LUCIA (DIS25D05) | AD26: 0.9 | AE26: 1 | AG26: STK | AH26: ST KITTS (DIS25D09) | AI26: 0.28470588
B27: NIC | C27: 287298 | D27: 329937 | E27: =D27/C27 -> 1.1484138 | F27: 0.92 | G27: 1.03 | H27: =G27/F27 -> 1.1195652 | I27: 2216 | J27: 2482 | K27: 2413 | M27: PLT | N27: 1734 | O27: 1801 | P27: 1891 | Q27: 1967 | R27: =SUM(N27:Q27) -> 7393 | S27: =R27/R9 -> 0.96329707 | U27: GRN | V27: 0.4875 | W27: 0.975 | X27: 1.4625 | Y27: 1.95 | Z27: =SUM(V27:Y27) -> 4.875 | AB27: SRI | AC27: SURINAME (DIS25D10) | AD27: 0.9 | AE27: 1 | AG27: STL | AH27: ST LUCIA (DIS25D05) | AI27: 0.21100917
B28: ALB | C28: 98878 | D28: 93056 | E28: =D28/C28 -> 0.94111936 | F28: - | G28: - | I28: - | J28: - | K28: 634 | M28: PNM | N28: 442 | O28: 495 | P28: 566 | Q28: 626 | R28: =SUM(N28:Q28) -> 2129 | S28: =R28/R10 -> 1.1805915 | U28: SRI | V28: 2.2916667 | W28: 4.5833333 | X28: 6.875 | Y28: 9.1666667 | Z28: =SUM(V28:Y28) -> 22.916667 | AB28: TRD | AC28: TRINIDAD Y TOBAGO (DIS25D01) | AD28: 0.9 | AE28: 0.96969697 | AG28: SRI | AH28: SURINAME (DIS25D10) | AI28: 1
B29: BLZ | C29: 33542 | D29: 40836 | E29: =D29/C29 -> 1.2174587 | F29: - | G29: - | I29: - | J29: - | K29: 152 | M29: BOL | N29: 471 | O29: 480 | P29: 487 | Q29: 491 | R29: =SUM(N29:Q29) -> 1929 | S29: =R29/R11 -> 0.9606773 | U29: STK | V29: 0.67083333 | W29: 1.3416667 | X29: 2.0125 | Y29: 2.6833333 | Z29: =SUM(V29:Y29) -> 6.7083333 | AB29: URU | AC29: Uruguay | AD29: 0.9 | AE29: 0.90604575 | AG29: TRD | AH29: TRINIDAD Y TOBAGO (DIS25D01) | AI29: 1
B30: CUR | C30: 99691 | D30: 97601 | E30: =D30/C30 -> 0.97903522 | F30: - | G30: - | I30: - | J30: - | K30: 747 | M30: PRG | N30: 336 | O30: 360 | P30: 407 | Q30: 434 | R30: =SUM(N30:Q30) -> 1537 | S30: =R30/R12 -> 1.0406229 | AG30: URU | AH30: Uruguay | AI30: 0.90638811
B31: DOM | C31: 1139939 | D31: 1120886 | E31: =D31/C31 -> 0.98328595 | F31: 1.51 | G31: 1.43 | H31: =G31/F31 -> 0.94701987 | I31: 9271 | J31: 8821 | K31: 6160 | M31: NIC | N31: 88 | O31: 90 | P31: 90 | Q31: 94 | R31: =SUM(N31:Q31) -> 362 | S31: =R31/R13 -> 0.89548547 | U31: NSC | V31: APR | W31: MAY | X31: JUN | Y31: JUL | Z31: FYTD | AB31: GEL | AC31: 0.9 | AD31: =(AE7+AE20+AE26)/3 -> 0.77417027 | AG31: GEL | AI31: =(AI7+AI21+AI27)/3 -> 0.30126741
B32: HIT | C32: 121350 | D32: 126221 | E32: =D32/C32 -> 1.0401401 | F32: 0.51 | G32: - | I32: 522 | J32: - | K32: 1028 | M32: ELS | N32: 178 | O32: 201 | P32: 219 | Q32: 234 | R32: =SUM(N32:Q32) -> 832 | S32: =R32/R14 -> 1.0242626 | U32: TRD | V32: 44 | W32: 67 | X32: 82 | Y32: 102 | Z32: =SUM(V32:Y32) -> 295 | AB32: MASSY | AC32: 0.9 | AD32: =(AE5+AE6+AE8+AE13+AE16+AE18+AE25+AE27+AE28)/9 -> 0.95218855 | AG32: MASSY | AI32: =(AI4+AI6+AI13+AI16+AI18+AI26+AI28+AI29)/8 -> 0.72184397
B33: PLT | C33: 954157 | D33: 816571 | E33: =D33/C33 -> 0.8558036 | F33: 0.86 | G33: 0.86 | H33: =G33/F33 -> 1 | I33: 23664 | J33: 23908 | K33: 27658 | M33: GUT | N33: 91 | O33: 97 | P33: 107 | Q33: 139 | R33: =SUM(N33:Q33) -> 434 | S33: =R33/R15 -> 0.83334667 | U33: ANT | V33: 0 | W33: 0 | X33: 0 | Y33: 0 | Z33: =SUM(V33:Y33) -> 0
B34: CST | C34: 2209419 | D34: 2416855 | E34: =D34/C34 -> 1.0938871 | F34: 1.32 | G34: 1.32 | H34: =G34/F34 -> 1 | I34: 18840 | J34: 18895 | K34: 14320 | M34: DOM | N34: 414 | O34: 421 | P34: 438 | Q34: 462 | R34: =SUM(N34:Q34) -> 1735 | S34: =R34/R16 -> 1.0096748 | U34: BHM | V34: 0 | W34: 0 | X34: 0 | Y34: 0 | Z34: =SUM(V34:Y34) -> 0
M35: HND | N35: 177 | O35: 185 | P35: 191 | Q35: 197 | R35: =SUM(N35:Q35) -> 750 | S35: =R35/R17 -> 0.9771987 | U35: DMT | V35: 1 | W35: 1 | X35: 1 | Y35: 1 | Z35: =SUM(V35:Y35) -> 4
B36: GEL | C36: =C11+C17+C20+C21 -> 20000 | D36: =D11+D17+D20+D21 -> 32428 | E36: =D36/C36 -> 1.6214 | F36: =I36/K36 -> 2.0824176 | G36: =J36/K36 -> 2.1794872 | H36: =G36/F36 -> 1.0466139 | I36: =I11+I17+I20+I21 -> 3411 | J36: =J11+J17+J20+J21 -> 3570 | K36: =K11+K17+K20+K21 -> 1638 | M36: TRD | N36: 44 | O36: 67 | P36: 82 | Q36: 102 | R36: =SUM(N36:Q36) -> 295 | S36: =R36/R18 -> 1.1614173 | U36: GRN | V36: 0 | W36: 0 | X36: 0 | Y36: 0 | Z36: =SUM(V36:Y36) -> 0
B37: MASSY | C37: =C10+C12+C13+C14+C15+C16+C18+C19+C22 -> 51858 | D37: =D10+D12+D13+D14+D15+D16+D18+D19+D22 -> 108093 | E37: =D37/C37 -> 2.0844036 | F37: =I37/K37 -> 1.0197649 | G37: =J37/K37 -> 0.981939 | H37: =G37/F37 -> 0.96290727 | I37: =I10+I12+I13+I14+I15+I16+I18+I19+I22 -> 5985 | J37: =J10+J12+J13+J14+J15+J16+J18+J19+J22 -> 5763 | K37: =K10+K12+K13+K14+K15+K16+K18+K19+K22 -> 5869 | U37: SRI | V37: 0 | W37: 0 | X37: 0 | Y37: 0 | Z37: =SUM(V37:Y37) -> 0
U38: STK | V38: 0 | W38: 0 | X38: 0 | Y38: 0 | Z38: =SUM(V38:Y38) -> 0
B40: Grafica Retention vs Sell In FYTD JUL
B41: 1 | C41: 2 | D41: 3 | E41: 4 | U41: TRD | V41: =Z23 -> 254 | W41: =Z32 -> 295 | X41: 1.1010101 | Y41: =IF(X41>=100%,75%,(X41*75%/100%)) -> 0.75
B42: NSC | C42: Retention | D42: Sell In | E42: Weigth | G42: NSC | H42: Target CSI | I42: CSI | J42: % Achiev. | K42: Target SSI | L42: SSI | M42: % Achiev. | U42: R9 | V42: =SUM(Z24:Z29) -> 68.041667 | W42: =SUM(Z33:Z38) -> 4 | X42: 0.037570445 | Y42: =IF(X42>=100%,25%,(X42*25%/100%)) -> 0.0093926111
...

Sheet AP25JUL
B3: Market | C3: CSI | D3: SSI | E3: NRC | F3: Training | G3: Ser. Campaign | H3: Lead Mng. | I3: Share of Inv. | J3: Game Plan | K3: Sell In | L3: Retention | M3: Retail Sales
B4: COL | C4: =VLOOKUP(B4,'OR Q2'!$G$61:$J$75,'OR Q2'!$H$60,FALSE) -> 1.0166667 | D4: =VLOOKUP(B4,'OR Q2'!$G$61:$J$75,'OR Q2'!$I$60,FALSE) -> 1.0413043 | E4: 1 | F4: 0.96701656 | G4: =VLOOKUP(B4,'OR Q2'!$M$22:$S$36,'OR Q2'!$S$21,FALSE) -> 1.032938 | H4: 1 | I4: 1 | J4: 1 | K4: =VLOOKUP(B4,'OR Q2'!$B$42:$E$57,'OR Q2'!$D$41,FALSE) -> 1.0378585 | L4: =VLOOKUP(B4,'OR Q2'!$B$42:$E$57,'OR Q2'!$C$41,FALSE) -> 1.0606061 | M4: 1.0923829
B5: PLT | C5: =VLOOKUP(B5,'OR Q2'!$G$61:$J$75,'OR Q2'!$H$60,FALSE) -> 1.0329268 | D5: =VLOOKUP(B5,'OR Q2'!$G$61:$J$75,'OR Q2'!$I$60,FALSE) -> 1.0010989 | E5: 1 | F5: 0 | G5: =VLOOKUP(B5,'OR Q2'!$M$22:$S$36,'OR Q2'!$S$21,FALSE) -> 0.96329707 | H5: 0.5 | I5: 1 | J5: 1 | K5: =VLOOKUP(B5,'OR Q2'!$B$42:$E$57,'OR Q2'!$D$41,FALSE) -> 0.8558036 | L5: =VLOOKUP(B5,'OR Q2'!$B$42:$E$57,'OR Q2'!$C$41,FALSE) -> 1 | M5: 0.86360399
B6: CST | C6: =VLOOKUP(B6,'OR Q2'!$G$61:$J$75,'OR Q2'!$H$60,FALSE) -> 1.0304348 | D6: =VLOOKUP(B6,'OR Q2'!$G$61:$J$75,'OR Q2'!$I$60,FALSE) -> 1.0184783 | E6: 1 | F6: 1.1111111 | G6: =VLOOKUP(B6,'OR Q2'!$M$22:$S$36,'OR Q2'!$S$21,FALSE) -> 1.1881728 | H6: 1 | I6: 1 | J6: 1 | K6: =VLOOKUP(B6,'OR Q2'!$B$42:$E$57,'OR Q2'!$D$41,FALSE) -> 1.0938871 | L6: =VLOOKUP(B6,'OR Q2'!$B$42:$E$57,'OR Q2'!$C$41,FALSE) -> 1 | M6: 1.0946695
B7: ECA | C7: =VLOOKUP(B7,'OR Q2'!$G$61:$J$75,'OR Q2'!$H$60,FALSE) -> 1.0152941 | D7: =VLOOKUP(B7,'OR Q2'!$G$61:$J$75,'OR Q2'!$I$60,FALSE) -> 1.0553191 | E7: 1 | F7: 1.0637912 | G7: =VLOOKUP(B7,'OR Q2'!$M$22:$S$36,'OR Q2'!$S$21,FALSE) -> 1.4880289 | H7: 1 | I7: 1 | J7: 1 | K7: =VLOOKUP(B7,'OR Q2'!$B$42:$E$57,'OR Q2'!$D$41,FALSE) -> 0.99188178 | L7: =VLOOKUP(B7,'OR Q2'!$B$42:$E$57,'OR Q2'!$C$41,FALSE) -> 1.0194175 | M7: 1.1082803
B8: PNM | C8: 1.022 | D8: 1.084 | E8: 1 | F8: 1.0957 | G8: 1.044 | H8: 1 | I8: 1 | J8: 1 | K8: 0.834 | L8: 1.039 | M8: 0.828
B9: URU | C9: =VLOOKUP(B9,'OR Q2'!$G$61:$J$75,'OR Q2'!$H$60,FALSE) -> 1.0542553 | D9: =VLOOKUP(B9,'OR Q2'!$G$61:$J$75,'OR Q2'!$I$60,FALSE) -> 1.0326316 | E9: 1 | F9: 1.0069077 | G9: =VLOOKUP(B9,'OR Q2'!$M$22:$S$36,'OR Q2'!$S$21,FALSE) -> 1.0528939 | H9: 1 | I9: 1 | J9: 1 | K9: =VLOOKUP(B9,'OR Q2'!$B$42:$E$57,'OR Q2'!$D$41,FALSE) -> 0.96495887 | L9: =VLOOKUP(B9,'OR Q2'!$B$42:$E$57,'OR Q2'!$C$41,FALSE) -> 0.98823529 | M9: 0.96616541
B10: ELS | C10: =VLOOKUP(B10,'OR Q2'!$G$61:$J$75,'OR Q2'!$H$60,FALSE) -> 1.1014286 | D10: =VLOOKUP(B10,'OR Q2'!$G$61:$J$75,'OR Q2'!$I$60,FALSE) -> 1.1554217 | E10: 1 | F10: 1.0857092 | G10: =VLOOKUP(B10,'OR Q2'!$M$22:$S$36,'OR Q2'!$S$21,FALSE) -> 1.0242626 | H10: 1 | I10: 1 | J10: 1 | K10: =VLOOKUP(B10,'OR Q2'!$B$42:$E$57,'OR Q2'!$D$41,FALSE) -> 1.0297694 | L10: =VLOOKUP(B10,'OR Q2'!$B$42:$E$57,'OR Q2'!$C$41,FALSE) -> 0.92079208 | M10: 0.90266667
B11: HND | C11: =VLOOKUP(B11,'OR Q2'!$G$61:$J$75,'OR Q2'!$H$60,FALSE) -> 0.89142857 | D11: =VLOOKUP(B11,'OR Q2'!$G$61:$J$75,'OR Q2'!$I$60,FALSE) -> 1.2048193 | E11: 1 | F11: 1.0987458 | G11: =VLOOKUP(B11,'OR Q2'!$M$22:$S$36,'OR Q2'!$S$21,FALSE) -> 0.9771987 | H11: 1 | I11: 1 | J11: 1 | K11: =VLOOKUP(B11,'OR Q2'!$B$42:$E$57,'OR Q2'!$D$41,FALSE) -> 1.1040704 | L11: =VLOOKUP(B11,'OR Q2'!$B$42:$E$57,'OR Q2'!$C$41,FALSE) -> 1.0258621 | M11: 0.91381346
B12: NIC | C12: =VLOOKUP(B12,'OR Q2'!$G$61:$J$75,'OR Q2'!$H$60,FALSE) -> 0.80714286 | D12: =VLOOKUP(B12,'OR Q2'!$G$61:$J$75,'OR Q2'!$I$60,FALSE) -> 1.1048193 | E12: 1 | F12: 1.0716166 | G12: =VLOOKUP(B12,'OR Q2'!$M$22:$S$36,'OR Q2'!$S$21,FALSE) -> 0.89548547 | H12: 1 | I12: 1 | J12: 1 | K12: =VLOOKUP(B12,'OR Q2'!$B$42:$E$57,'OR Q2'!$D$41,FALSE) -> 1.1484138 | L12: =VLOOKUP(B12,'OR Q2'!$B$42:$E$57,'OR Q2'!$C$41,FALSE) -> 1.1195652 | M12: 0.9513382
B13: DOM | C13: =VLOOKUP(B13,'OR Q2'!$G$61:$J$75,'OR Q2'!$H$60,FALSE) -> 1.1485714 | D13: =VLOOKUP(B13,'OR Q2'!$G$61:$J$75,'OR Q2'!$I$60,FALSE) -> 1.0829545 | E13: 1 | F13: 1.1111111 | G13: =VLOOKUP(B13,'OR Q2'!$M$22:$S$36,'OR Q2'!$S$21,FALSE) -> 1.0096748 | H13: 1 | I13: 1 | J13: 1 | K13: =VLOOKUP(B13,'OR Q2'!$B$42:$E$57,'OR Q2'!$D$41,FALSE) -> 0.98328595 | L13: =VLOOKUP(B13,'OR Q2'!$B$42:$E$57,'OR Q2'!$C$41,FALSE) -> 0.94701987 | M13: 0.88785047
B14: GUT | C14: =VLOOKUP(B14,'OR Q2'!$G$61:$J$75,'OR Q2'!$H$60,FALSE) -> 1.0213333 | D14: =VLOOKUP(B14,'OR Q2'!$G$61:$J$75,'OR Q2'!$I$60,FALSE) -> 0.94457831 | E14: 1 | F14: 0.99721559 | G14: =VLOOKUP(B14,'OR Q2'!$M$22:$S$36,'OR Q2'!$S$21,FALSE) -> 0.83334667 | H14: 1 | I14: - | J14: 1 | K14: =VLOOKUP(B14,'OR Q2'!$B$42:$E$57,'OR Q2'!$D$41,FALSE) -> 1.2576626 | L14: =VLOOKUP(B14,'OR Q2'!$B$42:$E$57,'OR Q2'!$C$41,FALSE) -> 0.98561151 | M14: 0.91508053
B15: PRG | C15: =VLOOKUP(B15,'OR Q2'!$G$61:$J$75,'OR Q2'!$H$60,FALSE) -> 1.0821429 | D15: =VLOOKUP(B15,'OR Q2'!$G$61:$J$75,'OR Q2'!$I$60,FALSE) -> 1.0444444 | E15: 1 | F15: 0.96666667 | G15: =VLOOKUP(B15,'OR Q2'!$M$22:$S$36,'OR Q2'!$S$21,FALSE) -> 1.0406229 | H15: 1 | I15: - | J15: 1 | K15: =VLOOKUP(B15,'OR Q2'!$B$42:$E$57,'OR Q2'!$D$41,FALSE) -> 0.88794267 | L15: =VLOOKUP(B15,'OR Q2'!$B$42:$E$57,'OR Q2'!$C$41,FALSE) -> 0.8976378 | M15: 0.81521739
B16: BOL | C16: =VLOOKUP(B16,'OR Q2'!$G$61:$J$75,'OR Q2'!$H$60,FALSE) -> 1.0376471 | D16: =VLOOKUP(B16,'OR Q2'!$G$61:$J$75,'OR Q2'!$I$60,FALSE) -> 1.0689655 | E16: 1 | F16: 1.0926032 | G16: =VLOOKUP(B16,'OR Q2'!$M$22:$S$36,'OR Q2'!$S$21,FALSE) -> 0.9606773 | H16: 1 | I16: - | J16: 1 | K16: =VLOOKUP(B16,'OR Q2'!$B$42:$E$57,'OR Q2'!$D$41,FALSE) -> 0.89212234 | L16: =VLOOKUP(B16,'OR Q2'!$B$42:$E$57,'OR Q2'!$C$41,FALSE) -> 0.94186047 | M16: 0.96134021
B17: MASSY | C17: =VLOOKUP(B17,'OR Q2'!$G$61:$J$75,'OR Q2'!$H$60,FALSE) -> 0.76857143 | D17: =VLOOKUP(B17,'OR Q2'!$G$61:$J$75,'OR Q2'!$I$60,FALSE) -> 1.0625 | E17: 1 | F17: 0.90102443 | G17: 0.76 | H17: 1 | I17: - | J17: 1 | K17: =VLOOKUP(B17,'OR Q2'!$B$42:$E$57,'OR Q2'!$D$41,FALSE) -> 2.0844036 | L17: =VLOOKUP(B17,'OR Q2'!$B$42:$E$57,'OR Q2'!$C$41,FALSE) -> 0.96290727 | M17: 0.89483066
B18: GEL | E18: 1 | F18: 0.59746538 | G18: ='OR Q2'!Y18 -> 0.86946677 | H18: 0.5 | I18: - | J18: 1 | K18: =VLOOKUP(B18,'OR Q2'!$B$42:$E$57,'OR Q2'!$D$41,FALSE) -> 1.6214 | L18: =VLOOKUP(B18,'OR Q2'!$B$42:$E$57,'OR Q2'!$C$41,FALSE) -> 1.0466139 | M18: 0.84210526
B21: Market | C21: CSI | D21: SSI | E21: NRC | F21: Training | G21: Ser. Campaign | H21: Lead Mng. | I21: Share of Inv. | J21: Game Plan | K21: Sell In | L21: Retention | M21: Retail Sales | N21: Total
B22: COL | C22: 0.06 | D22: 0.06 | E22: 0.05 | F22: 0.04 | G22: 0.04 | H22: 0.05 | I22: 0.03 | J22: 0.07 | K22: 0.2 | L22: 0.1 | M22: 0.3 | N22: =SUM(C22:M22) -> 1
B23: PLT | C23: 0.06 | D23: 0.06 | E23: 0.05 | F23: 0.04 | G23: 0.04 | H23: 0.05 | I23: 0.03 | J23: 0.07 | K23: 0.2 | L23: 0.1 | M23: 0.3 | N23: =SUM(C23:M23) -> 1
B24: CST | C24: 0.06 | D24: 0.06 | E24: 0.05 | F24: 0.04 | G24: 0.04 | H24: 0.05 | I24: 0.03 | J24: 0.07 | K24: 0.2 | L24: 0.1 | M24: 0.3 | N24: =SUM(C24:M24) -> 1
B25: ECA | C25: 0.06 | D25: 0.06 | E25: 0.05 | F25: 0.04 | G25: 0.04 | H25: 0.05 | I25: 0.03 | J25: 0.07 | K25: 0.2 | L25: 0.1 | M25: 0.3 | N25: =SUM(C25:M25) -> 1
B26: PNM | C26: 0.06 | D26: 0.06 | E26: 0.05 | F26: 0.04 | G26: 0.04 | H26: 0.05 | I26: 0.03 | J26: 0.07 | K26: 0.2 | L26: 0.1 | M26: 0.3 | N26: =SUM(C26:M26) -> 1
B27: URU | C27: 0.06 | D27: 0.06 | E27: 0.05 | F27: 0.04 | G27: 0.04 | H27: 0.05 | I27: 0.03 | J27: 0.07 | K27: 0.2 | L27: 0.1 | M27: 0.3 | N27: =SUM(C27:M27) -> 1
B28: ELS | C28: 0.06 | D28: 0.06 | E28: 0.05 | F28: 0.04 | G28: 0.04 | H28: 0.05 | I28: 0.03 | J28: 0.07 | K28: 0.2 | L28: 0.1 | M28: 0.3 | N28: =SUM(C28:M28) -> 1
B29: HND | C29: 0.06 | D29: 0.06 | E29: 0.05 | F29: 0.04 | G29: 0.04 | H29: 0.05 | I29: 0.03 | J29: 0.07 | K29: 0.2 | L29: 0.1 | M29: 0.3 | N29: =SUM(C29:M29) -> 1
B30: NIC | C30: 0.06 | D30: 0.06 | E30: 0.05 | F30: 0.04 | G30: 0.04 | H30: 0.05 | I30: 0.03 | J30: 0.07 | K30: 0.2 | L30: 0.1 | M30: 0.3 | N30: =SUM(C30:M30) -> 1
B31: DOM | C31: 0.06 | D31: 0.06 | E31: 0.05 | F31: 0.04 | G31: 0.04 | H31: 0.05 | I31: 0.03 | J31: 0.07 | K31: 0.2 | L31: 0.1 | M31: 0.3 | N31: =SUM(C31:M31) -> 1
B32: GUT | C32: 0.06 | D32: 0.06 | E32: 0.05 | F32: 0.04 | G32: 0.04 | H32: 0.05 | I32: - | J32: 0.1 | K32: 0.2 | L32: 0.1 | M32: 0.3 | N32: =SUM(C32:M32) -> 1
B33: PRG | C33: 0.06 | D33: 0.06 | E33: 0.05 | F33: 0.04 | G33: 0.04 | H33: 0.05 | I33: - | J33: 0.1 | K33: 0.2 | L33: 0.1 | M33: 0.3 | N33: =SUM(C33:M33) -> 1
B34: BOL | C34: 0.06 | D34: 0.06 | E34: 0.05 | F34: 0.04 | G34: 0.04 | H34: 0.05 | I34: - | J34: 0.1 | K34: 0.2 | L34: 0.1 | M34: 0.3 | N34: =SUM(C34:M34) -> 1
B35: MASSY | C35: 0.06 | D35: 0.06 | E35: 0.05 | F35: 0.04 | G35: 0.04 | H35: 0.05 | I35: - | J35: 0.1 | K35: 0.2 | L35: 0.1 | M35: 0.3 | N35: =SUM(C35:M35) -> 1
B36: Gel Group | C36: - | D36: - | E36: 0.05 | F36: 0.05 | G36: 0.05 | H36: 0.05 | I36: - | J36: 0.1 | K36: 0.25 | L36: 0.1 | M36: 0.35 | N36: =SUM(C36:M36) -> 1
B39: Market | C39: CSI | D39: SSI | E39: NRC | F39: Training | G39: Ser. Campaign | H39: Lead Mng. | I39: Share of Inv. | J39: Game Plan | K39: Sell In | L39: Retention | M39: Retail Sales | N39: Total
B40: COL | C40: =IF(C4>=100%,C22,(C4*C22)/100%) -> 0.06 | D40: =IF(D4>=100%,D22,(D4*D22)/100%) -> 0.06 | E40: =IF(E4>=100%,E22,(E4*E22)/100%) -> 0.05 | F40: =IF(F4>=100%,F22,(F4*F22)/100%) -> 0.038680662 | G40: =IF(G4>=100%,G22,(G4*G22)/100%) -> 0.04 | H40: =IF(H4>=100%,H22,(H4*H22)/100%) -> 0.05 | I40: =IF(I4>=100%,I22,(I4*I22)/100%) -> 0.03 | J40: =IF(J4>=100%,J22,(J4*J22)/100%) -> 0.07 | ... M40: =IF(M4>=100%,M22,(M4*M22)/100%) -> 0.3 | N40: =SUM(C40:M40) -> 0.99868066
B41: PLT | C41: =IF(C5>=100%,C23,(C5*C23)/100%) -> 0.06 | D41: =IF(D5>=100%,D23,(D5*D23)/100%) -> 0.06 | E41: =IF(E5>=100%,E23,(E5*E23)/100%) -> 0.05 | F41: =IF(F5>=100%,F23,(F5*F23)/100%) -> 0 | G41: =IF(G5>=100%,G23,(G5*G23)/100%) -> 0.038531883 | H41: =IF(H5>=100%,H23,(H5*H23)/100%) -> 0.025 | I41: =IF(I5>=100%,I23,(I5*I23)/100%) -> 0.03 | J41: =IF(J5>=100%,J23,(J5*J23)/100%) -> 0.07 | ... M41: =IF(M5>=100%,M23,(M5*M23)/100%) -> 0.2590812 | N41: =SUM(C41:M41) -> 0.8637738
B42: CST | C42: =IF(C6>=100%,C24,(C6*C24)/100%) -> 0.06 | D42: =IF(D6>=100%,D24,(D6*D24)/100%) -> 0.06 | E42: =IF(E6>=100%,E24,(E6*E24)/100%) -> 0.05 | F42: =IF(F6>=100%,F24,(F6*F24)/100%) -> 0.04 | G42: =IF(G6>=100%,G24,(G6*G24)/100%) -> 0.04 | H42: =IF(H6>=100%,H24,(H6*H24)/100%) -> 0.05 | I42: =IF(I6>=100%,I24,(I6*I24)/100%) -> 0.03 | J42: =IF(J6>=100%,J24,(J6*J24)/100%) -> 0.07 | ... M42: =IF(M6>=100%,M24,(M6*M24)/100%) -> 0.3 | N42: =SUM(C42:M42) -> 1
B43: ECA | C43: =IF(C7>=100%,C25,(C7*C25)/100%) -> 0.06 | D43: =IF(D7>=100%,D25,(D7*D25)/100%) -> 0.06 | E43: =IF(E7>=100%,E25,(E7*E25)/100%) -> 0.05 | F43: =IF(F7>=100%,F25,(F7*F25)/100%) -> 0.04 | G43: =IF(G7>=100%,G25,(G7*G25)/100%) -> 0.04 | H43: =IF(H7>=100%,H25,(H7*H25)/100%) -> 0.05 | I43: =IF(I7>=100%,I25,(I7*I25)/100%) -> 0.03 | J43: =IF(J7>=100%,J25,(J7*J25)/100%) -> 0.07 | ... M43: =IF(M7>=100%,M25,(M7*M25)/100%) -> 0.3 | N43: =SUM(C43:M43) -> 0.99837636
B44: PNM | C44: =IF(C8>=100%,C26,(C8*C26)/100%) -> 0.06 | D44: =IF(D8>=100%,D26,(D8*D26)/100%) -> 0.06 | E44: =IF(E8>=100%,E26,(E8*E26)/100%) -> 0.05 | F44: =IF(F8>=100%,F26,(F8*F26)/100%) -> 0.04 | G44: =IF(G8>=100%,G26,(G8*G26)/100%) -> 0.04 | H44: =IF(H8>=100%,H26,(H8*H26)/100%) -> 0.05 | I44: =IF(I8>=100%,I26,(I8*I26)/100%) -> 0.03 | J44: =IF(J8>=100%,J26,(J8*J26)/100%) -> 0.07 | ... M44: =IF(M8>=100%,M26,(M8*M26)/100%) -> 0.2484 | N44: =SUM(C44:M44) -> 0.9152
B45: URU | C45: =IF(C9>=100%,C27,(C9*C27)/100%) -> 0.06 | D45: =IF(D9>=100%,D27,(D9*D27)/100%) -> 0.06 | E45: =IF(E9>=100%,E27,(E9*E27)/100%) -> 0.05 | F45: =IF(F9>=100%,F27,(F9*F27)/100%) -> 0.04 | G45: =IF(G9>=100%,G27,(G9*G27)/100%) -> 0.04 | H45: =IF(H9>=100%,H27,(H9*H27)/100%) -> 0.05 | I45: =IF(I9>=100%,I27,(I9*I27)/100%) -> 0.03 | J45: =IF(J9>=100%,J27,(J9*J27)/100%) -> 0.07 | ... M45: =IF(M9>=100%,M27,(M9*M27)/100%) -> 0.28984962 | N45: =SUM(C45:M45) -> 0.98166493
B46: ELS | C46: =IF(C10>=100%,C28,(C10*C28)/100%) -> 0.06 | D46: =IF(D10>=100%,D28,(D10*D28)/100%) -> 0.06 | E46: =IF(E10>=100%,E28,(E10*E28)/100%) -> 0.05 | F46: =IF(F10>=100%,F28,(F10*F28)/100%) -> 0.04 | G46: =IF(G10>=100%,G28,(G10*G28)/100%) -> 0.04 | H46: =IF(H10>=100%,H28,(H10*H28)/100%) -> 0.05 | I46: =IF(I10>=100%,I28,(I10*I28)/100%) -> 0.03 | J46: =IF(J10>=100%,J28,(J10*J28)/100%) -> 0.07 | ... M46: =IF(M10>=100%,M28,(M10*M28)/100%) -> 0.2708 | N46: =SUM(C46:M46) -> 0.96287921
...

Sheet OR AUG
B1: 1 | C1: 2 | D1: 3 | F1: 1 | G1: 2 | H1: 3 | I1: 4 | J1: 5 | K1: 6 | L1: 7 | AI1: AFTERSALES TARGETS 2+10
B2: DESTINATION | C2: RS 5+7 | D2: % | F2: NSC | G2: Target CSI | H2: Real CSI | I2: %Achiev. CSI | J2: Target SSI | K2: Real SSI | L2: %Achiev. SSI | N2: SERVICE CAMPAIGN | S2: 1 | T2: 2
B3: MON | C3: 1 | D3: =C3/$C$35 -> 2.0011206e-05 | F3: COL | G3: =VLOOKUP(F3,'OR Q1'!$J$4:$N$18,'OR Q1'!$K$3,FALSE) -> 0.78 | H3: 0.784 | I3: =H3/G3 -> 1.0051282 | J3: =VLOOKUP(F3,'OR Q1'!$J$4:$N$18,'OR Q1'!$N$3,FALSE) -> 0.92 | K3: 0.957 | L3: =K3/J3 -> 1.0402174 | N3: 1 | O3: 2 | P3: 3 | Q3: 4 | S3: Market | T3: TR | V3: 1 | W3: 2 | X3: 3 | Y3: 4 | Z3: 5 | AA3: 6 | AB3: 7 | AC3: Target retention | AE3: Real retention | AI3: 1 | AJ3: 2 | AK3: 3 | AL3: 4 | AM3: 5 | AN3: 6 | AO3: 7 | AP3: 8 | AQ3: 9 | AT3: 1 | AU3: 2 | AV3: 3 | AW3: 4 | AX3: 5 | BJ3: 1 | BK3: 2 | BL3: 3 | BM3: 4
B4: ALB | C4: 231 | D4: =C4/$C$35 -> 0.0046225886 | F4: CST | G4: =VLOOKUP(F4,'OR Q1'!$J$4:$N$18,'OR Q1'!$K$3,FALSE) -> 0.92 | H4: 0.951 | I4: =H4/G4 -> 1.0336957 | J4: =VLOOKUP(F4,'OR Q1'!$J$4:$N$18,'OR Q1'!$N$3,FALSE) -> 0.92 | K4: 0.935 | L4: =K4/J4 -> 1.0163043 | N4: NSC | O4: Target | P4: Real | Q4: Cumpli. | S4: COL | T4: 0.96701656 | V4: NSC | W4: Target Sell-In | X4: Total Sell-In | Y4: %cumpli. | Z4: target retention | AA4: Service Frequency | AB4: %cumpli. | AC4: Total Repair Orders | AD4: UIO | AE4: Total Repair Orders | AF4: UIO | AI4: NSC | AJ4: Target Sell-In | AK4: Total Sell-In | AL4: %cumpli. | AM4: Target Retention | AN4: Service Frequency | AO4: %cumpli. | AP4: Total Repair Orders | AQ4: UIO | AT4: Market | AU4: Lead Mng. | AV4: Share of Inv. | AW4: Game Plan | AX4: %Cumpli. | AZ4: NSC | BA4: FY24 | BB4: FYTD25 AUG | BC4: Weigth | BE4: NSC | BF4: Retention | BG4: Spare Parts/ UIO WS ($) | BH4: Weigth | BJ4: NSC | BK4: WS | BL4: RS | BM4: Weigth
B5: ANT | C5: 137 | D5: =C5/$C$35 -> 0.0027415353 | F5: ECA | G5: =VLOOKUP(F5,'OR Q1'!$J$4:$N$18,'OR Q1'!$K$3,FALSE) -> 0.85 | H5: 0.868 | I5: =H5/G5 -> 1.0211765 | J5: =VLOOKUP(F5,'OR Q1'!$J$4:$N$18,'OR Q1'!$N$3,FALSE) -> 0.94 | K5: 0.982 | L5: =K5/J5 -> 1.0446809 | N5: ECA | O5: 0.34417278 | P5: 0.62640587 | Q5: =P5/O5 -> 1.8200332 | S5: PLT | T5: 0 | AT5: COL | AU5: 1 | AV5: 1 | AW5: 1 | AX5: =AVERAGE(AU5:AW5) -> 1 | AZ5: COL | BA5: 1 | BB5: =VLOOKUP(AZ5,$AT$4:$AX$19,$AX$3,FALSE) -> 1 | BC5: =VLOOKUP(AZ5,$B$2:$D$37,$D$1,FALSE) -> 0.27055151 | BE5: BOL | BF5: 0.8048231 | BG5: 177.94642 | BH5: =VLOOKUP(BE5,$B$2:$D$38,$D$1,FALSE) -> 0.021512047 | BJ5: COL | BK5: 0.96 | BL5: 1.06 | BM5: =VLOOKUP(BJ5,$B$2:$D$38,$D$1,FALSE) -> 0.27055151 | BO5: =BM5+BM6+BM15+BM17 -> 0.46311935
B6: BAR | C6: 184 | D6: =C6/$C$35 -> 0.003682062 | F6: PNM | G6: =VLOOKUP(F6,'OR Q1'!$J$4:$N$18,'OR Q1'!$K$3,FALSE) -> 0.86 | H6: 0.879 | I6: =H6/G6 -> 1.022093 | J6: =VLOOKUP(F6,'OR Q1'!$J$4:$N$18,'OR Q1'!$N$3,FALSE) -> 0.9 | K6: 0.976 | L6: =K6/J6 -> 1.0844444 | N6: CST | O6: 0.37527362 | P6: 0.51374465 | Q6: =P6/O6 -> 1.3689869 | S6: CST | T6: 1.1111111 | V6: COL | W6: 6772785 | X6: 6737647 | Y6: =X6/W6 -> 0.99481188 | Z6: 1 | AA6: 1.04 | AB6: =AA6/Z6 -> 1.04 | AC6: 60162 | AD6: 60336 | AE6: 62740 | AF6: 60336 | AI6: COL | AJ6: 6772785 | AK6: 6737647 | AL6: =AK6/AJ6 -> 0.99481188 | AM6: 1.02 | AN6: 1.04 | AO6: =AN6/AM6 -> 1.0196078 | AP6: 61579 | AQ6: 60336 | AT6: PLT | AU6: 0.75 | AV6: 1 | AW6: 1 | AX6: =AVERAGE(AU6:AW6) -> 0.91666667 | AZ6: CST | BA6: 1 | BB6: =VLOOKUP(AZ6,$AT$4:$AX$19,$AX$3,FALSE) -> 0.91666667 | BC6: =VLOOKUP(AZ6,$B$2:$D$37,$D$1,FALSE) -> 0.13185384 | BE6: COL | BF6: 1.0398464 | BG6: 251.57802 | BH6: =VLOOKUP(BE6,$B$2:$D$38,$D$1,FALSE) -> 0.27055151 | BJ6: CST | BK6: 0.96 | BL6: 1.19 | BM6: =VLOOKUP(BJ6,$B$2:$D$38,$D$1,FALSE) -> 0.13185384 | BO6: =BM8+BM9+BM13 -> 0.1323141
