Workbook
Name Slicer_BDM: #N/A
Name Slicer_Priority: #N/A
Name Slicer_RAM: #N/A

Sheet DB (2)
B3: PNM
C8: Target | D8: Real | E8: %Ach | F8: Diff | H8: Target | I8: Real | J8: %Ach | K8: Diff | M8: Target | N8: Real | O8: %Ach | P8: Diff | V8: NRC Implementation Plan
B9: CSI | C9: =VLOOKUP(B3,Data!$C$3:$BE$22,Data!D2,FALSE) -> 0.86 | D9: =VLOOKUP(B3,Data!$C$3:$BE$22,Data!E2,FALSE) -> 0.887 | E9: =VLOOKUP(B3,Data!$C$3:$BE$22,Data!F2,FALSE) -> 1.0313953 | F9: =IF(E9>=100%,0%,100%-E9) -> 0 | G9: SSI | H9: =VLOOKUP($B$3,Data!$C$3:$BE$22,Data!H2,FALSE) -> 0.9 | I9: =VLOOKUP($B$3,Data!$C$3:$BE$22,Data!I2,FALSE) -> 0.97 | J9: =VLOOKUP($B$3,Data!$C$3:$BE$22,Data!J2,FALSE) -> 1.0777778 | K9: =IF(J9>=100%,0%,100%-J9) -> 0 | L9: Campaign | M9: 0.52 | N9: =VLOOKUP($B$3,Data!$C$3:$BE$22,Data!U2,FALSE) -> 0.73817035 | O9: =VLOOKUP($B$3,Data!$C$3:$BE$22,Data!V2,FALSE) -> 1.1184399 | P9: =IF(O9>=100%,0%,100%-O9) -> 0
L10: TR Sales | M10: =VLOOKUP($B$3,Data!$C$3:$BE$22,Data!AW2,FALSE) -> 0.9 | N10: =VLOOKUP($B$3,Data!$C$3:$BE$22,Data!AX2,FALSE) -> 0.95964432 | O10: =VLOOKUP($B$3,Data!$C$3:$BE$22,Data!AY2,FALSE) -> 1.0662715 | P10: =IF(O10>=100%,0%,100%-O10) -> 0 | Q10: =VLOOKUP($B$3,Data!$C$3:$BE$22,Data!AZ2,FALSE) -> 0.47982216 | V10: Target | X10: Status
L11: TR AS | M11: =VLOOKUP($B$3,Data!$C$3:$BE$22,Data!BA2,FALSE) -> 0.9 | N11: =VLOOKUP($B$3,Data!$C$3:$BE$22,Data!BB2,FALSE) -> 1 | O11: =VLOOKUP($B$3,Data!$C$3:$BE$22,Data!BC2,FALSE) -> 1.1111111 | P11: =IF(O11>=100%,0%,100%-O11) -> 0 | Q11: =VLOOKUP($B$3,Data!$C$3:$BE$22,Data!BD2,FALSE) -> 0.5 | V11: =VLOOKUP(B3,Data!C3:BE22,Data!L2,FALSE) -> NRC Plan FY25-FY26, signed in Q1 FY25 | X11: =VLOOKUP(B3,Data!C3:BE22,Data!M2,FALSE) -> Signed
M13: Sales | N13: Aftersales | O13: Target | P13: TR Real | Q13: %Ach | R13: Diff
L14: Training | M14: =N10 -> 0.95964432 | N14: =N11 -> 1 | O14: 0.9 | P14: =Q10+Q11 -> 0.97982216 | Q14: =P14/O14 -> 1.0886913 | R14: =IF(Q14>=100%,0%,100%-Q14) -> 0
L15: Target | M15: 0.9 | N15: 0.9
V16: In Progress | W16: No Startet | X16: Completed
C24: Lead Management (From Leads to Closing) | J24: Share of Invesment | Q24: 360 Game Plan
C25: Target | G25: Real | J25: Target | N25: Real | Q25: Target | V25: Real
C26: =VLOOKUP(B3,Data!C3:BE22,Data!X2,FALSE) -> Montly Report | G26: 1 | J26: Declare Quarterly Top 5 Competitors + Nissan | N26: Q2 | 100% | Q26: Declare Quarterly According to Template Format | V26: Q2 | 100%
D34: Target | E34: Real | F34: %Ach | G34: Diff | K34: Target | L34: Real | M34: %Ach | N34: Diff | Q34: Target | R34: Real | S34: %Ach | T34: Diff | V34: 0.9152 | W34: =IF(V34>=100%,0%,100%-V34) -> 0.0848
C35: Sell In | D35: 1710206 | E35: 1426757 | F35: =E35/D35 -> 0.83426032 | G35: =IF(F35>=100%,0%,100%-F35) -> 0.16573968 | J35: Retention | K35: =VLOOKUP($B$3,Data!$C$3:$BE$22,Data!AK2,FALSE) -> 0.77 | L35: =VLOOKUP($B$3,Data!$C$3:$BE$22,Data!AL2,FALSE) -> 0.76 | M35: =VLOOKUP($B$3,Data!$C$3:$BE$22,Data!AM2,FALSE) -> 0.98701299 | N35: =IF(M35>=100%,0%,100%-M35) -> 0.012987013 | P35: RS | Q35: 906 | R35: =VLOOKUP($B$3,Data!$C$3:$BE$22,Data!AP2,FALSE) -> 1146 | S35: =R35/Q35 -> 1.2649007 | T35: =IF(S35>=100%,0%,100%-S35) -> 0
F56: Real | G56: Target
E57: TRD | F57: 0.29708223 | G57: 0.52625995 | H57: =F57/G57 -> 0.56451613 | I57: =100%-H57 -> 0.43548387
E58: R9 | F58: 0.007518797 | G58: 0.58533835 | H58: =F58/G58 -> 0.012845215 | I58: =100%-H58 -> 0.98715478
D78: fotos de PRG
D79: ALTO COMPROMISO

Sheet Data
C2: 1 | D2: 2 | E2: 3 | F2: 4 | G2: 5 | H2: 6 | I2: 7 | J2: 8 | K2: 9 | L2: 10 | M2: 11 | N2: 12 | O2: 13 | P2: 14 | Q2: 15 | R2: 16 | S2: 17 | T2: 18 | U2: 19 | V2: 20 | W2: 21 | X2: 22 | Y2: 23 | Z2: 24 | AA2: 25 | AB2: 26 | AC2: 27 | AD2: 28 | AE2: 29 | AF2: 30 | AG2: 31 | AH2: 32 | AI2: 33 | AJ2: 34 | AK2: 35 | AL2: 36 | AM2: 37 | AN2: 38 | AO2: 39 | AP2: 40 | AQ2: 41 | AR2: 42 | AS2: 43 | AT2: 44 | AU2: 45 | AV2: 46 | AW2: 47 | AX2: 48 | AY2: 49 | AZ2: 50 | BA2: 51 | BB2: 52 | BC2: 53 | BD2: 54 | BE2: 55
B3: Priority | C3: Market | D3: CSI | E3: Real CSI | F3: %Ach. CSI | G3: pts CSI | H3: SSI | I3: Real SSI | J3: %Ach. SSI | K3: pts SSI | L3: NRC Implementation | M3: Status NRC | N3: %Ach. NRC | O3: pts NRC | P3: Trainin (Compliance %) | Q3: Real TR | R3: %Ach. TR | S3: pts TR | T3: Service Campaing | U3: Real SC | V3: %Ach. SC | W3: pts SC | X3: Lead Management | Y3: %Ach. Lead Mang. | Z3: pts Lead | AA3: Share of Investment | AB3: %Ach. SOI | AC3: pts SOI | AD3: 360 Game Plan | AE3: % Ach. 360 | AF3: pts 360 | AG3: Sell In (USD) | AH3: Real Sell In | AI3: %Ach. Sell In | AJ3: pts Sell In | AK3: Retention | AL3: Real Retention | AM3: %Ach. Retention | AN3: pts Retention | AO3: Retail Sales | AP3: Real RS | AQ3: %Ach. RS | AR3: pts RS | AS3: RR CSI | AT3: RR SSI | AU3: TTT Sales | AV3: TTT Tech Level | AW3: TR Sales | AX3: Real TR Sales | AY3: %Ach. TR Sales | AZ3: pts TR Sales | BA3: TR AS | BB3: Real TR AS | BC3: %Ach. TR AS | BD3: pts TR AS | BE3: Total | BF3: NRC-IMP
B4: 6 MAIN | C4: COL | D4: 0.78 | E4: =VLOOKUP(C4,WB!$C$78:$U$92,WB!$J$76,FALSE) -> 0.791 | F4: =E4/D4 -> 1.0141026 | G4: =IF(F4>=100%,6%,F4*6%/100%) -> 0.06 | H4: 0.92 | I4: =VLOOKUP(C4,WB!$C$78:$U$92,WB!$K$76,FALSE) -> 0.958 | J4: =I4/H4 -> 1.0413043 | K4: =IF(J4>=100%,6%,J4*6%/100%) -> 0.06 | L4: NRC Plan FY25-FY26, signed in Q1 FY25 | M4: Signed | N4: 0.1 | O4: =IF(N4>=100%,5%,N4*5%/100%) -> 0.005 | P4: 0.9 | Q4: =AZ4+BD4 -> 0.85718714 | R4: =Q4/P4 -> 0.95243016 | S4: =IF(R4>=100%,4%,R4*4%/100%) -> 0.038097206 | T4: 0.69 | U4: =VLOOKUP(C4,WB!$C$137:$AA$154,WB!$Q$136,FALSE) -> 0.62841876 | V4: =U4/T4 -> 0.91075183 | W4: =IF(V4>=100%,4%,V4*4%/100%) -> 0.036430073 | X4: Montly Report | Y4: =VLOOKUP(C4,WB!$R$3:$AD$18,WB!$AD$2,FALSE) -> 0.5 | Z4: =IF(Y4>=100%,5%,Y4*5%/100%) -> 0.025 | AA4: Q2 | AB4: 0.5 | AC4: =IF(AB4>=100%,3%,AB4*3%/100%) -> 0.015 | AD4: Q3 | AE4: 0.75 | AF4: =IF(AE4>=100%,7%,AE4*7%/100%) -> 0.0525 | AG4: 22300000 | AH4: =VLOOKUP(C4,WB!$C$99:$U$132,WB!$J$98,FALSE) -> 11072189 | AI4: =AH4/AG4 -> 0.49651072 | AJ4: =IF(AI4>=100%,20%,AI4*20%/100%) -> 0.099302143 | AK4: 1 | AL4: =VLOOKUP(C4,WB!$C$99:$U$132,WB!$K$98,FALSE) -> 1.04 | AM4: =AL4/AK4 -> 1.04 | AN4: =IF(AM4>=100%,10%,AM4*10%/100%) -> 0.1 | AO4: 13201 | AP4: =VLOOKUP(C4,WB!$B$3:$O$35,WB!$O$2,FALSE) -> 7883 | AQ4: =AP4/AO4 -> 0.59715173 | AR4: =IF(AQ4>=100%,30%,AQ4*30%/100%) -> 0.17914552 | AS4: 0.29 | AT4: 0.41 | AW4: 0.9 | AX4: =VLOOKUP(C4,WB!$B$42:$U$71,WB!$I$40,FALSE) -> 0.98448729 | AY4: =AX4/AW4 -> 1.0938748 | AZ4: =IF(AND(BC4<100%,AY4>=100%),45%,AY4*45%/100%) -> 0.45 | BA4: 0.9 | BB4: =VLOOKUP(C4,WB!$B$42:$U$71,WB!$H$40,FALSE) -> 0.81437428 | BC4: =BB4/BA4 -> 0.90486031 | BD4: =IF(AND(AY4<100%,BC4>=100%),45%,BC4*45%/100%) -> 0.40718714 | BE4: =AR4+AN4+AJ4+W4+S4+K4+G4+AF4+AC4+Z4+O4 -> 0.67047494 | BF4: 0.3
B5: 6 MAIN | C5: PLT | D5: 0.82 | E5: =VLOOKUP(C5,WB!$C$78:$U$92,WB!$J$76,FALSE) -> 0.848 | F5: =E5/D5 -> 1.0341463 | G5: =IF(F5>=100%,6%,F5*6%/100%) -> 0.06 | H5: 0.91 | I5: =VLOOKUP(C5,WB!$C$78:$U$92,WB!$K$76,FALSE) -> 0.918 | J5: =I5/H5 -> 1.0087912 | K5: =IF(J5>=100%,6%,J5*6%/100%) -> 0.06 | L5: NRC Plan FY25-FY26, signed in Q1 FY25 | M5: WIP | N5: 0 | O5: =IF(N5>=100%,5%,N5*5%/100%) -> 0 | P5: 0.9 | Q5: =AZ5+BD5 -> 0.83333333 | R5: =Q5/P5 -> 0.92592593 | S5: =IF(R5>=100%,4%,R5*4%/100%) -> 0.037037037 | T5: 0.5 | U5: =VLOOKUP(C5,WB!$C$137:$AA$154,WB!$Q$136,FALSE) -> 0.46404996 | V5: =U5/T5 -> 0.92809991 | W5: =IF(V5>=100%,4%,V5*4%/100%) -> 0.037123996 | X5: Montly Report | Y5: =VLOOKUP(C5,WB!$R$3:$AD$18,WB!$AD$2,FALSE) -> 0.5 | Z5: =IF(Y5>=100%,5%,Y5*5%/100%) -> 0.025 | AA5: Q2 | AB5: 0.5 | AC5: =IF(AB5>=100%,3%,AB5*3%/100%) -> 0.015 | AD5: Q3 | AE5: 0.75 | AF5: =IF(AE5>=100%,7%,AE5*7%/100%) -> 0.0525 | AG5: 3200000 | AH5: =VLOOKUP(C5,WB!$C$99:$U$132,WB!$J$98,FALSE) -> 1360596 | AI5: =AH5/AG5 -> 0.42518625 | AJ5: =IF(AI5>=100%,20%,AI5*20%/100%) -> 0.08503725 | AK5: 0.86 | AL5: =VLOOKUP(C5,WB!$C$99:$U$132,WB!$K$98,FALSE) -> 0.86 | AM5: =AL5/AK5 -> 1 | AN5: =IF(AM5>=100%,10%,AM5*10%/100%) -> 0.1 | AO5: 6363 | AP5: =VLOOKUP(C5,WB!$B$3:$O$35,WB!$O$2,FALSE) -> 3818 | AQ5: =AP5/AO5 -> 0.60003143 | AR5: =IF(AQ5>=100%,30%,AQ5*30%/100%) -> 0.18000943 | AS5: 0.23 | AT5: 0.35 | AW5: 0.9 | AX5: =VLOOKUP(C5,WB!$B$42:$U$71,WB!$I$40,FALSE) -> 0.96511628 | AY5: =AX5/AW5 -> 1.0723514 | AZ5: =IF(AND(BC5<100%,AY5>=100%),45%,AY5*45%/100%) -> 0.45 | BA5: 0.9 | BB5: =VLOOKUP(C5,WB!$B$42:$U$71,WB!$H$40,FALSE) -> 0.76666667 | BC5: =BB5/BA5 -> 0.85185185 | BD5: =IF(AND(AY5<100%,BC5>=100%),45%,BC5*45%/100%) -> 0.38333333 | BE5: =AR5+AN5+AJ5+W5+S5+K5+G5+AF5+AC5+Z5+O5 -> 0.65170771
B6: 6 MAIN | C6: CST | D6: 0.92 | E6: =VLOOKUP(C6,WB!$C$78:$U$92,WB!$J$76,FALSE) -> 0.953 | F6: =E6/D6 -> 1.0358696 | G6: =IF(F6>=100%,6%,F6*6%/100%) -> 0.06 | H6: 0.92 | I6: =VLOOKUP(C6,WB!$C$78:$U$92,WB!$K$76,FALSE) -> 0.937 | J6: =I6/H6 -> 1.0184783 | K6: =IF(J6>=100%,6%,J6*6%/100%) -> 0.06 | L6: NRC Plan FY25-FY26, signed in Q1 FY25 | M6: Signed | N6: 0.1 | O6: =IF(N6>=100%,5%,N6*5%/100%) -> 0.005 | P6: 0.9 | Q6: =AZ6+BD6 -> 0.9942383 | R6: =Q6/P6 -> 1.1047092 | S6: =IF(R6>=100%,4%,R6*4%/100%) -> 0.04 | T6: 0.56 | U6: =VLOOKUP(C6,WB!$C$137:$AA$154,WB!$Q$136,FALSE) -> 0.59163103 | V6: =U6/T6 -> 1.056484 | W6: =IF(V6>=100%,4%,V6*4%/100%) -> 0.04 | X6: Montly Report | Y6: =VLOOKUP(C6,WB!$R$3:$AD$18,WB!$AD$2,FALSE) -> 0.5 | Z6: =IF(Y6>=100%,5%,Y6*5%/100%) -> 0.025 | AA6: Q2 | AB6: 0.5 | AC6: =IF(AB6>=100%,3%,AB6*3%/100%) -> 0.015 | AD6: Q3 | AE6: 0.75 | AF6: =IF(AE6>=100%,7%,AE6*7%/100%) -> 0.0525 | AG6: 6300000 | AH6: =VLOOKUP(C6,WB!$C$99:$U$132,WB!$J$98,FALSE) -> 4097809 | AI6: =AH6/AG6 -> 0.65044587 | AJ6: =IF(AI6>=100%,20%,AI6*20%/100%) -> 0.13008917 | AK6: 1.32 | AL6: =VLOOKUP(C6,WB!$C$99:$U$132,WB!$K$98,FALSE) -> 1.33 | AM6: =AL6/AK6 -> 1.0075758 | AN6: =IF(AM6>=100%,10%,AM6*10%/100%) -> 0.1 | AO6: 7091 | AP6: =VLOOKUP(C6,WB!$B$3:$O$35,WB!$O$2,FALSE) -> 4033 | AQ6: =AP6/AO6 -> 0.56874912 | AR6: =IF(AQ6>=100%,30%,AQ6*30%/100%) -> 0.17062474 | AS6: 0.36 | AT6: 0.41 | AW6: 0.9 | AX6: =VLOOKUP(C6,WB!$B$42:$U$71,WB!$I$40,FALSE) -> 0.98931624 | AY6: =AX6/AW6 -> 1.0992403 | AZ6: =IF(AND(BC6<100%,AY6>=100%),45%,AY6*45%/100%) -> 0.49465812 | BA6: 0.9 | BB6: =VLOOKUP(C6,WB!$B$42:$U$71,WB!$H$40,FALSE) -> 0.99916037 | BC6: =BB6/BA6 -> 1.1101782 | BD6: =IF(AND(AY6<100%,BC6>=100%),45%,BC6*45%/100%) -> 0.49958018 | BE6: =AR6+AN6+AJ6+W6+S6+K6+G6+AF6+AC6+Z6+O6 -> 0.69821391 | BF6: 0.7
B7: 6 MAIN | C7: ECA | D7: 0.85 | E7: =VLOOKUP(C7,WB!$C$78:$U$92,WB!$J$76,FALSE) -> 0.871 | F7: =E7/D7 -> 1.0247059 | G7: =IF(F7>=100%,6%,F7*6%/100%) -> 0.06 | H7: 0.94 | I7: =VLOOKUP(C7,WB!$C$78:$U$92,WB!$K$76,FALSE) -> 0.963 | J7: =I7/H7 -> 1.0244681 | K7: =IF(J7>=100%,6%,J7*6%/100%) -> 0.06 | L7: Dealer Network Plan Proposal Approved by NIBU - Q3 | M7: Signed | N7: 0.1 | O7: =IF(N7>=100%,5%,N7*5%/100%) -> 0.005 | P7: 0.9 | Q7: =AZ7+BD7 -> 0.93439028 | R7: =Q7/P7 -> 1.0382114 | S7: =IF(R7>=100%,4%,R7*4%/100%) -> 0.04 | T7: 0.55 | U7: =VLOOKUP(C7,WB!$C$137:$AA$154,WB!$Q$136,FALSE) -> 0.6801956 | V7: =U7/T7 -> 1.2367193 | W7: =IF(V7>=100%,4%,V7*4%/100%) -> 0.04 | X7: Montly Report | Y7: =VLOOKUP(C7,WB!$R$3:$AD$18,WB!$AD$2,FALSE) -> 0.5 | Z7: =IF(Y7>=100%,5%,Y7*5%/100%) -> 0.025 | AA7: Q2 | AB7: 0.5 | AC7: =IF(AB7>=100%,3%,AB7*3%/100%) -> 0.015 | AD7: Q3 | AE7: 0.75 | AF7: =IF(AE7>=100%,7%,AE7*7%/100%) -> 0.0525 | AG7: 4600000 | AH7: =VLOOKUP(C7,WB!$C$99:$U$132,WB!$J$98,FALSE) -> 2441588 | AI7: =AH7/AG7 -> 0.53078 | AJ7: =IF(AI7>=100%,20%,AI7*20%/100%) -> 0.106156 | AK7: 1.04 | AL7: =VLOOKUP(C7,WB!$C$99:$U$132,WB!$K$98,FALSE) -> 1.04 | AM7: =AL7/AK7 -> 1 | AN7: =IF(AM7>=100%,10%,AM7*10%/100%) -> 0.1 | AO7: 1750 | AP7: =VLOOKUP(C7,WB!$B$3:$O$35,WB!$O$2,FALSE) -> 908 | AQ7: =AP7/AO7 -> 0.51885714 | AR7: =IF(AQ7>=100%,30%,AQ7*30%/100%) -> 0.15565714 | AS7: 0.36 | AT7: 0.4 | AW7: 0.9 | AX7: =VLOOKUP(C7,WB!$B$42:$U$71,WB!$I$40,FALSE) -> 0.91666667 | AY7: =AX7/AW7 -> 1.0185185 | AZ7: =IF(AND(BC7<100%,AY7>=100%),45%,AY7*45%/100%) -> 0.45833333 | BA7: 0.9 | BB7: =VLOOKUP(C7,WB!$B$42:$U$71,WB!$H$40,FALSE) -> 0.95211389 | BC7: =BB7/BA7 -> 1.0579043 | BD7: =IF(AND(AY7<100%,BC7>=100%),45%,BC7*45%/100%) -> 0.47605695 | BE7: =AR7+AN7+AJ7+W7+S7+K7+G7+AF7+AC7+Z7+O7 -> 0.65931314 | BF7: -
B8: 6 MAIN | C8: PNM | D8: 0.86 | E8: =VLOOKUP(C8,WB!$C$78:$U$92,WB!$J$76,FALSE) -> 0.887 | F8: =E8/D8 -> 1.0313953 | G8: =IF(F8>=100%,6%,F8*6%/100%) -> 0.06 | H8: 0.9 | I8: =VLOOKUP(C8,WB!$C$78:$U$92,WB!$K$76,FALSE) -> 0.97 | J8: =I8/H8 -> 1.0777778 | K8: =IF(J8>=100%,6%,J8*6%/100%) -> 0.06 | L8: NRC Plan FY25-FY26, signed in Q1 FY25 | M8: Signed | N8: 0.1 | O8: =IF(N8>=100%,5%,N8*5%/100%) -> 0.005 | P8: 0.9 | Q8: =AZ8+BD8 -> 0.97982216 | R8: =Q8/P8 -> 1.0886913 | S8: =IF(R8>=100%,4%,R8*4%/100%) -> 0.04 | T8: 0.66 | U8: =VLOOKUP(C8,WB!$C$137:$AA$154,WB!$Q$136,FALSE) -> 0.73817035 | V8: =U8/T8 -> 1.1184399 | W8: =IF(V8>=100%,4%,V8*4%/100%) -> 0.04 | X8: Montly Report | Y8: =VLOOKUP(C8,WB!$R$3:$AD$18,WB!$AD$2,FALSE) -> 0.5 | Z8: =IF(Y8>=100%,5%,Y8*5%/100%) -> 0.025 | AA8: Q2 | AB8: 0.5 | AC8: =IF(AB8>=100%,3%,AB8*3%/100%) -> 0.015 | AD8: Q3 | AE8: 0.75 | AF8: =IF(AE8>=100%,7%,AE8*7%/100%) -> 0.0525 | AG8: 5130381 | AH8: =VLOOKUP(C8,WB!$C$99:$U$132,WB!$J$98,FALSE) -> 2215566 | AI8: =AH8/AG8 -> 0.43185214 | AJ8: =IF(AI8>=100%,20%,AI8*20%/100%) -> 0.086370427 | AK8: 0.77 | AL8: =VLOOKUP(C8,WB!$C$99:$U$132,WB!$K$98,FALSE) -> 0.76 | AM8: =AL8/AK8 -> 0.98701299 | AN8: =IF(AM8>=100%,10%,AM8*10%/100%) -> 0.098701299 | AO8: 2600 | AP8: =VLOOKUP(C8,WB!$B$3:$O$35,WB!$O$2,FALSE) -> 1146 | AQ8: =AP8/AO8 -> 0.44076923 | AR8: =IF(AQ8>=100%,30%,AQ8*30%/100%) -> 0.13223077 | AS8: 0.36 | AT8: 0.41 | AW8: 0.9 | AX8: =VLOOKUP(C8,WB!$B$42:$U$71,WB!$I$40,FALSE) -> 0.95964432 | AY8: =AX8/AW8 -> 1.0662715 | AZ8: =IF(AND(BC8<100%,AY8>=100%),45%,AY8*45%/100%) -> 0.47982216 | BA8: 0.9 | BB8: =VLOOKUP(C8,WB!$B$42:$U$71,WB!$H$40,FALSE) -> 1 | BC8: =BB8/BA8 -> 1.1111111 | BD8: =IF(AND(AY8<100%,BC8>=100%),45%,BC8*45%/100%) -> 0.5 | BE8: =AR8+AN8+AJ8+W8+S8+K8+G8+AF8+AC8+Z8+O8 -> 0.6148025 | BF8: 0.8
B9: 6 MAIN | C9: URU | D9: 0.94 | E9: =VLOOKUP(C9,WB!$C$78:$U$92,WB!$J$76,FALSE) -> 0.992 | F9: =E9/D9 -> 1.0553191 | G9: =IF(F9>=100%,6%,F9*6%/100%) -> 0.06 | H9: 0.95 | I9: =VLOOKUP(C9,WB!$C$78:$U$92,WB!$K$76,FALSE) -> 0.989 | J9: =I9/H9 -> 1.0410526 | K9: =IF(J9>=100%,6%,J9*6%/100%) -> 0.06 | L9: NRC Plan FY25-FY26, signed in Q1 FY25 | M9: Signed | N9: 0.1 | O9: =IF(N9>=100%,5%,N9*5%/100%) -> 0.005 | P9: 0.9 | Q9: =AZ9+BD9 -> 0.89956487 | R9: =Q9/P9 -> 0.99951653 | S9: =IF(R9>=100%,4%,R9*4%/100%) -> 0.039980661 | T9: 0.45 | U9: =VLOOKUP(C9,WB!$C$137:$AA$154,WB!$Q$136,FALSE) -> 0.41526298 | V9: =U9/T9 -> 0.92280662 | W9: =IF(V9>=100%,4%,V9*4%/100%) -> 0.036912265 | X9: Montly Report | Y9: =VLOOKUP(C9,WB!$R$3:$AD$18,WB!$AD$2,FALSE) -> 0.5 | Z9: =IF(Y9>=100%,5%,Y9*5%/100%) -> 0.025 | AA9: Q2 | AB9: 0.5 | AC9: =IF(AB9>=100%,3%,AB9*3%/100%) -> 0.015 | AD9: Q3 | AE9: 0.75 | AF9: =IF(AE9>=100%,7%,AE9*7%/100%) -> 0.0525 | AG9: 2730000 | AH9: =VLOOKUP(C9,WB!$C$99:$U$132,WB!$J$98,FALSE) -> 1638459 | AI9: =AH9/AG9 -> 0.60016813 | AJ9: =IF(AI9>=100%,20%,AI9*20%/100%) -> 0.12003363 | AK9: 0.85 | AL9: =VLOOKUP(C9,WB!$C$99:$U$132,WB!$K$98,FALSE) -> 0.85 | AM9: =AL9/AK9 -> 1 | AN9: =IF(AM9>=100%,10%,AM9*10%/100%) -> 0.1 | AO9: 2200 | AP9: =VLOOKUP(C9,WB!$B$3:$O$35,WB!$O$2,FALSE) -> 846 | AQ9: =AP9/AO9 -> 0.38454545 | AR9: =IF(AQ9>=100%,30%,AQ9*30%/100%) -> 0.11536364 | AS9: 0.3 | AT9: 0.36 | AW9: 0.9 | AX9: =VLOOKUP(C9,WB!$B$42:$U$71,WB!$I$40,FALSE) -> 0.90604575 | AY9: =AX9/AW9 -> 1.0067175 | AZ9: =IF(AND(BC9<100%,AY9>=100%),45%,AY9*45%/100%) -> 0.45 | BA9: 0.9 | BB9: =VLOOKUP(C9,WB!$B$42:$U$71,WB!$H$40,FALSE) -> 0.89912975 | BC9: =BB9/BA9 -> 0.99903305 | BD9: =IF(AND(AY9<100%,BC9>=100%),45%,BC9*45%/100%) -> 0.44956487 | BE9: =AR9+AN9+AJ9+W9+S9+K9+G9+AF9+AC9+Z9+O9 -> 0.62979019 | BF9: 0.4
B10: NO MAIN | C10: ELS | D10: 0.7 | E10: =VLOOKUP(C10,WB!$C$78:$U$92,WB!$J$76,FALSE) -> 0.755 | F10: =E10/D10 -> 1.0785714 | G10: =IF(F10>=100%,6%,F10*6%/100%) -> 0.06 | H10: 0.83 | I10: =VLOOKUP(C10,WB!$C$78:$U$92,WB!$K$76,FALSE) -> 0.949 | J10: =I10/H10 -> 1.1433735 | K10: =IF(J10>=100%,6%,J10*6%/100%) -> 0.06 | L10: NRC Plan FY25-FY26, signed in Q1 FY25 | M10: Signed | N10: 0.1 | O10: =IF(N10>=100%,5%,N10*5%/100%) -> 0.005 | P10: 0.9 | Q10: =AZ10+BD10 -> 0.96117502 | R10: =Q10/P10 -> 1.0679722 | S10: =IF(R10>=100%,4%,R10*4%/100%) -> 0.04 | T10: 0.67 | U10: =VLOOKUP(C10,WB!$C$137:$AA$154,WB!$Q$136,FALSE) -> 0.54865424 | V10: =U10/T10 -> 0.81888693 | W10: =IF(V10>=100%,4%,V10*4%/100%) -> 0.032755477 | X10: Montly Report | Y10: =VLOOKUP(C10,WB!$R$3:$AD$18,WB!$AD$2,FALSE) -> 0.5 | Z10: =IF(Y10>=100%,5%,Y10*5%/100%) -> 0.025 | AA10: Q2 | AB10: 0.5 | AC10: =IF(AB10>=100%,3%,AB10*3%/100%) -> 0.015 | AD10: Q3 | AE10: 0.75 | AF10: =IF(AE10>=100%,7%,AE10*7%/100%) -> 0.0525 | AG10: 2582000 | AH10: =VLOOKUP(C10,WB!$C$99:$U$132,WB!$J$98,FALSE) -> 1482874 | AI10: =AH10/AG10 -> 0.57431216 | AJ10: =IF(AI10>=100%,20%,AI10*20%/100%) -> 0.11486243 | AK10: 1.02 | AL10: =VLOOKUP(C10,WB!$C$99:$U$132,WB!$K$98,FALSE) -> 0.94 | AM10: =AL10/AK10 -> 0.92156863 | AN10: =IF(AM10>=100%,10%,AM10*10%/100%) -> 0.092156863 | AO10: 2436 | AP10: =VLOOKUP(C10,WB!$B$3:$O$35,WB!$O$2,FALSE) -> 1158 | AQ10: =AP10/AO10 -> 0.47536946 | AR10: =IF(AQ10>=100%,30%,AQ10*30%/100%) -> 0.14261084 | AS10: 0.25 | AT10: 0.36 | AW10: 0.9 | AX10: =VLOOKUP(C10,WB!$B$42:$U$71,WB!$I$40,FALSE) -> 0.96969697 | AY10: =AX10/AW10 -> 1.0774411 | AZ10: =IF(AND(BC10<100%,AY10>=100%),45%,AY10*45%/100%) -> 0.48484848 | BA10: 0.9 | BB10: =VLOOKUP(C10,WB!$B$42:$U$71,WB!$H$40,FALSE) -> 0.95265306 | BC10: =BB10/BA10 -> 1.0585034 | BD10: =IF(AND(AY10<100%,BC10>=100%),45%,BC10*45%/100%) -> 0.47632653 | BE10: =AR10+AN10+AJ10+W10+S10+K10+G10+AF10+AC10+Z10+O10 -> 0.63988561 | BF10: 0.2
B11: NO MAIN | C11: HND | D11: 0.7 | E11: =VLOOKUP(C11,WB!$C$78:$U$92,WB!$J$76,FALSE) -> 0.663 | F11: =E11/D11 -> 0.94714286 | G11: =IF(F11>=100%,6%,F11*6%/100%) -> 0.056828571 | H11: 0.83 | I11: =VLOOKUP(C11,WB!$C$78:$U$92,WB!$K$76,FALSE) -> 0.991 | J11: =I11/H11 -> 1.1939759 | K11: =IF(J11>=100%,6%,J11*6%/100%) -> 0.06 | L11: NRC Plan FY25-FY26, signed in Q1 FY25 | M11: Signed | N11: 0.1 | O11: =IF(N11>=100%,5%,N11*5%/100%) -> 0.005 | P11: 0.9 | Q11: =AZ11+BD11 -> 0.98637602 | R11: =Q11/P11 -> 1.0959734 | S11: =IF(R11>=100%,4%,R11*4%/100%) -> 0.04 | T11: 0.62 | U11: =VLOOKUP(C11,WB!$C$137:$AA$154,WB!$Q$136,FALSE) -> 0.47816594 | V11: =U11/T11 -> 0.77123539 | W11: =IF(V11>=100%,4%,V11*4%/100%) -> 0.030849415 | X11: Montly Report | Y11: =VLOOKUP(C11,WB!$R$3:$AD$18,WB!$AD$2,FALSE) -> 0.5 | Z11: =IF(Y11>=100%,5%,Y11*5%/100%) -> 0.025 | AA11: Q2 | AB11: 0.5 | AC11: =IF(AB11>=100%,3%,AB11*3%/100%) -> 0.015 | AD11: Q3 | AE11: 0.75 | AF11: =IF(AE11>=100%,7%,AE11*7%/100%) -> 0.0525 | AG11: 2642000 | AH11: =VLOOKUP(C11,WB!$C$99:$U$132,WB!$J$98,FALSE) -> 1604426 | AI11: =AH11/AG11 -> 0.60727706 | AJ11: =IF(AI11>=100%,20%,AI11*20%/100%) -> 0.12145541 | AK11: 1.17 | AL11: =VLOOKUP(C11,WB!$C$99:$U$132,WB!$K$98,FALSE) -> 1.19 | AM11: =AL11/AK11 -> 1.017094 | AN11: =IF(AM11>=100%,10%,AM11*10%/100%) -> 0.1 | AO11: 2620 | AP11: =VLOOKUP(C11,WB!$B$3:$O$35,WB!$O$2,FALSE) -> 1425 | AQ11: =AP11/AO11 -> 0.54389313 | AR11: =IF(AQ11>=100%,30%,AQ11*30%/100%) -> 0.16316794 | AS11: 0.25 | AT11: 0.36 | AW11: 0.9 | AX11: =VLOOKUP(C11,WB!$B$42:$U$71,WB!$I$40,FALSE) -> 1 | AY11: =AX11/AW11 -> 1.1111111 | AZ11: =IF(AND(BC11<100%,AY11>=100%),45%,AY11*45%/100%) -> 0.5 | BA11: 0.9 | BB11: =VLOOKUP(C11,WB!$B$42:$U$71,WB!$H$40,FALSE) -> 0.97275204 | BC11: =BB11/BA11 -> 1.0808356 | BD11: =IF(AND(AY11<100%,BC11>=100%),45%,BC11*45%/100%) -> 0.48637602 | BE11: =AR11+AN11+AJ11+W11+S11+K11+G11+AF11+AC11+Z11+O11 -> 0.66980134 | BF11: 0.2
B12: NO MAIN | C12: NIC | D12: 0.7 | E12: =VLOOKUP(C12,WB!$C$78:$U$92,WB!$J$76,FALSE) -> 0.567 | F12: =E12/D12 -> 0.81 | G12: =IF(F12>=100%,6%,F12*6%/100%) -> 0.0486 | H12: 0.83 | I12: =VLOOKUP(C12,WB!$C$78:$U$92,WB!$K$76,FALSE) -> 0.903 | J12: =I12/H12 -> 1.0879518 | K12: =IF(J12>=100%,6%,J12*6%/100%) -> 0.06 | L12: NRC Plan FY25-FY26, signed in Q1 FY25 | M12: Signed | N12: 0.1 | O12: =IF(N12>=100%,5%,N12*5%/100%) -> 0.005 | P12: 0.9 | Q12: =AZ12+BD12 -> 0.86049672 | R12: =Q12/P12 -> 0.95610747 | S12: =IF(R12>=100%,4%,R12*4%/100%) -> 0.038244299 | T12: 0.75 | U12: =VLOOKUP(C12,WB!$C$137:$AA$154,WB!$Q$136,FALSE) -> 0.54455446 | V12: =U12/T12 -> 0.72607261 | W12: =IF(V12>=100%,4%,V12*4%/100%) -> 0.029042904 | X12: Montly Report | Y12: =VLOOKUP(C12,WB!$R$3:$AD$18,WB!$AD$2,FALSE) -> 0.5 | Z12: =IF(Y12>=100%,5%,Y12*5%/100%) -> 0.025 | AA12: Q2 | AB12: 0.5 | AC12: =IF(AB12>=100%,3%,AB12*3%/100%) -> 0.015 | AD12: Q3 | AE12: 0.75 | AF12: =IF(AE12>=100%,7%,AE12*7%/100%) -> 0.0525 | AG12: 1142000 | AH12: =VLOOKUP(C12,WB!$C$99:$U$132,WB!$J$98,FALSE) -> 579421 | AI12: =AH12/AG12 -> 0.50737391 | AJ12: =IF(AI12>=100%,20%,AI12*20%/100%) -> 0.10147478 | AK12: 0.9 | AL12: =VLOOKUP(C12,WB!$C$99:$U$132,WB!$K$98,FALSE) -> 1.08 | AM12: =AL12/AK12 -> 1.2 | AN12: =IF(AM12>=100%,10%,AM12*10%/100%) -> 0.1 | AO12: 1326 | AP12: =VLOOKUP(C12,WB!$B$3:$O$35,WB!$O$2,FALSE) -> 661 | AQ12: =AP12/AO12 -> 0.4984917 | AR12: =IF(AQ12>=100%,30%,AQ12*30%/100%) -> 0.14954751 | AS12: 0.25 | AT12: 0.36 | AW12: 0.9 | AX12: =VLOOKUP(C12,WB!$B$42:$U$71,WB!$I$40,FALSE) -> 1 | AY12: =AX12/AW12 -> 1.1111111 | AZ12: =IF(AND(BC12<100%,AY12>=100%),45%,AY12*45%/100%) -> 0.45 | BA12: 0.9 | BB12: =VLOOKUP(C12,WB!$B$42:$U$71,WB!$H$40,FALSE) -> 0.82099344 | BC12: =BB12/BA12 -> 0.91221493 | BD12: =IF(AND(AY12<100%,BC12>=100%),45%,BC12*45%/100%) -> 0.41049672 | BE12: =AR12+AN12+AJ12+W12+S12+K12+G12+AF12+AC12+Z12+O12 -> 0.6244095 | BF12: 0.9
B13: NO MAIN | C13: DOM | D13: 0.7 | E13: =VLOOKUP(C13,WB!$C$78:$U$92,WB!$J$76,FALSE) -> 0.763 | F13: =E13/D13 -> 1.09 | G13: =IF(F13>=100%,6%,F13*6%/100%) -> 0.06 | H13: 0.88 | I13: =VLOOKUP(C13,WB!$C$78:$U$92,WB!$K$76,FALSE) -> 0.956 | J13: =I13/H13 -> 1.0863636 | K13: =IF(J13>=100%,6%,J13*6%/100%) -> 0.06 | L13: NRC Plan FY25-FY26, signed in Q1 FY25 | M13: Signed | N13: 0.1 | O13: =IF(N13>=100%,5%,N13*5%/100%) -> 0.005 | P13: 0.9 | Q13: =AZ13+BD13 -> 1 | R13: =Q13/P13 -> 1.1111111 | S13: =IF(R13>=100%,4%,R13*4%/100%) -> 0.04 | T13: 0.74 | U13: =VLOOKUP(C13,WB!$C$137:$AA$154,WB!$Q$136,FALSE) -> 0.73988439 | V13: =U13/T13 -> 0.99984377 | W13: =IF(V13>=100%,4%,V13*4%/100%) -> 0.039993751 | X13: Montly Report | Y13: =VLOOKUP(C13,WB!$R$3:$AD$18,WB!$AD$2,FALSE) -> 0.6 | Z13: =IF(Y13>=100%,5%,Y13*5%/100%) -> 0.03 | AA13: Q3 | AB13: 0.75 | AC13: =IF(AB13>=100%,3%,AB13*3%/100%) -> 0.0225 | AD13: Q3 | AE13: 0.75 | AF13: =IF(AE13>=100%,7%,AE13*7%/100%) -> 0.0525 | AG13: 3400000 | AH13: =VLOOKUP(C13,WB!$C$99:$U$132,WB!$J$98,FALSE) -> 1760989 | AI13: =AH13/AG13 -> 0.51793794 | AJ13: =IF(AI13>=100%,20%,AI13*20%/100%) -> 0.10358759 | AK13: 1.48 | AL13: =VLOOKUP(C13,WB!$C$99:$U$132,WB!$K$98,FALSE) -> 1.44 | AM13: =AL13/AK13 -> 0.97297297 | AN13: =IF(AM13>=100%,10%,AM13*10%/100%) -> 0.097297297 | AO13: 2390 | AP13: =VLOOKUP(C13,WB!$B$3:$O$35,WB!$O$2,FALSE) -> 990 | AQ13: =AP13/AO13 -> 0.41422594 | AR13: =IF(AQ13>=100%,30%,AQ13*30%/100%) -> 0.12426778 | AS13: 0.23 | AT13: 0.33 | AW13: 0.9 | AX13: =VLOOKUP(C13,WB!$B$42:$U$71,WB!$I$40,FALSE) -> 1 | AY13: =AX13/AW13 -> 1.1111111 | AZ13: =IF(AND(BC13<100%,AY13>=100%),45%,AY13*45%/100%) -> 0.5 | BA13: 0.9 | BB13: =VLOOKUP(C13,WB!$B$42:$U$71,WB!$H$40,FALSE) -> 1 | BC13: =BB13/BA13 -> 1.1111111 | BD13: =IF(AND(AY13<100%,BC13>=100%),45%,BC13*45%/100%) -> 0.5 | BE13: =AR13+AN13+AJ13+W13+S13+K13+G13+AF13+AC13+Z13+O13 -> 0.63514642 | BF13: 0.7
B14: NO MAIN | C14: GUT | D14: 0.75 | E14: =VLOOKUP(C14,WB!$C$78:$U$92,WB!$J$76,FALSE) -> 0.761 | F14: =E14/D14 -> 1.0146667 | G14: =IF(F14>=100%,6%,F14*6%/100%) -> 0.06 | H14: 0.83 | I14: =VLOOKUP(C14,WB!$C$78:$U$92,WB!$K$76,FALSE) -> 0.878 | J14: =I14/H14 -> 1.0578313 | K14: =IF(J14>=100%,6%,J14*6%/100%) -> 0.06 | L14: NRC Plan FY25-FY26, signed in Q1 FY25 | M14: Signed | N14: 0.1 | O14: =IF(N14>=100%,5%,N14*5%/100%) -> 0.005 | P14: 0.9 | Q14: =AZ14+BD14 -> 0.86935484 | R14: =Q14/P14 -> 0.96594982 | S14: =IF(R14>=100%,4%,R14*4%/100%) -> 0.038637993 | T14: 0.71 | U14: =VLOOKUP(C14,WB!$C$137:$AA$154,WB!$Q$136,FALSE) -> 0.54352941 | V14: =U14/T14 -> 0.76553438 | W14: =IF(V14>=100%,4%,V14*4%/100%) -> 0.030621375 | X14: Montly Report | Y14: =VLOOKUP(C14,WB!$R$3:$AD$18,WB!$AD$2,FALSE) -> 0.5 | Z14: =IF(Y14>=100%,5%,Y14*5%/100%) -> 0.025 | AA14: NA | AB14: NA | AD14: Q3 | AE14: 0.75 | AF14: =IF(AE14>=100%,10%,AE14*10%/100%) -> 0.075 | AG14: 2360000 | AH14: =VLOOKUP(C14,WB!$C$99:$U$132,WB!$J$98,FALSE) -> 1705808 | AI14: =AH14/AG14 -> 0.7228 | AJ14: =IF(AI14>=100%,20%,AI14*20%/100%) -> 0.14456 | AK14: 1.39 | AL14: =VLOOKUP(C14,WB!$C$99:$U$132,WB!$K$98,FALSE) -> 1.37 | AM14: =AL14/AK14 -> 0.98561151 | AN14: =IF(AM14>=100%,10%,AM14*10%/100%) -> 0.098561151 | AO14: 2400 | AP14: =VLOOKUP(C14,WB!$B$3:$O$35,WB!$O$2,FALSE) -> 1165 | AQ14: =AP14/AO14 -> 0.48541667 | AR14: =IF(AQ14>=100%,30%,AQ14*30%/100%) -> 0.145625 | AS14: 0.28 | AT14: 0.4 | AW14: 0.9 | AX14: =VLOOKUP(C14,WB!$B$42:$U$71,WB!$I$40,FALSE) -> 0.94 | AY14: =AX14/AW14 -> 1.0444444 | AZ14: =IF(AND(BC14<100%,AY14>=100%),45%,AY14*45%/100%) -> 0.45 | BA14: 0.9 | BB14: =VLOOKUP(C14,WB!$B$42:$U$71,WB!$H$40,FALSE) -> 0.83870968 | BC14: =BB14/BA14 -> 0.93189964 | BD14: =IF(AND(AY14<100%,BC14>=100%),45%,BC14*45%/100%) -> 0.41935484 | BE14: =AR14+AN14+AJ14+W14+S14+K14+G14+AF14+AC14+Z14+O14 -> 0.68300552 | BF14: 0.3
B15: NO MAIN | C15: PRG | D15: 0.84 | E15: =VLOOKUP(C15,WB!$C$78:$U$92,WB!$J$76,FALSE) -> 0.892 | F15: =E15/D15 -> 1.0619048 | G15: =IF(F15>=100%,6%,F15*6%/100%) -> 0.06 | H15: 0.9 | I15: =VLOOKUP(C15,WB!$C$78:$U$92,WB!$K$76,FALSE) -> 0.945 | J15: =I15/H15 -> 1.05 | K15: =IF(J15>=100%,6%,J15*6%/100%) -> 0.06 | L15: NRC Plan FY25-FY26, signed in Q1 FY25 | M15: Signed | N15: 0.1 | O15: =IF(N15>=100%,5%,N15*5%/100%) -> 0.005 | P15: 0.9 | Q15: =AZ15+BD15 -> 0.88478261 | R15: =Q15/P15 -> 0.98309179 | S15: =IF(R15>=100%,4%,R15*4%/100%) -> 0.039323671 | T15: 0.74 | U15: =VLOOKUP(C15,WB!$C$137:$AA$154,WB!$Q$136,FALSE) -> 0.70674487 | V15: =U15/T15 -> 0.95506063 | W15: =IF(V15>=100%,4%,V15*4%/100%) -> 0.038202425 | X15: Montly Report | Y15: =VLOOKUP(C15,WB!$R$3:$AD$18,WB!$AD$2,FALSE) -> 0.2 | Z15: =IF(Y15>=100%,5%,Y15*5%/100%) -> 0.01 | AA15: NA | AB15: NA | AD15: Q3 | AE15: 0.75 | AF15: =IF(AE15>=100%,10%,AE15*10%/100%) -> 0.075 | AG15: 4850000 | AH15: =VLOOKUP(C15,WB!$C$99:$U$132,WB!$J$98,FALSE) -> 2167868 | AI15: =AH15/AG15 -> 0.44698309 | AJ15: =IF(AI15>=100%,20%,AI15*20%/100%) -> 0.089396619 | AK15: 1.27 | AL15: =VLOOKUP(C15,WB!$C$99:$U$132,WB!$K$98,FALSE) -> 1.56 | AM15: =AL15/AK15 -> 1.2283465 | AN15: =IF(AM15>=100%,10%,AM15*10%/100%) -> 0.1 | AO15: 2300 | AP15: =VLOOKUP(C15,WB!$B$3:$O$35,WB!$O$2,FALSE) -> 1061 | AQ15: =AP15/AO15 -> 0.46130435 | AR15: =IF(AQ15>=100%,30%,AQ15*30%/100%) -> 0.1383913 | AS15: 0.28 | AT15: 0.41 | AW15: 0.9 | AX15: =VLOOKUP(C15,WB!$B$42:$U$71,WB!$I$40,FALSE) -> 0.86956522 | AY15: =AX15/AW15 -> 0.96618357 | AZ15: =IF(AND(BC15<100%,AY15>=100%),45%,AY15*45%/100%) -> 0.43478261 | BA15: 0.9 | BB15: =VLOOKUP(C15,WB!$B$42:$U$71,WB!$H$40,FALSE) -> 0.93508937 | BC15: =BB15/BA15 -> 1.0389882 | BD15: =IF(AND(AY15<100%,BC15>=100%),45%,BC15*45%/100%) -> 0.45 | BE15: =AR15+AN15+AJ15+W15+S15+K15+G15+AF15+AC15+Z15+O15 -> 0.61531402
B16: NO MAIN | C16: BOL | D16: 0.85 | E16: =VLOOKUP(C16,WB!$C$78:$U$92,WB!$J$76,FALSE) -> 0.895 | F16: =E16/D16 -> 1.0529412 | G16: =IF(F16>=100%,6%,F16*6%/100%) -> 0.06 | H16: 0.87 | I16: =VLOOKUP(C16,WB!$C$78:$U$92,WB!$K$76,FALSE) -> 0.934 | J16: =I16/H16 -> 1.0735632 | K16: =IF(J16>=100%,6%,J16*6%/100%) -> 0.06 | L16: NRC Plan FY25-FY26, signed in Q1 FY25 | M16: Signed | N16: 0.1 | O16: =IF(N16>=100%,5%,N16*5%/100%) -> 0.005 | P16: 0.9 | Q16: =AZ16+BD16 -> 0.9619096 | R16: =Q16/P16 -> 1.0687884 | S16: =IF(R16>=100%,4%,R16*4%/100%) -> 0.04 | T16: 0.68 | U16: =VLOOKUP(C16,WB!$C$137:$AA$154,WB!$Q$136,FALSE) -> 0.55658436 | V16: =U16/T16 -> 0.81850641 | W16: =IF(V16>=100%,4%,V16*4%/100%) -> 0.032740257 | X16: Montly Report | Y16: =VLOOKUP(C16,WB!$R$3:$AD$18,WB!$AD$2,FALSE) -> 0.5 | Z16: =IF(Y16>=100%,5%,Y16*5%/100%) -> 0.025 | AA16: NA | AB16: NA | AD16: Q3 | AE16: 0.75 | AF16: =IF(AE16>=100%,10%,AE16*10%/100%) -> 0.075 | AG16: 2153000 | AH16: =VLOOKUP(C16,WB!$C$99:$U$132,WB!$J$98,FALSE) -> 862181 | AI16: =AH16/AG16 -> 0.40045564 | AJ16: =IF(AI16>=100%,20%,AI16*20%/100%) -> 0.080091129 | AK16: 0.84 | AL16: =VLOOKUP(C16,WB!$C$99:$U$132,WB!$K$98,FALSE) -> 0.81 | AM16: =AL16/AK16 -> 0.96428571 | AN16: =IF(AM16>=100%,10%,AM16*10%/100%) -> 0.096428571 | AO16: 1100 | AP16: =VLOOKUP(C16,WB!$B$3:$O$35,WB!$O$2,FALSE) -> 617 | AQ16: =AP16/AO16 -> 0.56090909 | AR16: =IF(AQ16>=100%,30%,AQ16*30%/100%) -> 0.16827273 | AS16: 0.36 | AT16: 0.41 | AW16: 0.9 | AX16: =VLOOKUP(C16,WB!$B$42:$U$71,WB!$I$40,FALSE) -> 1 | AY16: =AX16/AW16 -> 1.1111111 | AZ16: =IF(AND(BC16<100%,AY16>=100%),45%,AY16*45%/100%) -> 0.5 | BA16: 0.9 | BB16: =VLOOKUP(C16,WB!$B$42:$U$71,WB!$H$40,FALSE) -> 0.9238192 | BC16: =BB16/BA16 -> 1.0264658 | BD16: =IF(AND(AY16<100%,BC16>=100%),45%,BC16*45%/100%) -> 0.4619096 | BE16: =AR16+AN16+AJ16+W16+S16+K16+G16+AF16+AC16+Z16+O16 -> 0.64253268 | BF16: 0.5
B17: RHD | C17: MASSY | D17: 0.7 | E17: =VLOOKUP(C17,WB!$C$78:$U$92,WB!$J$76,FALSE) -> 0.562 | F17: =E17/D17 -> 0.80285714 | G17: =IF(F17>=100%,6%,F17*6%/100%) -> 0.048171429 | H17: 0.88 | I17: =VLOOKUP(C17,WB!$C$78:$U$92,WB!$K$76,FALSE) -> 0.93 | J17: =I17/H17 -> 1.0568182 | K17: =IF(J17>=100%,6%,J17*6%/100%) -> 0.06 | L17: NRC Plan FY25-FY26, signed in Q1 FY25 | M17: Signed | N17: 0.1 | O17: =IF(N17>=100%,5%,N17*5%/100%) -> 0.005 | P17: 0.9 | Q17: =AZ17+BD17 -> 0.79826013 | R17: =Q17/P17 -> 0.8869557 | S17: =IF(R17>=100%,4%,R17*4%/100%) -> 0.035478228 | T17: 0.53 | U17: =VLOOKUP(C17,WB!$C$137:$AA$154,WB!$Q$136,FALSE) -> 0 | V17: =U17/T17 -> 0 | W17: =IF(V17>=100%,4%,V17*4%/100%) -> 0 | X17: Montly Report | Y17: =VLOOKUP(C17,WB!$R$3:$AD$18,WB!$AD$2,FALSE) -> 0.5 | Z17: =IF(Y17>=100%,5%,Y17*5%/100%) -> 0.025 | AA17: NA | AB17: NA | AD17: Q3 | AE17: 0.75 | AF17: =IF(AE17>=100%,10%,AE17*10%/100%) -> 0.075 | AG17: 700000 | AH17: =VLOOKUP(C17,WB!$C$99:$U$132,WB!$J$98,FALSE) -> 219059 | AI17: =AH17/AG17 -> 0.31294143 | AJ17: =IF(AI17>=100%,20%,AI17*20%/100%) -> 0.062588286 | AK17: 1.03 | AL17: =VLOOKUP(C17,WB!$C$99:$U$132,WB!$K$98,FALSE) -> 0 | AM17: =AL17/AK17 -> 0 | AN17: =IF(AM17>=100%,10%,AM17*10%/100%) -> 0 | AO17: 1269 | AP17: =VLOOKUP(C17,WB!$B$3:$O$37,WB!$O$2,FALSE) -> 774 | AQ17: =AP17/AO17 -> 0.60992908 | AR17: =IF(AQ17>=100%,30%,AQ17*30%/100%) -> 0.18297872 | AS17: 0.36 | AT17: 0.41 | AW17: 0.9 | AX17: =VLOOKUP(C17,WB!$B$42:$U$73,WB!$I$40,FALSE) -> 0.95218855 | AY17: =AX17/AW17 -> 1.0579873 | AZ17: =IF(AND(BC17<100%,AY17>=100%),45%,AY17*45%/100%) -> 0.45 | BA17: 0.9 | BB17: =VLOOKUP(C17,WB!$B$42:$U$73,WB!$H$40,FALSE) -> 0.69652026 | BC17: =BB17/BA17 -> 0.7739114 | BD17: =IF(AND(AY17<100%,BC17>=100%),45%,BC17*45%/100%) -> 0.34826013 | BE17: =AR17+AN17+AJ17+W17+S17+K17+G17+AF17+AC17+Z17+O17 -> 0.49421667 | BF17: 0.65
B18: RHD | C18: GEL | D18: - | E18: - | F18: - | G18: - | H18: - | I18: - | J18: - | K18: - | L18: NRC Plan FY25-FY26, signed in Q1 FY25 | M18: Signed | N18: 0.1 | O18: =IF(N18>=100%,5%,N18*5%/100%) -> 0.005 | P18: 0.9 | Q18: =AZ18+BD18 -> 0.52876084 | R18: =Q18/P18 -> 0.58751205 | S18: =IF(R18>=100%,5%,R18*5%/100%) -> 0.029375602 | T18: 0.63 | U18: =VLOOKUP(C18,WB!$C$137:$AA$154,WB!$Q$136,FALSE) -> 0.37886598 | V18: =U18/T18 -> 0.60137457 | W18: =IF(V18>=100%,5%,V18*5%/100%) -> 0.030068729 | X18: Montly Report | Y18: =VLOOKUP(C18,WB!$R$3:$AD$18,WB!$AD$2,FALSE) -> 0.4 | Z18: =IF(Y18>=100%,5%,Y18*5%/100%) -> 0.02 | AA18: NA | AB18: NA | AD18: Q3 | AE18: 0.75 | AF18: =IF(AE18>=100%,10%,AE18*10%/100%) -> 0.075 | AG18: 100000 | AH18: =VLOOKUP(C18,WB!$C$99:$U$132,WB!$J$98,FALSE) -> 55143 | AI18: =AH18/AG18 -> 0.55143 | AJ18: =IF(AI18>=100%,25%,AI18*25%/100%) -> 0.1378575 | AK18: 2.02 | AL18: =VLOOKUP(C18,WB!$C$99:$U$132,WB!$K$98,FALSE) -> 0 | AM18: =AL18/AK18 -> 0 | AN18: =IF(AM18>=100%,10%,AM18*10%/100%) -> 0 | AO18: 742 | AP18: =VLOOKUP(C18,WB!$B$3:$O$37,WB!$O$2,FALSE) -> 320 | AQ18: =AP18/AO18 -> 0.43126685 | AR18: =IF(AQ18>=100%,35%,AQ18*35%/100%) -> 0.1509434 | AS18: NA | AT18: NA | AW18: 0.9 | AX18: =VLOOKUP(C18,WB!$B$42:$U$73,WB!$I$40,FALSE) -> 0.75800866 | AY18: =AX18/AW18 -> 0.84223184 | AZ18: =IF(AND(BC18<100%,AY18>=100%),45%,AY18*45%/100%) -> 0.37900433 | BA18: 0.9 | BB18: =VLOOKUP(C18,WB!$B$42:$U$73,WB!$H$40,FALSE) -> 0.29951303 | BC18: =BB18/BA18 -> 0.33279226 | BD18: =IF(AND(AY18<100%,BC18>=100%),45%,BC18*45%/100%) -> 0.14975652 | BE18: =AR18+AN18+AJ18+W18+S18+AF18+Z18+O18 -> 0.44824523 | BF18: 0.95
B19: No Annual Plan | C19: HIT | D19: - | E19: - | F19: - | H19: NA | I19: NA | J19: - | L19: NA | P19: 0.9 | Q19: =AZ19+BD19 -> 0.0017793594 | R19: =Q19/P19 -> 0.001977066 | T19: 0.75 | U19: =VLOOKUP(C19,Sheet2!$B$38:$D$52,Sheet2!$D$37,FALSE) -> #N/A | V19: =U19/T19 -> #N/A | X19: NA | AG19: 597149 | AH19: =VLOOKUP(C19,WB!$C$99:$U$132,WB!$J$98,FALSE) -> 290483 | AI19: =AH19/AG19 -> 0.48644978 | AK19: 0.51 | AL19: =VLOOKUP(C19,WB!$C$99:$U$132,WB!$K$98,FALSE) -> - | AM19: =AL19/AK19 -> #VALUE! | AO19: 115 | AP19: =VLOOKUP(C19,WB!$B$3:$O$35,WB!$O$2,FALSE) -> 95 | AQ19: =AP19/AO19 -> 0.82608696 | AS19: NA | AT19: NA | AW19: 0.9 | AX19: =VLOOKUP(C19,WB!$B$42:$U$71,WB!$I$40,FALSE) -> 0 | AY19: =AX19/AW19 -> 0 | AZ19: =IF(AND(BC19<100%,AY19>=100%),45%,AY19*45%/100%) -> 0 | BA19: 0.9 | BB19: =VLOOKUP(C19,WB!$B$42:$U$71,WB!$H$40,FALSE) -> 0.0035587189 | BC19: =BB19/BA19 -> 0.0039541321 | BD19: =IF(AND(AY19<100%,BC19>=100%),45%,BC19*45%/100%) -> 0.0017793594
B20: No Annual Plan | C20: ALB | D20: - | E20: - | F20: - | H20: NA | I20: NA | J20: - | L20: NA | P20: 0.9 | Q20: =AZ20+BD20 -> 0.86891892 | R20: =Q20/P20 -> 0.96546547 | T20: 0.71 | U20: =VLOOKUP(C20,Sheet2!$B$38:$D$52,Sheet2!$D$37,FALSE) -> #N/A | V20: =U20/T20 -> #N/A | X20: NA | AG20: 320320 | AH20: =VLOOKUP(C20,WB!$C$99:$U$132,WB!$J$98,FALSE) -> 168353 | AI20: =AH20/AG20 -> 0.52557755 | AK20: 0.6 | AL20: =VLOOKUP(C20,WB!$C$99:$U$132,WB!$K$98,FALSE) -> - | AM20: =AL20/AK20 -> #VALUE! | AO20: - | AP20: =VLOOKUP(C20,WB!$B$3:$O$35,WB!$O$2,FALSE) -> 166 | AQ20: - | AR20: - | AS20: NA | AT20: NA | AW20: 0.9 | AX20: =VLOOKUP(C20,WB!$B$42:$U$71,WB!$I$40,FALSE) -> 1 | AY20: =AX20/AW20 -> 1.1111111 | AZ20: =IF(AND(BC20<100%,AY20>=100%),45%,AY20*45%/100%) -> 0.45 | BA20: 0.9 | BB20: =VLOOKUP(C20,WB!$B$42:$U$71,WB!$H$40,FALSE) -> 0.83783784 | BC20: =BB20/BA20 -> 0.93093093 | BD20: =IF(AND(AY20<100%,BC20>=100%),45%,BC20*45%/100%) -> 0.41891892
B21: No Annual Plan | C21: BLZ | D21: - | E21: - | F21: - | H21: NA | I21: NA | J21: - | L21: NA | P21: 0.9 | Q21: =AZ21+BD21 -> 0.26775956 | R21: =Q21/P21 -> 0.29751063 | T21: 0.75 | U21: =VLOOKUP(C21,Sheet2!$B$38:$D$52,Sheet2!$D$37,FALSE) -> #N/A | V21: =U21/T21 -> #N/A | X21: NA | AG21: 113417 | AH21: =VLOOKUP(C21,WB!$C$99:$U$132,WB!$J$98,FALSE) -> 53204 | AI21: =AH21/AG21 -> 0.46910075 | AK21: 2.3 | AL21: =VLOOKUP(C21,WB!$C$99:$U$132,WB!$K$98,FALSE) -> - | AM21: =AL21/AK21 -> #VALUE! | AO21: - | AP21: =VLOOKUP(C21,WB!$B$3:$O$35,WB!$O$2,FALSE) -> 22 | AQ21: - | AR21: - | AS21: NA | AT21: NA | AW21: 0.9 | AX21: =VLOOKUP(C21,WB!$B$42:$U$71,WB!$I$40,FALSE) -> 0 | AY21: =AX21/AW21 -> 0 | AZ21: =IF(AND(BC21<100%,AY21>=100%),45%,AY21*45%/100%) -> 0 | BA21: 0.9 | BB21: =VLOOKUP(C21,WB!$B$42:$U$71,WB!$H$40,FALSE) -> 0.53551913 | BC21: =BB21/BA21 -> 0.59502125 | BD21: =IF(AND(AY21<100%,BC21>=100%),45%,BC21*45%/100%) -> 0.26775956
B22: No Annual Plan | C22: CUR | D22: - | E22: - | F22: - | H22: NA | I22: NA | J22: - | L22: NA | P22: 0.9 | Q22: =AZ22+BD22 -> 1 | R22: =Q22/P22 -> 1.1111111 | T22: 0.57 | U22: =VLOOKUP(C22,Sheet2!$B$38:$D$52,Sheet2!$D$37,FALSE) -> #N/A | V22: =U22/T22 -> #N/A | X22: NA | AG22: 266933 | AH22: =VLOOKUP(C22,WB!$C$99:$U$132,WB!$J$98,FALSE) -> 177187 | AI22: =AH22/AG22 -> 0.66378829 | AK22: 0.59 | AL22: =VLOOKUP(C22,WB!$C$99:$U$132,WB!$K$98,FALSE) -> - | AM22: =AL22/AK22 -> #VALUE! | AO22: - | AP22: =VLOOKUP(C22,WB!$B$3:$O$35,WB!$O$2,FALSE) -> 172 | AQ22: - | AR22: - | AS22: NA | AT22: NA | AW22: 0.9 | AX22: =VLOOKUP(C22,WB!$B$42:$U$71,WB!$I$40,FALSE) -> 1 | AY22: =AX22/AW22 -> 1.1111111 | AZ22: =IF(AND(BC22<100%,AY22>=100%),45%,AY22*45%/100%) -> 0.5 | BA22: 0.9 | BB22: =VLOOKUP(C22,WB!$B$42:$U$71,WB!$H$40,FALSE) -> 1 | BC22: =BB22/BA22 -> 1.1111111 | BD22: =IF(AND(AY22<100%,BC22>=100%),45%,BC22*45%/100%) -> 0.5

Sheet Annual Plan
F9: CUSTOMER EXPERIENCE | Z9: BRAND POWER | AI9: SUSTAINABLE GROWTH
B10: Priority | C10: BDM | D10: RAM | E10: Market | F10: CSI | G10: Real CSI | H10: %Ach. CSI | I10: pts CSI | J10: SSI | K10: Real SSI | L10: %Ach. SSI | M10: pts SSI | N10: NRC Implementation | O10: Status NRC | P10: %Ach. NRC | Q10: pts NRC | R10: Trainin (Compliance %) | S10: Real TR | T10: %Ach. TR | U10: pts TR | V10: Service Campaing | W10: Real SC | X10: %Ach. SC | Y10: pts SC | Z10: Lead Management | AA10: %Ach. Lead Mang. | AB10: pts Lead | AC10: Share of Investment | AD10: %Ach. SOI | AE10: pts SOI | AF10: 360 Game Plan | AG10: % Ach. 360 | AH10: pts 360 | AI10: Sell In (USD) | AJ10: Real Sell In | AK10: %Ach. Sell In | AL10: pts Sell In | AM10: Retention | AN10: Real Retention | AO10: %Ach. Retention | AP10: pts Retention | AQ10: Retail Sales | AR10: Real RS | AS10: %Ach. RS | AT10: pts RS | AU10: TR Sales | AV10: Real TR Sales | AW10: %Ach. TR Sales | AX10: pts TR Sales | AY10: TR AS | AZ10: Real TR AS | BA10: %Ach. TR AS | BB10: pts TR AS | BC10: Total
B11: 6 MAIN | C11: Wilson Rincon | D11: Eduardo Trabado | E11: COL | F11: 0.78 | G11: 0.784 | H11: 1.0051282 | I11: 0.06 | J11: 0.92 | K11: 0.957 | L11: 1.0402174 | M11: 0.06 | N11: NRC Plan FY25-FY26, signed in Q1 FY25 | O11: Signed | P11: 0.1 | Q11: 0.005 | R11: 0.9 | S11: 0.8703149 | T11: 0.96701656 | U11: 0.038680662 | V11: 0.69 | W11: 0.58911429 | X11: 0.85378883 | Y11: 0.034151553 | Z11: > All Channels (Phisicals and Digitals) > Per model > Per month FCST (1 week before starting N month) > Per month Results (1 week after N month closure) | AA11: 0.4 | AB11: 0.02 | AC11: Q2 | AD11: 0.25 | AE11: 0.0075 | AF11: Q2 | AG11: 0.5 | AH11: 0.035 | AI11: 22300000 | AJ11: 6737647 | AK11: 0.30213664 | AL11: 0.060427327 | AM11: 1 | AN11: 1.04 | AO11: 1.04 | AP11: 0.1 | AQ11: 13201 | AR11: 5300 | AS11: 0.40148474 | AT11: 0.12044542 | AU11: 0.9 | AV11: 0.99531465 | AW11: 1.1059052 | AX11: 0.45 | AY11: 0.9 | AZ11: 0.8406298 | BA11: 0.93403311 | BB11: 0.4203149 | BC11: 0.54120496
B12: 6 MAIN | C12: Diego Suarez | D12: Salvador Alvarez | E12: PLT | F12: 0.82 | G12: 0.838 | H12: 1.0219512 | I12: 0.06 | J12: 0.91 | K12: 0.918 | L12: 1.0087912 | M12: 0.06 | N12: NRC Plan FY25-FY26, signed in Q1 FY25 | O12: WIP | P12: 0 | Q12: 0 | R12: 0.9 | S12: 0 | T12: 0 | U12: 0 | V12: 0.5 | W12: 0.37859054 | X12: 0.75718109 | Y12: 0.030287244 | Z12: > All Channels (Phisicals and Digitals) > Per model > Per month FCST (1 week before starting N month) > Per month Results (1 week after N month closure) | AA12: 0.3 | AB12: 0.015 | AC12: Q2 | AD12: 0.25 | AE12: 0.0075 | AF12: Q2 | AG12: 0.5 | AH12: 0.035 | AI12: 3200000 | AJ12: 975247 | AK12: 0.30476469 | AL12: 0.060952938 | AM12: 0.86 | AN12: 0.86 | AO12: 1 | AP12: 0.1 | AQ12: 6363 | AR12: 2909 | AS12: 0.45717429 | AT12: 0.13715229 | AU12: 0.9 | AV12: 0 | AW12: 0 | AX12: 0 | AY12: 0.9 | AZ12: 0 | BA12: 0 | BB12: 0 | BC12: 0.50589247
B13: 6 MAIN | C13: Wilson Rincon | D13: Salvador Alvarez | E13: CST | F13: 0.92 | G13: 0.951 | H13: 1.0336957 | I13: 0.06 | J13: 0.92 | K13: 0.935 | L13: 1.0163043 | M13: 0.06 | N13: NRC Plan FY25-FY26, signed in Q1 FY25 | O13: Signed | P13: 0.1 | Q13: 0.005 | R13: 0.9 | S13: 1 | T13: 1.1111111 | U13: 0.04 | V13: 0.56 | W13: 0.51374465 | X13: 0.91740117 | Y13: 0.036696047 | Z13: > All Channels (Phisicals and Digitals) > Per model > Per month FCST (1 week before starting N month) > Per month Results (1 week after N month closure) | AA13: 0.3 | AB13: 0.015 | AC13: Q2 | AD13: 0.25 | AE13: 0.0075 | AF13: Q2 | AG13: 0.5 | AH13: 0.035 | AI13: 6300000 | AJ13: 3008469 | AK13: 0.47753476 | AL13: 0.095506952 | AM13: 1.32 | AN13: 1.33 | AO13: 1.0075758 | AP13: 0.1 | AQ13: 7091 | AR13: 3053 | AS13: 0.43054576 | AT13: 0.12916373 | AU13: 0.9 | AV13: 1 | AW13: 1.1111111 | AX13: 0.5 | AY13: 0.9 | AZ13: 1 | BA13: 1.1111111 | BB13: 0.5 | BC13: 0.58386673
B14: 6 MAIN | C14: Tomas Arias | D14: Alberto Saldaña | E14: ECA | F14: 0.85 | G14: 0.868 | H14: 1.0211765 | I14: 0.06 | J14: 0.94 | K14: 0.982 | L14: 1.0446809 | M14: 0.06 | N14: Dealer Network Plan Proposal Approved by NIBU - Q3 | O14: Signed | P14: 0.1 | Q14: 0.005 | R14: 0.9 | S14: 0.95741209 | T14: 1.0637912 | U14: 0.04 | V14: 0.55 | W14: 0.62640587 | X14: 1.1389198 | Y14: 0.04 | Z14: > All Channels (Phisicals and Digitals) > Per model > Per month FCST (1 week before starting N month) > Per month Results (1 week after N month closure) | AA14: 0.4 | AB14: 0.02 | AC14: Q2 | AD14: 0.25 | AE14: 0.0075 | AF14: Q2 | AG14: 0.5 | AH14: 0.035 | AI14: 4600000 | AJ14: 1548634 | AK14: 0.33665957 | AL14: 0.067331913 | AM14: 1.04 | AN14: 1.04 | AO14: 1 | AP14: 0.1 | AQ14: 1750 | AR14: 669 | AS14: 0.38228571 | AT14: 0.11468571 | AU14: 0.9 | AV14: 0.95864198 | AW14: 1.0651578 | AX14: 0.47932099 | AY14: 0.9 | AZ14: 0.95618221 | BA14: 1.0624247 | BB14: 0.47809111 | BC14: 0.54951763
B15: 6 MAIN | C15: Tomas Arias | D15: Jessica Vargas | E15: PNM | F15: 0.86 | G15: 0.879 | H15: 1.022093 | I15: 0.06 | J15: 0.9 | K15: 0.976 | L15: 1.0844444 | M15: 0.06 | N15: NRC Plan FY25-FY26, signed in Q1 FY25 | O15: Signed | P15: 0.1 | Q15: 0.005 | R15: 0.9 | S15: 1 | T15: 1.1111111 | U15: 0.04 | V15: 0.66 | W15: 0.68874869 | X15: 1.0435586 | Y15: 0.04 | Z15: > All Channels (Phisicals and Digitals) > Per model > Per month FCST (1 week before starting N month) > Per month Results (1 week after N month closure) | AA15: 0.4 | AB15: 0.02 | AC15: Q2 | AD15: 0.25 | AE15: 0.0075 | AF15: Q2 | AG15: 0.5 | AH15: 0.035 | AI15: 5130381 | AJ15: 1426757 | AK15: 0.27809962 | AL15: 0.055619924 | AM15: 0.77 | AN15: 0.77 | AO15: 1 | AP15: 0.1 | AQ15: 2600 | AR15: 750 | AS15: 0.28846154 | AT15: 0.086538462 | AU15: 0.9 | AV15: 1 | AW15: 1.1111111 | AX15: 0.5 | AY15: 0.9 | AZ15: 1 | BA15: 1.1111111 | BB15: 0.5 | BC15: 0.50965839
B16: 6 MAIN | C16: Diego Suarez | D16: Alberto Saldaña | E16: URU | F16: 0.94 | G16: 0.993 | H16: 1.056383 | I16: 0.06 | J16: 0.95 | K16: 0.986 | L16: 1.0378947 | M16: 0.06 | N16: NRC Plan FY25-FY26, signed in Q1 FY25 | O16: Signed | P16: 0.1 | Q16: 0.005 | R16: 0.9 | S16: 0.90621693 | T16: 1.0069077 | U16: 0.04 | V16: 0.45 | W16: 0.40168443 | X16: 0.89263206 | Y16: 0.035705282 | Z16: > All Channels (Phisicals and Digitals) > Per model > Per month FCST (1 week before starting N month) > Per month Results (1 week after N month closure) | AA16: 0.4 | AB16: 0.02 | AC16: Q2 | AD16: 0.25 | AE16: 0.0075 | AF16: Q2 | AG16: 0.5 | AH16: 0.035 | AI16: 2730000 | AJ16: 1143779 | AK16: 0.41896667 | AL16: 0.083793333 | AM16: 0.85 | AN16: 0.85 | AO16: 1 | AP16: 0.1 | AQ16: 2200 | AR16: 618 | AS16: 0.28090909 | AT16: 0.084272727 | AU16: 0.9 | AV16: 0.90604575 | AW16: 1.0067175 | AX16: 0.45302288 | AY16: 0.9 | AZ16: 0.90638811 | BA16: 1.0070979 | BB16: 0.45319405 | BC16: 0.53127134
B17: NO MAIN | C17: Pablo Brito | D17: Jessica Vargas | E17: ELS | F17: 0.7 | G17: 0.777 | H17: 1.11 | I17: 0.06 | J17: 0.83 | K17: 0.945 | L17: 1.1385542 | M17: 0.06 | N17: NRC Plan FY25-FY26, signed in Q1 FY25 | O17: Signed | P17: 0.1 | Q17: 0.005 | R17: 0.9 | S17: 0.97713831 | T17: 1.0857092 | U17: 0.04 | V17: 0.67 | W17: 0.51345756 | X17: 0.76635456 | Y17: 0.030654183 | Z17: > All Channels (Phisicals and Digitals) > Per model > Per month FCST (1 week before starting N month) > Per month Results (1 week after N month closure) | AA17: 0.3 | AB17: 0.015 | AC17: Q2 | AD17: 0.25 | AE17: 0.0075 | AF17: Q2 | AG17: 0.5 | AH17: 0.035 | AI17: 2582000 | AJ17: 1000559 | AK17: 0.38751317 | AL17: 0.077502634 | AM17: 1.02 | AN17: 0.93 | AO17: 0.91176471 | AP17: 0.091176471 | AQ17: 2436 | AR17: 847 | AS17: 0.34770115 | AT17: 0.10431034 | AU17: 0.9 | AV17: 0.96428571 | AW17: 1.0714286 | AX17: 0.48214286 | AY17: 0.9 | AZ17: 0.9899909 | BA17: 1.0999899 | BB17: 0.49499545 | BC17: 0.52614363
B18: NO MAIN | C18: Pablo Brito | D18: Jessica Vargas | E18: HND | F18: 0.7 | G18: 0.643 | H18: 0.91857143 | I18: 0.055114286 | J18: 0.83 | K18: 1 | L18: 1.2048193 | M18: 0.06 | N18: NRC Plan FY25-FY26, signed in Q1 FY25 | O18: Signed | P18: 0.1 | Q18: 0.005 | R18: 0.9 | S18: 0.98887122 | T18: 1.0987458 | U18: 0.04 | V18: 0.62 | W18: 0.45633188 | X18: 0.73601916 | Y18: 0.029440766 | Z18: > All Channels (Phisicals and Digitals) > Per model > Per month FCST (1 week before starting N month) > Per month Results (1 week after N month closure) | AA18: 0.3 | AB18: 0.015 | AC18: Q2 | AD18: 0.25 | AE18: 0.0075 | AF18: Q2 | AG18: 0.5 | AH18: 0.035 | AI18: 2642000 | AJ18: 1184707 | AK18: 0.44841294 | AL18: 0.089682589 | AM18: 1.17 | AN18: 1.2 | AO18: 1.025641 | AP18: 0.1 | AQ18: 2620 | AR18: 975 | AS18: 0.3721374 | AT18: 0.11164122 | AU18: 0.9 | AV18: 1 | AW18: 1.1111111 | AX18: 0.5 | AY18: 0.9 | AZ18: 0.97774245 | BA18: 1.0863805 | BB18: 0.48887122 | BC18: 0.54837886
B19: NO MAIN | C19: Pablo Brito | D19: Jessica Vargas | E19: NIC | F19: 0.7 | G19: 0.6 | H19: 0.85714286 | I19: 0.051428571 | J19: 0.83 | K19: 0.918 | L19: 1.1060241 | M19: 0.06 | N19: NRC Plan FY25-FY26, signed in Q1 FY25 | O19: Signed | P19: 0.1 | Q19: 0.005 | R19: 0.9 | S19: 0.96445498 | T19: 1.0716166 | U19: 0.04 | V19: 0.75 | W19: 0.48019802 | X19: 0.64026403 | Y19: 0.025610561 | Z19: > All Channels (Phisicals and Digitals) > Per model > Per month FCST (1 week before starting N month) > Per month Results (1 week after N month closure) | AA19: 0.3 | AB19: 0.015 | AC19: Q2 | AD19: 0.25 | AE19: 0.0075 | AF19: Q2 | AG19: 0.5 | AH19: 0.035 | AI19: 1142000 | AJ19: 424289 | AK19: 0.37153152 | AL19: 0.074306305 | AM19: 0.9 | AN19: 1.04 | AO19: 1.1555556 | AP19: 0.1 | AQ19: 1326 | AR19: 485 | AS19: 0.36576169 | AT19: 0.10972851 | AU19: 0.9 | AV19: 1 | AW19: 1.1111111 | AX19: 0.5 | AY19: 0.9 | AZ19: 0.92890995 | BA19: 1.0321222 | BB19: 0.46445498 | BC19: 0.52357394
B20: NO MAIN | C20: Diego Suarez | D20: Salvador Alvarez | E20: DOM | F20: 0.7 | G20: 0.79 | H20: 1.1285714 | I20: 0.06 | J20: 0.88 | K20: 0.963 | L20: 1.0943182 | M20: 0.06 | N20: NRC Plan FY25-FY26, signed in Q1 FY25 | O20: Signed | P20: 0.1 | Q20: 0.005 | R20: 0.9 | S20: 1 | T20: 1.1111111 | U20: 0.04 | V20: 0.74 | W20: 0.68786127 | X20: 0.92954226 | Y20: 0.03718169 | Z20: > All Channels (Phisicals and Digitals) > Per model > Per month FCST (1 week before starting N month) > Per month Results (1 week after N month closure) | AA20: 0.4 | AB20: 0.02 | AC20: Q2 | AD20: 0.25 | AE20: 0.0075 | AF20: Q2 | AG20: 0.5 | AH20: 0.035 | AI20: 3400000 | AJ20: 1446325 | AK20: 0.42538971 | AL20: 0.085077941 | AM20: 1.48 | AN20: 1.44 | AO20: 0.97297297 | AP20: 0.097297297 | AQ20: 2390 | AR20: 720 | AS20: 0.30125523 | AT20: 0.090376569 | AU20: 0.9 | AV20: 1 | AW20: 1.1111111 | AX20: 0.5 | AY20: 0.9 | AZ20: 1 | BA20: 1.1111111 | BB20: 0.5 | BC20: 0.5374335
B21: NO MAIN | C21: Tomas Arias | D21: Jessica Vargas | E21: GUT | F21: 0.75 | G21: 0.757 | H21: 1.0093333 | I21: 0.06 | J21: 0.83 | K21: 0.862 | L21: 1.0385542 | M21: 0.06 | N21: NRC Plan FY25-FY26, signed in Q1 FY25 | O21: Signed | P21: 0.1 | Q21: 0.005 | R21: 0.9 | S21: 0.89749403 | T21: 0.99721559 | U21: 0.039888624 | V21: 0.71 | W21: 0.44941176 | X21: 0.63297432 | Y21: 0.025318973 | Z21: > All Channels (Phisicals and Digitals) > Per model > Per month FCST (1 week before starting N month) > Per month Results (1 week after N month closure) | AA21: 0.3 | AB21: 0.015 | AC21: NA | AD21: NA | AE21: NA | AF21: Q2 | AG21: 0.5 | AH21: 0.05 | AI21: 2360000 | AJ21: 1306799 | AK21: 0.55372839 | AL21: 0.11074568 | AM21: 1.39 | AN21: 1.37 | AO21: 0.98561151 | AP21: 0.098561151 | AQ21: 2400 | AR21: 808 | AS21: 0.33666667 | AT21: 0.101 | AU21: 0.9 | AV21: 1 | AW21: 1.1111111 | AX21: 0.45 | AY21: 0.9 | AZ21: 0.89498807 | BA21: 0.99443119 | BB21: 0.44749403 | BC21: 0.56551443
B22: NO MAIN | C22: Diego Suarez | D22: Alberto Saldaña | E22: PRG | F22: 0.84 | G22: 0.91 | H22: 1.0833333 | I22: 0.06 | J22: 0.9 | K22: 0.936 | L22: 1.04 | M22: 0.06 | N22: NRC Plan FY25-FY26, signed in Q1 FY25 | O22: Signed | P22: 0.1 | Q22: 0.005 | R22: 0.9 | S22: 0.87 | T22: 0.96666667 | U22: 0.038666667 | V22: 0.74 | W22: 0.67155425 | X22: 0.90750575 | Y22: 0.03630023 | Z22: > All Channels (Phisicals and Digitals) > Per model > Per month FCST (1 week before starting N month) > Per month Results (1 week after N month closure) | AA22: 0.2 | AB22: 0.01 | AC22: NA | AD22: NA | AE22: NA | AF22: Q2 | AG22: 0.5 | AH22: 0.05 | AI22: 4850000 | AJ22: 1410976 | AK22: 0.29092289 | AL22: 0.058184577 | AM22: 1.27 | AN22: 1.56 | AO22: 1.2283465 | AP22: 0.1 | AQ22: 2300 | AR22: 659 | AS22: 0.28652174 | AT22: 0.085956522 | AU22: 0.9 | AV22: 0.84 | AW22: 0.93333333 | AX22: 0.42 | AY22: 0.9 | AZ22: 0.98919308 | BA22: 1.0991034 | BB22: 0.45 | BC22: 0.504108
B23: NO MAIN | C23: Diego Suarez | D23: Alberto Saldaña | E23: BOL | F23: 0.85 | G23: 0.893 | H23: 1.0505882 | I23: 0.06 | J23: 0.87 | K23: 0.924 | L23: 1.062069 | M23: 0.06 | N23: NRC Plan FY25-FY26, signed in Q1 FY25 | O23: Signed | P23: 0.1 | Q23: 0.005 | R23: 0.9 | S23: 0.98334291 | T23: 1.0926032 | U23: 0.04 | V23: 0.68 | W23: 0.52057613 | X23: 0.76555313 | Y23: 0.030622125 | Z23: > All Channels (Phisicals and Digitals) > Per model > Per month FCST (1 week before starting N month) > Per month Results (1 week after N month closure) | AA23: 0.3 | AB23: 0.015 | AC23: NA | AD23: NA | AE23: NA | AF23: Q2 | AG23: 0.5 | AH23: 0.05 | AI23: 2153000 | AJ23: 756854 | AK23: 0.3515346 | AL23: 0.070306921 | AM23: 0.84 | AN23: 0.8 | AO23: 0.95238095 | AP23: 0.095238095 | AQ23: 1100 | AR23: 439 | AS23: 0.39909091 | AT23: 0.11972727 | AU23: 0.9 | AV23: 1 | AW23: 1.1111111 | AX23: 0.5 | AY23: 0.9 | AZ23: 0.96668581 | BA23: 1.0740953 | BB23: 0.48334291 | BC23: 0.54589441
B24: RHD | C24: Pablo Brito | D24: Eduardo Trabado | E24: MASSY | F24: 0.7 | G24: 0.529 | H24: 0.75571429 | I24: 0.045342857 | J24: 0.88 | K24: 0.927 | L24: 1.0534091 | M24: 0.06 | N24: NRC Plan FY25-FY26, signed in Q1 FY25 | O24: Signed | P24: 0.1 | Q24: 0.005 | R24: 0.9 | S24: 0.81092199 | T24: 0.90102443 | U24: 0.036040977 | V24: 0.53 | W24: 0 | X24: 0 | Y24: 0 | Z24: > All Channels (Phisicals and Digitals) > Per model > Per month FCST (1 week before starting N month) > Per month Results (1 week after N month closure) | AA24: 0.3 | AB24: 0.015 | AC24: NA | AD24: NA | AE24: NA | AF24: Q2 | AG24: 0.5 | AH24: 0.05 | AI24: 700000 | AJ24: 126970 | AK24: 0.18138571 | AL24: 0.036277143 | AM24: 1.03 | AN24: 0 | AO24: 0 | AP24: 0 | AQ24: 1269 | AR24: 681 | AS24: 0.53664303 | AT24: 0.16099291 | AU24: 0.9 | AV24: 0.95218855 | AW24: 1.0579873 | AX24: 0.45 | AY24: 0.9 | AZ24: 0.72184397 | BA24: 0.80204886 | BB24: 0.36092199 | BC24: 0.40865388
B25: RHD | C25: Pablo Brito | D25: Eduardo Trabado | E25: GEL | F25: - | G25: - | H25: - | I25: - | J25: - | K25: - | L25: - | M25: - | N25: NRC Plan FY25-FY26, signed in Q1 FY25 | O25: Signed | P25: 0.1 | Q25: 0.005 | R25: 0.9 | S25: 0.53771884 | T25: 0.59746538 | U25: 0.029873269 | V25: 0.63 | W25: 0.32989691 | X25: 0.52364588 | Y25: 0.026182294 | Z25: > All Channels (Phisicals and Digitals) > Per model > Per month FCST (1 week before starting N month) > Per month Results (1 week after N month closure) | AA25: 0.3 | AB25: 0.015 | AC25: NA | AD25: NA | AE25: NA | AF25: Q2 | AG25: 0.5 | AH25: 0.05 | AI25: 100000 | AJ25: 32719 | AK25: 0.32719 | AL25: 0.0817975 | AM25: 2.02 | AN25: 0 | AO25: 0 | AP25: 0 | AQ25: 742 | AR25: 234 | AS25: 0.31536388 | AT25: 0.11037736 | AU25: 0.9 | AV25: 0.77417027 | AW25: 0.86018919 | AX25: 0.38708514 | AY25: 0.9 | AZ25: 0.30126741 | BA25: 0.33474157 | BB25: 0.15063371 | BC25: 0.31823042

Sheet DB
B3: DOM
C8: Target | D8: Real | E8: %Ach | F8: Diff | H8: Target | I8: Real | J8: %Ach | K8: Diff | M8: Target | N8: Real | O8: %Ach | P8: Diff | V8: NRC Implementation Plan
B9: CSI | C9: =VLOOKUP(B3,Data!$C$3:$BE$22,Data!D2,FALSE) -> 0.7 | D9: =VLOOKUP(B3,Data!$C$3:$BE$22,Data!E2,FALSE) -> 0.763 | E9: =VLOOKUP(B3,Data!$C$3:$BE$22,Data!F2,FALSE) -> 1.09 | F9: =IF(E9>=100%,0%,100%-E9) -> 0 | G9: SSI | H9: =VLOOKUP($B$3,Data!$C$3:$BE$22,Data!H2,FALSE) -> 0.88 | I9: =VLOOKUP($B$3,Data!$C$3:$BE$22,Data!I2,FALSE) -> 0.956 | J9: =VLOOKUP($B$3,Data!$C$3:$BE$22,Data!J2,FALSE) -> 1.0863636 | K9: =IF(J9>=100%,0%,100%-J9) -> 0 | L9: Campaign | M9: =VLOOKUP($B$3,Data!$C$3:$BE$22,Data!T2,FALSE) -> 0.74 | N9: =VLOOKUP($B$3,Data!$C$3:$BE$22,Data!U2,FALSE) -> 0.73988439 | O9: =VLOOKUP($B$3,Data!$C$3:$BE$22,Data!V2,FALSE) -> 0.99984377 | P9: =IF(O9>=100%,0%,100%-O9) -> 0.00015622559
L10: TR Sales | M10: =VLOOKUP($B$3,Data!$C$3:$BE$22,Data!AW2,FALSE) -> 0.9 | N10: =VLOOKUP($B$3,Data!$C$3:$BE$22,Data!AX2,FALSE) -> 1 | O10: =VLOOKUP($B$3,Data!$C$3:$BE$22,Data!AY2,FALSE) -> 1.1111111 | P10: =IF(O10>=100%,0%,100%-O10) -> 0 | Q10: =VLOOKUP($B$3,Data!$C$3:$BE$22,Data!AZ2,FALSE) -> 0.5 | V10: Target | X10: Status
L11: TR AS | M11: =VLOOKUP($B$3,Data!$C$3:$BE$22,Data!BA2,FALSE) -> 0.9 | N11: =VLOOKUP($B$3,Data!$C$3:$BE$22,Data!BB2,FALSE) -> 1 | O11: =VLOOKUP($B$3,Data!$C$3:$BE$22,Data!BC2,FALSE) -> 1.1111111 | P11: =IF(O11>=100%,0%,100%-O11) -> 0 | Q11: =VLOOKUP($B$3,Data!$C$3:$BE$22,Data!BD2,FALSE) -> 0.5 | V11: =VLOOKUP(B3,Data!C3:BE22,Data!L2,FALSE) -> NRC Plan FY25-FY26, signed in Q1 FY25 | X11: =VLOOKUP(B3,Data!C3:BE22,Data!M2,FALSE) -> Signed
M13: Sales | N13: Aftersales | O13: Target | P13: TR Real | Q13: %Ach | R13: Diff
L14: Training | M14: =N10 -> 1 | N14: =N11 -> 1 | O14: 0.9 | P14: =Q10+Q11 -> 1 | Q14: =P14/O14 -> 1.1111111 | R14: =IF(Q14>=100%,0%,100%-Q14) -> 0
L15: Target | M15: 0.9 | N15: 0.9
V16: In Progress | W16: No Startet | X16: Completed
V17: 2 | W17: 0 | X17: 0
C24: Lead Management (From Leads to Closing) | J24: Share of Invesment | Q24: 360 Game Plan
C25: Target | G25: Real | J25: Target | N25: Real | Q25: Target | V25: Real
C26: =VLOOKUP(B3,Data!C3:BE22,Data!X2,FALSE) -> Montly Report | G26: =VLOOKUP(B3,Data!C3:BE22,Data!Y2,FALSE) -> 0.6 | J26: Declare Quarterly Top 5 Competitors + Nissan | N26: =VLOOKUP(B3,Data!C3:BE22,Data!AA2,FALSE) -> Q3 | Q26: Declare Quarterly According to Template Format | V26: =VLOOKUP(B3,Data!C3:BE22,Data!AD2,FALSE) -> Q3
D34: Target | E34: Real | F34: %Ach | G34: Diff | K34: Target | L34: Real | M34: %Ach | N34: Diff | Q34: Target | R34: Real | S34: %Ach | T34: Diff | V34: =VLOOKUP(B3,Data!C3:BE22,Data!BE2,FALSE) -> 0.63514642 | W34: =IF(V34>=100%,0%,100%-V34) -> 0.36485358
C35: Sell In | D35: =VLOOKUP(B3,Data!$C$3:$BE$22,Data!AG2,FALSE) -> 3400000 | E35: =VLOOKUP($B$3,Data!$C$3:$BE$22,Data!AH2,FALSE) -> 1760989 | F35: =VLOOKUP($B$3,Data!$C$3:$BE$22,Data!AI2,FALSE) -> 0.51793794 | G35: =IF(F35>=100%,0%,100%-F35) -> 0.48206206 | J35: Retention | K35: =VLOOKUP($B$3,Data!$C$3:$BE$22,Data!AK2,FALSE) -> 1.48 | L35: =VLOOKUP($B$3,Data!$C$3:$BE$22,Data!AL2,FALSE) -> 1.44 | M35: =VLOOKUP($B$3,Data!$C$3:$BE$22,Data!AM2,FALSE) -> 0.97297297 | N35: =IF(M35>=100%,0%,100%-M35) -> 0.027027027 | P35: RS | Q35: =VLOOKUP($B$3,Data!$C$3:$BE$22,Data!AO2,FALSE) -> 2390 | R35: =VLOOKUP($B$3,Data!$C$3:$BE$22,Data!AP2,FALSE) -> 990 | S35: =VLOOKUP($B$3,Data!$C$3:$BE$22,Data!AQ2,FALSE) -> 0.41422594 | T35: =IF(S35>=100%,0%,100%-S35) -> 0.58577406

Sheet WB
B1: Retail Sales | R1: Lead Managament | AF1: Share of Investment
B2: 1 | C2: 2 | D2: 3 | E2: 4 | F2: 5 | G2: 6 | H2: 7 | I2: 8 | J2: 9 | K2: 10 | L2: 11 | M2: 12 | N2: 13 | O2: 14 | R2: 1 | S2: 2 | T2: 3 | U2: 4 | V2: 5 | W2: 6 | X2: 7 | Y2: 8 | Z2: 9 | AA2: 10 | AB2: 11 | AC2: 12 | AD2: 13 | AF2: 1 | AG2: 2 | AH2: 3 | AI2: 4 | AJ2: 5 | AK2: 6
B3: NSC | C3: APR | D3: MAY | E3: JUN | F3: JUL | G3: AUG | H3: SEP | I3: OCT | J3: NOV | K3: DEC | L3: JAN | M3: FEB | N3: MAR | O3: TOTAL | R3: Market | S3: Mayo | T3: Junio | U3: Julio | V3: Agosto | W3: Septiembre | X3: Octubre | Y3: Noviembre | Z3: Diciembre | AA3: Enero | AB3: Febrero | AC3: Marzo | AD3: Total | AF3: Market | AG3: Q1 | AH3: Q2 | AI3: Q3 | AJ3: Q4 | AK3: Total | AM3: 1 | AN3: 2 | AO3: 3 | AP3: 4 | AQ3: 5 | AR3: 6 | AS3: 7 | AT3: 8 | AU3: 9 | AV3: 10 | AW3: 11
B4: MON | C4: 0 | D4: 0 | E4: 0 | F4: 0 | G4: 0 | H4: 0 | I4: 1 | O4: =SUM(C4:N4) -> 1 | R4: COL | T4: =IF(AN6=3,10%,0) -> 0.1 | U4: =IF(AO6=3,10%,0) -> 0.1 | V4: =IF(AP6=3,10%,0) -> 0.1 | W4: =IF(AQ6=3,10%,0) -> 0.1 | X4: =IF(AR6=3,10%,0) -> 0.1 | Y4: =IF(AS6=3,10%,0) -> 0 | Z4: =IF(AT6=3,10%,0) -> 0 | AA4: =IF(AU6=3,10%,0) -> 0 | ... AC4: =IF(AW6=3,10%,0) -> 0 | AD4: =SUM(S4:AC4) -> 0.5 | AF4: COL | AG4: 0.25 | AH4: 0.25 | AI4: - | AJ4: - | AK4: =SUM(AG4:AJ4) -> 0.5 | AN4: JUNE | AO4: JULY | AP4: AUGUST | AQ4: SEPTEMBER | AR4: OCTOBER | AS4: NOVEMBER | AT4: DECEMBER | AU4: JANUARY | AV4: FEBRUARY | AW4: MARCH
B5: ALB | C5: 22 | D5: 17 | E5: 36 | F5: 26 | G5: 11 | H5: 29 | I5: 25 | O5: =SUM(C5:N5) -> 166 | R5: PLT | T5: =IF(AN7=3,10%,0) -> 0.1 | U5: =IF(AO7=3,10%,0) -> 0.1 | V5: =IF(AP7=3,10%,0) -> 0.1 | W5: =IF(AQ7=3,10%,0) -> 0.1 | X5: =IF(AR7=3,10%,0) -> 0.1 | Y5: =IF(AS7=3,10%,0) -> 0 | Z5: =IF(AT7=3,10%,0) -> 0 | AA5: =IF(AU7=3,10%,0) -> 0 | ... AC5: =IF(AW7=3,10%,0) -> 0 | AD5: =SUM(S5:AC5) -> 0.5 | AF5: PLT | AG5: 0.25 | AH5: 0.25 | AI5: - | AJ5: - | AK5: =SUM(AG5:AJ5) -> 0.5 | AM5: Market | AN5: RES MAY | FCST JUN | AO5: RES JUN| FCST JUL | AP5: RES JUL | FCST AUG | AQ5: RES AUG | FCST SEP | AR5: RES SEP | FCST OCT | AS5: RES OCT | FCST NOV | AT5: RES NOV | FCST DEC | AU5: RES DEC | FCST JAN | AV5: RES JAN | FCST FEB | AW5: RES FEB | FCST MAR
B6: ANT | C6: 8 | D6: 4 | E6: 6 | F6: 0 | G6: 9 | H6: 6 | I6: 4 | O6: =SUM(C6:N6) -> 37 | R6: CST | T6: =IF(AN8=3,10%,0) -> 0.1 | U6: =IF(AO8=3,10%,0) -> 0.1 | V6: =IF(AP8=3,10%,0) -> 0.1 | W6: =IF(AQ8=3,10%,0) -> 0.1 | X6: =IF(AR8=3,10%,0) -> 0.1 | Y6: =IF(AS8=3,10%,0) -> 0 | Z6: =IF(AT8=3,10%,0) -> 0 | AA6: =IF(AU8=3,10%,0) -> 0 | ... AC6: =IF(AW8=3,10%,0) -> 0 | AD6: =SUM(S6:AC6) -> 0.5 | AF6: CST | AG6: 0.25 | AH6: 0.25 | AI6: - | AJ6: - | AK6: =SUM(AG6:AJ6) -> 0.5 | AM6: COL | AN6: 3 | AO6: 3 | AP6: 3 | AQ6: 3 | AR6: 3 | AS6: - | AT6: - | AU6: - | AV6: - | AW6: -
B7: BAR | C7: 15 | D7: 12 | E7: 13 | F7: 6 | G7: 9 | H7: 31 | I7: 15 | O7: =SUM(C7:N7) -> 101 | R7: ECA | T7: =IF(AN9=3,10%,0) -> 0.1 | U7: =IF(AO9=3,10%,0) -> 0.1 | V7: =IF(AP9=3,10%,0) -> 0.1 | W7: =IF(AQ9=3,10%,0) -> 0.1 | X7: =IF(AR9=3,10%,0) -> 0.1 | Y7: =IF(AS9=3,10%,0) -> 0 | Z7: =IF(AT9=3,10%,0) -> 0 | AA7: =IF(AU9=3,10%,0) -> 0 | ... AC7: =IF(AW9=3,10%,0) -> 0 | AD7: =SUM(S7:AC7) -> 0.5 | AF7: ECA | AG7: 0.25 | AH7: 0.25 | AI7: - | AJ7: - | AK7: =SUM(AG7:AJ7) -> 0.5 | AM7: PLT | AN7: 3 | AO7: 3 | AP7: 3 | AQ7: 3 | AR7: 3 | AS7: - | AT7: - | AU7: - | AV7: - | AW7: -
B8: BEM | C8: 2 | D8: 2 | E8: 0 | F8: 1 | G8: 1 | H8: 2 | I8: 2 | O8: =SUM(C8:N8) -> 10 | R8: PNM | T8: =IF(AN10=3,10%,0) -> 0.1 | U8: =IF(AO10=3,10%,0) -> 0.1 | V8: =IF(AP10=3,10%,0) -> 0.1 | W8: =IF(AQ10=3,10%,0) -> 0.1 | X8: =IF(AR10=3,10%,0) -> 0.1 | Y8: =IF(AS10=3,10%,0) -> 0 | Z8: =IF(AT10=3,10%,0) -> 0 | AA8: =IF(AU10=3,10%,0) -> 0 | ... AC8: =IF(AW10=3,10%,0) -> 0 | AD8: =SUM(S8:AC8) -> 0.5 | AF8: PNM | AG8: 0.25 | AH8: 0.25 | AI8: - | AJ8: - | AK8: =SUM(AG8:AJ8) -> 0.5 | AM8: CST | AN8: 3 | AO8: 3 | AP8: 3 | AQ8: 3 | AR8: 3 | AS8: - | AT8: - | AU8: - | AV8: - | AW8: -
B9: BHM | C9: 16 | D9: 8 | E9: 9 | F9: 6 | G9: 5 | H9: 11 | I9: 0 | O9: =SUM(C9:N9) -> 55 | R9: URU | T9: =IF(AN11=3,10%,0) -> 0.1 | U9: =IF(AO11=3,10%,0) -> 0.1 | V9: =IF(AP11=3,10%,0) -> 0.1 | W9: =IF(AQ11=3,10%,0) -> 0.1 | X9: =IF(AR11=3,10%,0) -> 0.1 | Y9: =IF(AS11=3,10%,0) -> 0 | Z9: =IF(AT11=3,10%,0) -> 0 | AA9: =IF(AU11=3,10%,0) -> 0 | ... AC9: =IF(AW11=3,10%,0) -> 0 | AD9: =SUM(S9:AC9) -> 0.5 | AF9: URU | AG9: 0.25 | AH9: 0.25 | AI9: - | AJ9: - | AK9: =SUM(AG9:AJ9) -> 0.5 | AM9: ECA | AN9: 3 | AO9: 3 | AP9: 3 | AQ9: 3 | AR9: 3 | AS9: - | AT9: - | AU9: - | AV9: - | AW9: -
